package com.github.technus.tectech.thing.metaTileEntity.multi;

import com.github.technus.tectech.thing.block.QuantumGlassBlock;
import com.github.technus.tectech.thing.metaTileEntity.multi.base.GT_MetaTileEntity_MultiblockBase_EM;
import com.github.technus.tectech.thing.metaTileEntity.multi.base.render.TT_RenderedExtendedFacingTexture;
import com.github.technus.tectech.util.CommonValues;
import com.gtnewhorizon.structurelib.alignment.constructable.IConstructable;
import com.gtnewhorizon.structurelib.structure.IStructureDefinition;
import com.gtnewhorizon.structurelib.structure.StructureDefinition;
import cpw.mods.fml.relauncher.Side;
import cpw.mods.fml.relauncher.SideOnly;
import gregtech.api.enums.Textures;
import gregtech.api.interfaces.ITexture;
import gregtech.api.interfaces.metatileentity.IMetaTileEntity;
import gregtech.api.interfaces.tileentity.IGregTechTileEntity;
import net.minecraft.client.renderer.texture.IIconRegister;
import net.minecraft.item.ItemStack;
import net.minecraft.util.EnumChatFormatting;

import static com.github.technus.tectech.thing.casing.GT_Block_CasingsTT.textureOffset;
import static com.github.technus.tectech.thing.casing.GT_Block_CasingsTT.texturePage;
import static com.github.technus.tectech.thing.casing.TT_Container_Casings.sBlockCasingsTT;
import static com.github.technus.tectech.thing.metaTileEntity.multi.GT_MetaTileEntity_EM_decay.URANIUM_INGOT_MASS_DIFF;
import static com.github.technus.tectech.thing.metaTileEntity.multi.GT_MetaTileEntity_EM_decay.URANIUM_MASS_TO_EU_INSTANT;
import static com.gtnewhorizon.structurelib.structure.StructureUtility.ofBlock;
import static com.gtnewhorizon.structurelib.structure.StructureUtility.transpose;
import static gregtech.api.enums.GT_Values.E;
import static gregtech.api.util.GT_StructureUtility.ofHatchAdderOptional;
import static net.minecraft.util.StatCollector.translateToLocal;

/**
 * Created by danie_000 on 17.12.2016.
 */
public class GT_MetaTileEntity_EM_bhg extends GT_MetaTileEntity_MultiblockBase_EM implements IConstructable {
    //region variables
    private static Textures.BlockIcons.CustomIcon ScreenOFF;
    private static Textures.BlockIcons.CustomIcon ScreenON;

    //todo CHECK VALUES
    private static final double NEUTRONIUM_BLOCK_MASS = 4.1E17;
    private static final double NEUTRONIUM_BLOCK_ATOM_COUNT = 2.4478671E44;
    private static final double NEUTRONIUM_BLOCK_TO_EU_INSTANT = URANIUM_MASS_TO_EU_INSTANT * NEUTRONIUM_BLOCK_MASS / (URANIUM_INGOT_MASS_DIFF * 1.78266191e-36);//~ 5.314e40
    private static final double NEUTRON_TO_EU_INSTANT = NEUTRONIUM_BLOCK_TO_EU_INSTANT / NEUTRONIUM_BLOCK_ATOM_COUNT;//~ 0.00021708694

    public boolean glassDome = false;
    //endregion

    //Time dillatation - to slow down the explosion thing but REALLY REDUCE POWER OUTPUT
    //Startcodes to startup
    //per dim disable thingies

    //region structure actual
    private static final IStructureDefinition<GT_MetaTileEntity_EM_bhg> STRUCTURE_DEFINITION=
            StructureDefinition.<GT_MetaTileEntity_EM_bhg>builder()
            .addShape("main_t1", transpose(new String[][]{
                    {"                                 ","                                 ","                                 ","                                 ","                                 ","                                 ","                                 ","                                 ","                                 ","                                 ","                                 ","                                 ","               C C               ","               C C               ","               C C               ","            CCCCCCCCC            ","               C C               ","            CCCCCCCCC            ","               C C               ","               C C               ","               C C               ","                                 ","                                 ","                                 ","                                 ","                                 ","                                 ","                                 ","                                 ","                                 ","                                 ","                                 ","                                 "},
                    {"                                 ","                                 ","                                 ","                                 ","                                 ","                                 ","                                 ","                                 ","                                 ","               C C               ","               C C               ","               C C               ","               C C               ","              DDDDD              ","             DDCDCDD             ","         CCCCDCCDCCDCCCC         ","             DDDDDDD             ","         CCCCDCCDCCDCCCC         ","             DDCDCDD             ","              DDDDD              ","               C C               ","               C C               ","               C C               ","               C C               ","                                 ","                                 ","                                 ","                                 ","                                 ","                                 ","                                 ","                                 ","                                 "},
                    {"                                 ","                                 ","                                 ","                                 ","                                 ","                                 ","                                 ","               C C               ","               C C               ","               C C               ","                D                ","                D                ","             DDDDDDD             ","            DD     DD            ","            D  EEE  D            ","       CCC  D EAAAE D  CCC       ","          DDD EAAAE DDD          ","       CCC  D EAAAE D  CCC       ","            D  EEE  D            ","            DD     DD            ","             DDDDDDD             ","                D                ","                D                ","               C C               ","               C C               ","               C C               ","                                 ","                                 ","                                 ","                                 ","                                 ","                                 ","                                 "},
                    {"                                 ","                                 ","                                 ","                                 ","                                 ","                                 ","               C C               ","               C C               ","                D                ","                D                ","                                 ","                                 ","                                 ","                                 ","                                 ","      CC                 CC      ","        DD             DD        ","      CC                 CC      ","                                 ","                                 ","                                 ","                                 ","                                 ","                D                ","                D                ","               C C               ","               C C               ","                                 ","                                 ","                                 ","                                 ","                                 ","                                 "},
                    {"                                 ","                                 ","                                 ","                                 ","                                 ","               C C               ","              CCCCC              ","                D                ","                B                ","                B                ","                                 ","                                 ","                                 ","                                 ","      C                   C      ","     CC                   CC     ","      CDBB             BBDC      ","     CC                   CC     ","      C                   C      ","                                 ","                                 ","                                 ","                                 ","                B                ","                B                ","                D                ","              CCCCC              ","               C C               ","                                 ","                                 ","                                 ","                                 ","                                 "},
                    {"                                 ","                                 ","                                 ","                                 ","               C C               ","               C C               ","                D                ","             EEEBEEE             ","                                 ","                                 ","                                 ","                                 ","                                 ","       E                 E       ","       E                 E       ","    CC E                 E CC    ","      DB                 BD      ","    CC E                 E CC    ","       E                 E       ","       E                 E       ","                                 ","                                 ","                                 ","                                 ","                                 ","             EEEBEEE             ","                D                ","               C C               ","               C C               ","                                 ","                                 ","                                 ","                                 "},
                    {"                                 ","                                 ","                                 ","               C C               ","              CCCCC              ","                D                ","                B                ","                                 ","                                 ","                                 ","                                 ","                                 ","                                 ","                                 ","    C                       C    ","   CC                       CC   ","    CDB                   BDC    ","   CC                       CC   ","    C                       C    ","                                 ","                                 ","                                 ","                                 ","                                 ","                                 ","                                 ","                B                ","                D                ","              CCCCC              ","               C C               ","                                 ","                                 ","                                 "},
                    {"                                 ","                                 ","               C C               ","               C C               ","                D                ","             EEEBEEE             ","                                 ","                                 ","                                 ","                                 ","                                 ","                                 ","                                 ","     E                     E     ","     E                     E     ","  CC E                     E CC  ","    DB                     BD    ","  CC E                     E CC  ","     E                     E     ","     E                     E     ","                                 ","                                 ","                                 ","                                 ","                                 ","                                 ","                                 ","             EEEBEEE             ","                D                ","               C C               ","               C C               ","                                 ","                                 "},
                    {"                                 ","                                 ","               C C               ","                D                ","                B                ","                                 ","                                 ","                                 ","                                 ","                                 ","                                 ","                                 ","                                 ","                                 ","                                 ","  C                           C  ","   DB                       BD   ","  C                           C  ","                                 ","                                 ","                                 ","                                 ","                                 ","                                 ","                                 ","                                 ","                                 ","                                 ","                B                ","                D                ","               C C               ","                                 ","                                 "},
                    {"                                 ","               C C               ","               C C               ","                D                ","                B                ","                                 ","                                 ","                                 ","                                 ","                                 ","                                 ","                                 ","                                 ","                                 ","                                 "," CC                           CC ","   DB                       BD   "," CC                           CC ","                                 ","                                 ","                                 ","                                 ","                                 ","                                 ","                                 ","                                 ","                                 ","                                 ","                B                ","                D                ","               C C               ","               C C               ","                                 "},
                    {"                                 ","               C C               ","                D                ","                                 ","                                 ","                                 ","                                 ","                                 ","                                 ","                                 ","                                 ","                                 ","                                 ","                                 ","                                 "," C                             C ","  D                           D  "," C                             C ","                                 ","                                 ","                                 ","                                 ","                                 ","                                 ","                                 ","                                 ","                                 ","                                 ","                                 ","                                 ","                D                ","               C C               ","                                 "},
                    {"                                 ","               C C               ","                D                ","                                 ","                                 ","                                 ","                                 ","                                 ","                                 ","                                 ","                                 ","                                 ","                                 ","                                 ","                                 "," C                             C ","  D                           D  "," C                             C ","                                 ","                                 ","                                 ","                                 ","                                 ","                                 ","                                 ","                                 ","                                 ","                                 ","                                 ","                                 ","                D                ","               C C               ","                                 "},
                    {"             CCCCCCC             ","               C C               ","             DDDDDDD             ","                                 ","                                 ","                                 ","                                 ","                                 ","                                 ","                                 ","                                 ","                                 ","                                 ","  D                           D  ","  D                           D  ","CCD                           DCC","  D                           D  ","CCD                           DCC","  D                           D  ","  D                           D  ","                                 ","                                 ","                                 ","                                 ","                                 ","                                 ","                                 ","                                 ","                                 ","                                 ","             DDDDDDD             ","               C C               ","               C C               "},
                    {"            CCHHHHHCC            ","              DDDDD              ","            DD     DD            ","                                 ","                                 ","       E                 E       ","                                 ","     E                     E     ","                                 ","                                 ","                                 ","                                 ","  D                           D  ","  D                           D  "," D                             D ","CD                             DC"," D                             D ","CD                             DC"," D                             D ","  D                           D  ","  D                           D  ","                                 ","                                 ","                                 ","                                 ","     E                     E     ","                                 ","       E                 E       ","                                 ","                                 ","            DD     DD            ","              DDDDD              ","               C C               "},
                    {"            CHHHHHHHC            ","             DDCDCDD             ","            D  EEE  D            ","                                 ","      C                   C      ","       E                 E       ","    C                       C    ","     E                     E     ","                                 ","                                 ","                                 ","                                 ","  D                           D  "," D                             D "," D                             D ","CCE                           ECC"," DE                           ED ","CCE                           ECC"," D                             D "," D                             D ","  D                           D  ","                                 ","                                 ","                                 ","                                 ","     E                     E     ","    C                       C    ","       E                 E       ","      C                   C      ","                                 ","            D  EEE  D            ","             DDCDCDD             ","               C C               "},
                    {"            CHHFFFHHC            ","         CCCCDCCDCCDCCCC         ","       CCC  D EAAAE D  CCC       ","      CC                 CC      ","     CC                   CC     ","    CC E                 E CC    ","   CC                       CC   ","  CC E                     E CC  ","  C                           C  "," CC                           CC "," C                             C "," C                             C ","CCD                           DCC","CD                             DC","CCE                           ECC","CCA                           ACC","CDA                           ADC","CCA                           ACC","CCE                           ECC","CD                             DC","CCD                           DCC"," C                             C "," C                             C "," CC                           CC ","  C                           C  ","  CC E                     E CC  ","   CC                       CC   ","    CC E                 E CC    ","     CC                   CC     ","      CC                 CC      ","       CCC  D EAAAE D  CCC       ","         CCCCDCCDCCDCCCC         ","            CCCCCCCCC            "},
                    {"            CHHF~FHHC            ","             DDDDDDD             ","          DDD EAAAE DDD          ","        DD             DD        ","      CDBB             BBDC      ","      DB                 BD      ","    CDB                   BDC    ","    DB                     BD    ","   DB                       BD   ","   DB                       BD   ","  D                           D  ","  D                           D  ","  D                           D  "," D                             D "," DE                           ED ","CDA                           ADC"," DA                           AD ","CDA                           ADC"," DE                           ED "," D                             D ","  D                           D  ","  D                           D  ","  D                           D  ","   DB                       BD   ","   DB                       BD   ","    DB                     BD    ","    CDB                   BDC    ","      DB                 BD      ","      CDBB             BBDC      ","        DD             DD        ","          DDD EAAAE DDD          ","             DDDDDDD             ","               C C               "},
                    {"            CHHFFFHHC            ","         CCCCDCCDCCDCCCC         ","       CCC  D EAAAE D  CCC       ","      CC                 CC      ","     CC                   CC     ","    CC E                 E CC    ","   CC                       CC   ","  CC E                     E CC  ","  C                           C  "," CC                           CC "," C                             C "," C                             C ","CCD                           DCC","CD                             DC","CCE                           ECC","CCA                           ACC","CDA                           ADC","CCA                           ACC","CCE                           ECC","CD                             DC","CCD                           DCC"," C                             C "," C                             C "," CC                           CC ","  C                           C  ","  CC E                     E CC  ","   CC                       CC   ","    CC E                 E CC    ","     CC                   CC     ","      CC                 CC      ","       CCC  D EAAAE D  CCC       ","         CCCCDCCDCCDCCCC         ","            CCCCCCCCC            "},
                    {"            CHHHHHHHC            ","             DDCDCDD             ","            D  EEE  D            ","                                 ","      C                   C      ","       E                 E       ","    C                       C    ","     E                     E     ","                                 ","                                 ","                                 ","                                 ","  D                           D  "," D                             D "," D                             D ","CCE                           ECC"," DE                           ED ","CCE                           ECC"," D                             D "," D                             D ","  D                           D  ","                                 ","                                 ","                                 ","                                 ","     E                     E     ","    C                       C    ","       E                 E       ","      C                   C      ","                                 ","            D  EEE  D            ","             DDCDCDD             ","               C C               "},
                    {"            CCHHHHHCC            ","              DDDDD              ","            DD     DD            ","                                 ","                                 ","       E                 E       ","                                 ","     E                     E     ","                                 ","                                 ","                                 ","                                 ","  D                           D  ","  D                           D  "," D                             D ","CD                             DC"," D                             D ","CD                             DC"," D                             D ","  D                           D  ","  D                           D  ","                                 ","                                 ","                                 ","                                 ","     E                     E     ","                                 ","       E                 E       ","                                 ","                                 ","            DD     DD            ","              DDDDD              ","               C C               "},
                    {"             CCCCCCC             ","               C C               ","             DDDDDDD             ","                                 ","                                 ","                                 ","                                 ","                                 ","                                 ","                                 ","                                 ","                                 ","                                 ","  D                           D  ","  D                           D  ","CCD                           DCC","  D                           D  ","CCD                           DCC","  D                           D  ","  D                           D  ","                                 ","                                 ","                                 ","                                 ","                                 ","                                 ","                                 ","                                 ","                                 ","                                 ","             DDDDDDD             ","               C C               ","               C C               "},
                    {"                                 ","               C C               ","                D                ","                                 ","                                 ","                                 ","                                 ","                                 ","                                 ","                                 ","                                 ","                                 ","                                 ","                                 ","                                 "," C                             C ","  D                           D  "," C                             C ","                                 ","                                 ","                                 ","                                 ","                                 ","                                 ","                                 ","                                 ","                                 ","                                 ","                                 ","                                 ","                D                ","               C C               ","                                 "},
                    {"                                 ","               C C               ","                D                ","                                 ","                                 ","                                 ","                                 ","                                 ","                                 ","                                 ","                                 ","                                 ","                                 ","                                 ","                                 "," C                             C ","  D                           D  "," C                             C ","                                 ","                                 ","                                 ","                                 ","                                 ","                                 ","                                 ","                                 ","                                 ","                                 ","                                 ","                                 ","                D                ","               C C               ","                                 "},
                    {"                                 ","               C C               ","               C C               ","                D                ","                B                ","                                 ","                                 ","                                 ","                                 ","                                 ","                                 ","                                 ","                                 ","                                 ","                                 "," CC                           CC ","   DB                       BD   "," CC                           CC ","                                 ","                                 ","                                 ","                                 ","                                 ","                                 ","                                 ","                                 ","                                 ","                                 ","                B                ","                D                ","               C C               ","               C C               ","                                 "},
                    {"                                 ","                                 ","               C C               ","                D                ","                B                ","                                 ","                                 ","                                 ","                                 ","                                 ","                                 ","                                 ","                                 ","                                 ","                                 ","  C                           C  ","   DB                       BD   ","  C                           C  ","                                 ","                                 ","                                 ","                                 ","                                 ","                                 ","                                 ","                                 ","                                 ","                                 ","                B                ","                D                ","               C C               ","                                 ","                                 "},
                    {"                                 ","                                 ","               C C               ","               C C               ","                D                ","             EEEBEEE             ","                                 ","                                 ","                                 ","                                 ","                                 ","                                 ","                                 ","     E                     E     ","     E                     E     ","  CC E                     E CC  ","    DB                     BD    ","  CC E                     E CC  ","     E                     E     ","     E                     E     ","                                 ","                                 ","                                 ","                                 ","                                 ","                                 ","                                 ","             EEEBEEE             ","                D                ","               C C               ","               C C               ","                                 ","                                 "},
                    {"                                 ","                                 ","                                 ","               C C               ","              CCCCC              ","                D                ","                B                ","                                 ","                                 ","                                 ","                                 ","                                 ","                                 ","                                 ","    C                       C    ","   CC                       CC   ","    CDB                   BDC    ","   CC                       CC   ","    C                       C    ","                                 ","                                 ","                                 ","                                 ","                                 ","                                 ","                                 ","                B                ","                D                ","              CCCCC              ","               C C               ","                                 ","                                 ","                                 "},
                    {"                                 ","                                 ","                                 ","                                 ","               C C               ","               C C               ","                D                ","             EEEBEEE             ","                                 ","                                 ","                                 ","                                 ","                                 ","       E                 E       ","       E                 E       ","    CC E                 E CC    ","      DB                 BD      ","    CC E                 E CC    ","       E                 E       ","       E                 E       ","                                 ","                                 ","                                 ","                                 ","                                 ","             EEEBEEE             ","                D                ","               C C               ","               C C               ","                                 ","                                 ","                                 ","                                 "},
                    {"                                 ","                                 ","                                 ","                                 ","                                 ","               C C               ","              CCCCC              ","                D                ","                B                ","                B                ","                                 ","                                 ","                                 ","                                 ","      C                   C      ","     CC                   CC     ","      CDBB             BBDC      ","     CC                   CC     ","      C                   C      ","                                 ","                                 ","                                 ","                                 ","                B                ","                B                ","                D                ","              CCCCC              ","               C C               ","                                 ","                                 ","                                 ","                                 ","                                 "},
                    {"                                 ","                                 ","                                 ","                                 ","                                 ","                                 ","               C C               ","               C C               ","                D                ","                D                ","                                 ","                                 ","                                 ","                                 ","                                 ","      CC                 CC      ","        DD             DD        ","      CC                 CC      ","                                 ","                                 ","                                 ","                D                ","                D                ","                D                ","                D                ","               C C               ","               C C               ","                                 ","                                 ","                                 ","                                 ","                                 ","                                 "},
                    {"                                 ","                                 ","                                 ","                                 ","                                 ","                                 ","                                 ","               C C               ","               C C               ","               C C               ","                D                ","                D                ","             DDDDDDD             ","            DD     DD            ","            D  EEE  D            ","       CCC  D EAAAE D  CCC       ","          DDD EAAAE DDD          ","       CCC  D EAAAE D  CCC       ","            D  EEE  D            ","            DD     DD            ","             DDDDDDD             ","                D                ","                D                ","               C C               ","               C C               ","               C C               ","                                 ","                                 ","                                 ","                                 ","                                 ","                                 ","                                 "},
                    {"                                 ","                                 ","                                 ","                                 ","                                 ","                                 ","                                 ","                                 ","                                 ","               C C               ","               C C               ","               C C               ","               C C               ","              DDDDD              ","             DDCDCDD             ","         CCCCDCCDCCDCCCC         ","             DDDDDDD             ","         CCCCDCCDCCDCCCC         ","             DDCDCDD             ","              DDDDD              ","               C C               ","               C C               ","               C C               ","               C C               ","                                 ","                                 ","                                 ","                                 ","                                 ","                                 ","                                 ","                                 ","                                 "},
                    {"                                 ","                                 ","                                 ","                                 ","                                 ","                                 ","                                 ","                                 ","                                 ","                                 ","                                 ","                                 ","               C C               ","               C C               ","               C C               ","            CCCCCCCCC            ","               C C               ","            CCCCCCCCC            ","               C C               ","               C C               ","               C C               ","                                 ","                                 ","                                 ","                                 ","                                 ","                                 ","                                 ","                                 ","                                 ","                                 ","                                 ","                                 "}
            }))
            .addShape("main_t2", transpose(new String[][]{
                    {"                                 ","                                 ","                                 ","                                 ","                                 ","                                 ","                                 ","                                 ","                                 ","                                 ","                                 ","                                 ","               C C               ","               C C               ","               C C               ","            CCCCCCCCC            ","               C C               ","            CCCCCCCCC            ","               C C               ","               C C               ","               C C               ","                                 ","                                 ","                                 ","                                 ","                                 ","                                 ","                                 ","                                 ","                                 ","                                 ","                                 ","                                 "},
                    {"                                 ","                                 ","                                 ","                                 ","                                 ","                                 ","                                 ","                                 ","                                 ","               C C               ","             GGC CGG             ","            GGGC CGGG            ","           GGGGC CGGGG           ","          GGGGDDDDDGGGG          ","          GGGDDCDCDDGGG          ","         CCCCDCCDCCDCCCC         ","             DDDDDDD             ","         CCCCDCCDCCDCCCC         ","          GGGDDCDCDDGGG          ","          GGGGDDDDDGGGG          ","           GGGGC CGGGG           ","            GGGC CGGG            ","             GGC CGG             ","               C C               ","                                 ","                                 ","                                 ","                                 ","                                 ","                                 ","                                 ","                                 ","                                 "},
                    {"                                 ","                                 ","                                 ","                                 ","                                 ","                                 ","                                 ","               C C               ","             GGC CGG             ","           GGGGC CGGGG           ","          GGG   D   GGG          ","         GGG    D    GGG         ","         GG  DDDDDDD  GG         ","        GG  DD     DD  GG        ","        GG  D  EEE  D  GG        ","       CCC  D EAAAE D  CCC       ","          DDD EAAAE DDD          ","       CCC  D EAAAE D  CCC       ","        GG  D  EEE  D  GG        ","        GG  DD     DD  GG        ","         GG  DDDDDDD  GG         ","         GGG    D    GGG         ","          GGG   D   GGG          ","           GGGGC CGGGG           ","             GGC CGG             ","               C C               ","                                 ","                                 ","                                 ","                                 ","                                 ","                                 ","                                 "},
                    {"                                 ","                                 ","                                 ","                                 ","                                 ","                                 ","               C C               ","            GGGC CGGG            ","          GGG   D   GGG          ","         GG     D     GG         ","        GG             GG        ","        G               G        ","       GG               GG       ","       G                 G       ","       G                 G       ","      CC                 CC      ","        DD             DD        ","      CC                 CC      ","       G                 G       ","       G                 G       ","       GG               GG       ","        G               G        ","        GG             GG        ","         GG     D     GG         ","          GGG   D   GGG          ","            GGGC CGGG            ","               C C               ","                                 ","                                 ","                                 ","                                 ","                                 ","                                 "},
                    {"                                 ","                                 ","                                 ","                                 ","                                 ","               C C               ","           GGGCCCCCGGG           ","         GGG    D    GGG         ","        GG      B      GG        ","       GG       B       GG       ","       G                 G       ","      GG                 GG      ","      G                   G      ","      G                   G      ","      C                   C      ","     CC                   CC     ","      CDBB             BBDC      ","     CC                   CC     ","      C                   C      ","      G                   G      ","      G                   G      ","      GG                 GG      ","       G                 G       ","       GG       B       GG       ","        GG      B      GG        ","         GGG    D    GGG         ","           GGGCCCCCGGG           ","               C C               ","                                 ","                                 ","                                 ","                                 ","                                 "},
                    {"                                 ","                                 ","                                 ","                                 ","               C C               ","          GGGGGC CGGGGG          ","        GGG     D     GGG        ","       GG    EEEBEEE    GG       ","      GG                 GG      ","      G                   G      ","     GG                   GG     ","     G                     G     ","     G                     G     ","     G E                 E G     ","     G E                 E G     ","    CC E                 E CC    ","      DB                 BD      ","    CC E                 E CC    ","     G E                 E G     ","     G E                 E G     ","     G                     G     ","     G                     G     ","     GG                   GG     ","      G                   G      ","      GG                 GG      ","       GG    EEEBEEE    GG       ","        GGG     D     GGG        ","          GGGGGC CGGGGG          ","               C C               ","                                 ","                                 ","                                 ","                                 "},
                    {"                                 ","                                 ","                                 ","               C C               ","           GGGCCCCCGGG           ","        GGG     D     GGG        ","       GG       B       GG       ","      G                   G      ","     GG                   GG     ","     G                     G     ","     G                     G     ","    G                       G    ","    G                       G    ","    G                       G    ","    C                       C    ","   CC                       CC   ","    CDB                   BDC    ","   CC                       CC   ","    C                       C    ","    G                       G    ","    G                       G    ","    G                       G    ","     G                     G     ","     G                     G     ","     GG                   GG     ","      G                   G      ","       GG       B       GG       ","        GGG     D     GGG        ","           GGGCCCCCGGG           ","               C C               ","                                 ","                                 ","                                 "},
                    {"                                 ","                                 ","               C C               ","            GGGC CGGG            ","         GGG    D    GGG         ","       GG    EEEBEEE    GG       ","      G                   G      ","     G                     G     ","     G                     G     ","    G                       G    ","    G                       G    ","    G                       G    ","   G                         G   ","   G E                     E G   ","   G E                     E G   ","  CC E                     E CC  ","    DB                     BD    ","  CC E                     E CC  ","   G E                     E G   ","   G E                     E G   ","   G                         G   ","    G                       G    ","    G                       G    ","    G                       G    ","     G                     G     ","     G                     G     ","      G                   G      ","       GG    EEEBEEE    GG       ","         GGG    D    GGG         ","            GGGC CGGG            ","               C C               ","                                 ","                                 "},
                    {"                                 ","                                 ","             GGC CGG             ","          GGG   D   GGG          ","        GG      B      GG        ","      GG                 GG      ","     GG                   GG     ","     G                     G     ","    G                       G    ","    G                       G    ","   G                         G   ","   G                         G   ","   G                         G   ","  G                           G  ","  G                           G  ","  C                           C  ","   DB                       BD   ","  C                           C  ","  G                           G  ","  G                           G  ","   G                         G   ","   G                         G   ","   G                         G   ","    G                       G    ","    G                       G    ","     G                     G     ","     GG                   GG     ","      GG                 GG      ","        GG      B      GG        ","          GGG   D   GGG          ","             GGC CGG             ","                                 ","                                 "},
                    {"                                 ","               C C               ","           GGGGC CGGGG           ","         GG     D     GG         ","       GG       B       GG       ","      G                   G      ","     G                     G     ","    G                       G    ","    G                       G    ","   G                         G   ","   G                         G   ","  G                           G  ","  G                           G  ","  G                           G  ","  G                           G  "," CC                           CC ","   DB                       BD   "," CC                           CC ","  G                           G  ","  G                           G  ","  G                           G  ","  G                           G  ","   G                         G   ","   G                         G   ","    G                       G    ","    G                       G    ","     G                     G     ","      G                   G      ","       GG       B       GG       ","         GG     D     GG         ","           GGGGC CGGGG           ","               C C               ","                                 "},
                    {"                                 ","             GGC CGG             ","          GGG   D   GGG          ","        GG             GG        ","       G                 G       ","     GG                   GG     ","     G                     G     ","    G                       G    ","   G                         G   ","   G                         G   ","  G                           G  ","  G                           G  ","  G                           G  "," G                             G "," G                             G "," C                             C ","  D                           D  "," C                             C "," G                             G "," G                             G ","  G                           G  ","  G                           G  ","  G                           G  ","   G                         G   ","   G                         G   ","    G                       G    ","     G                     G     ","     GG                   GG     ","       G                 G       ","        GG             GG        ","          GGG   D   GGG          ","             GGC CGG             ","                                 "},
                    {"                                 ","            GGGC CGGG            ","         GGG    D    GGG         ","        G               G        ","      GG                 GG      ","     G                     G     ","    G                       G    ","    G                       G    ","   G                         G   ","  G                           G  ","  G                           G  ","  G                           G  "," G                             G "," G                             G "," G                             G "," C                             C ","  D                           D  "," C                             C "," G                             G "," G                             G "," G                             G ","  G                           G  ","  G                           G  ","  G                           G  ","   G                         G   ","    G                       G    ","    G                       G    ","     G                     G     ","      GG                 GG      ","        G               G        ","         GGG    D    GGG         ","            GGGC CGGG            ","                                 "},
                    {"             CCCCCCC             ","           GGGGC CGGGG           ","         GG  DDDDDDD  GG         ","       GG               GG       ","      G                   G      ","     G                     G     ","    G                       G    ","   G                         G   ","   G                         G   ","  G                           G  ","  G                           G  "," G                             G "," G                             G "," GD                           DG "," GD                           DG ","CCD                           DCC","  D                           D  ","CCD                           DCC"," GD                           DG "," GD                           DG "," G                             G "," G                             G ","  G                           G  ","  G                           G  ","   G                         G   ","   G                         G   ","    G                       G    ","     G                     G     ","      G                   G      ","       GG               GG       ","         GG  DDDDDDD  GG         ","           GGGGC CGGGG           ","               C C               "},
                    {"            CCHHHHHCC            ","          GGGGDDDDDGGGG          ","        GG  DD     DD  GG        ","       G                 G       ","      G                   G      ","     G E                 E G     ","    G                       G    ","   G E                     E G   ","  G                           G  ","  G                           G  "," G                             G "," G                             G "," GD                           DG "," GD                           DG "," D                             D ","CD                             DC"," D                             D ","CD                             DC"," D                             D "," GD                           DG "," GD                           DG "," G                             G "," G                             G ","  G                           G  ","  G                           G  ","   G E                     E G   ","    G                       G    ","     G E                 E G     ","      G                   G      ","       G                 G       ","        GG  DD     DD  GG        ","          GGGGDDDDDGGGG          ","               C C               "},
                    {"            CHHHHHHHC            ","          GGGDDCDCDDGGG          ","        GG  D  EEE  D  GG        ","       G                 G       ","      C                   C      ","     G E                 E G     ","    C                       C    ","   G E                     E G   ","  G                           G  ","  G                           G  "," G                             G "," G                             G "," GD                           DG "," D                             D "," D                             D ","CCE                           ECC"," DE                           ED ","CCE                           ECC"," D                             D "," D                             D "," GD                           DG "," G                             G "," G                             G ","  G                           G  ","  G                           G  ","   G E                     E G   ","    C                       C    ","     G E                 E G     ","      C                   C      ","       G                 G       ","        GG  D  EEE  D  GG        ","          GGGDDCDCDDGGG          ","               C C               "},
                    {"            CHHFFFHHC            ","         CCCCDCCDCCDCCCC         ","       CCC  D EAAAE D  CCC       ","      CC                 CC      ","     CC                   CC     ","    CC E                 E CC    ","   CC                       CC   ","  CC E                     E CC  ","  C                           C  "," CC                           CC "," C                             C "," C                             C ","CCD                           DCC","CD                             DC","CCE                           ECC","CCA                           ACC","CDA                           ADC","CCA                           ACC","CCE                           ECC","CD                             DC","CCD                           DCC"," C                             C "," C                             C "," CC                           CC ","  C                           C  ","  CC E                     E CC  ","   CC                       CC   ","    CC E                 E CC    ","     CC                   CC     ","      CC                 CC      ","       CCC  D EAAAE D  CCC       ","         CCCCDCCDCCDCCCC         ","            CCCCCCCCC            "},
                    {"            CHHF~FHHC            ","             DDDDDDD             ","          DDD EAAAE DDD          ","        DD             DD        ","      CDBB             BBDC      ","      DB                 BD      ","    CDB                   BDC    ","    DB                     BD    ","   DB                       BD   ","   DB                       BD   ","  D                           D  ","  D                           D  ","  D                           D  "," D                             D "," DE                           ED ","CDA                           ADC"," DA                           AD ","CDA                           ADC"," DE                           ED "," D                             D ","  D                           D  ","  D                           D  ","  D                           D  ","   DB                       BD   ","   DB                       BD   ","    DB                     BD    ","    CDB                   BDC    ","      DB                 BD      ","      CDBB             BBDC      ","        DD             DD        ","          DDD EAAAE DDD          ","             DDDDDDD             ","               C C               "},
                    {"            CHHFFFHHC            ","         CCCCDCCDCCDCCCC         ","       CCC  D EAAAE D  CCC       ","      CC                 CC      ","     CC                   CC     ","    CC E                 E CC    ","   CC                       CC   ","  CC E                     E CC  ","  C                           C  "," CC                           CC "," C                             C "," C                             C ","CCD                           DCC","CD                             DC","CCE                           ECC","CCA                           ACC","CDA                           ADC","CCA                           ACC","CCE                           ECC","CD                             DC","CCD                           DCC"," C                             C "," C                             C "," CC                           CC ","  C                           C  ","  CC E                     E CC  ","   CC                       CC   ","    CC E                 E CC    ","     CC                   CC     ","      CC                 CC      ","       CCC  D EAAAE D  CCC       ","         CCCCDCCDCCDCCCC         ","            CCCCCCCCC            "},
                    {"            CHHHHHHHC            ","          GGGDDCDCDDGGG          ","        GG  D  EEE  D  GG        ","       G                 G       ","      C                   C      ","     G E                 E G     ","    C                       C    ","   G E                     E G   ","  G                           G  ","  G                           G  "," G                             G "," G                             G "," GD                           DG "," D                             D "," D                             D ","CCE                           ECC"," DE                           ED ","CCE                           ECC"," D                             D "," D                             D "," GD                           DG "," G                             G "," G                             G ","  G                           G  ","  G                           G  ","   G E                     E G   ","    C                       C    ","     G E                 E G     ","      C                   C      ","       G                 G       ","        GG  D  EEE  D  GG        ","          GGGDDCDCDDGGG          ","               C C               "},
                    {"            CCHHHHHCC            ","          GGGGDDDDDGGGG          ","        GG  DD     DD  GG        ","       G                 G       ","      G                   G      ","     G E                 E G     ","    G                       G    ","   G E                     E G   ","  G                           G  ","  G                           G  "," G                             G "," G                             G "," GD                           DG "," GD                           DG "," D                             D ","CD                             DC"," D                             D ","CD                             DC"," D                             D "," GD                           DG "," GD                           DG "," G                             G "," G                             G ","  G                           G  ","  G                           G  ","   G E                     E G   ","    G                       G    ","     G E                 E G     ","      G                   G      ","       G                 G       ","        GG  DD     DD  GG        ","          GGGGDDDDDGGGG          ","               C C               "},
                    {"             CCCCCCC             ","           GGGGC CGGGG           ","         GG  DDDDDDD  GG         ","       GG               GG       ","      G                   G      ","     G                     G     ","    G                       G    ","   G                         G   ","   G                         G   ","  G                           G  ","  G                           G  "," G                             G "," G                             G "," GD                           DG "," GD                           DG ","CCD                           DCC","  D                           D  ","CCD                           DCC"," GD                           DG "," GD                           DG "," G                             G "," G                             G ","  G                           G  ","  G                           G  ","   G                         G   ","   G                         G   ","    G                       G    ","     G                     G     ","      G                   G      ","       GG               GG       ","         GG  DDDDDDD  GG         ","           GGGGC CGGGG           ","               C C               "},
                    {"                                 ","            GGGC CGGG            ","         GGG    D    GGG         ","        G               G        ","      GG                 GG      ","     G                     G     ","    G                       G    ","    G                       G    ","   G                         G   ","  G                           G  ","  G                           G  ","  G                           G  "," G                             G "," G                             G "," G                             G "," C                             C ","  D                           D  "," C                             C "," G                             G "," G                             G "," G                             G ","  G                           G  ","  G                           G  ","  G                           G  ","   G                         G   ","    G                       G    ","    G                       G    ","     G                     G     ","      GG                 GG      ","        G               G        ","         GGG    D    GGG         ","            GGGC CGGG            ","                                 "},
                    {"                                 ","             GGC CGG             ","          GGG   D   GGG          ","        GG             GG        ","       G                 G       ","     GG                   GG     ","     G                     G     ","    G                       G    ","   G                         G   ","   G                         G   ","  G                           G  ","  G                           G  ","  G                           G  "," G                             G "," G                             G "," C                             C ","  D                           D  "," C                             C "," G                             G "," G                             G ","  G                           G  ","  G                           G  ","  G                           G  ","   G                         G   ","   G                         G   ","    G                       G    ","     G                     G     ","     GG                   GG     ","       G                 G       ","        GG             GG        ","          GGG   D   GGG          ","             GGC CGG             ","                                 "},
                    {"                                 ","               C C               ","           GGGGC CGGGG           ","         GG     D     GG         ","       GG       B       GG       ","      G                   G      ","     G                     G     ","    G                       G    ","    G                       G    ","   G                         G   ","   G                         G   ","  G                           G  ","  G                           G  ","  G                           G  ","  G                           G  "," CC                           CC ","   DB                       BD   "," CC                           CC ","  G                           G  ","  G                           G  ","  G                           G  ","  G                           G  ","   G                         G   ","   G                         G   ","    G                       G    ","    G                       G    ","     G                     G     ","      G                   G      ","       GG       B       GG       ","         GG     D     GG         ","           GGGGC CGGGG           ","               C C               ","                                 "},
                    {"                                 ","                                 ","             GGC CGG             ","          GGG   D   GGG          ","        GG      B      GG        ","      GG                 GG      ","     GG                   GG     ","     G                     G     ","    G                       G    ","    G                       G    ","   G                         G   ","   G                         G   ","   G                         G   ","  G                           G  ","  G                           G  ","  C                           C  ","   DB                       BD   ","  C                           C  ","  G                           G  ","  G                           G  ","   G                         G   ","   G                         G   ","   G                         G   ","    G                       G    ","    G                       G    ","     G                     G     ","     GG                   GG     ","      GG                 GG      ","        GG      B      GG        ","          GGG   D   GGG          ","             GGC CGG             ","                                 ","                                 "},
                    {"                                 ","                                 ","               C C               ","            GGGC CGGG            ","         GGG    D    GGG         ","       GG    EEEBEEE    GG       ","      G                   G      ","     G                     G     ","     G                     G     ","    G                       G    ","    G                       G    ","    G                       G    ","   G                         G   ","   G E                     E G   ","   G E                     E G   ","  CC E                     E CC  ","    DB                     BD    ","  CC E                     E CC  ","   G E                     E G   ","   G E                     E G   ","   G                         G   ","    G                       G    ","    G                       G    ","    G                       G    ","     G                     G     ","     G                     G     ","      G                   G      ","       GG    EEEBEEE    GG       ","         GGG    D    GGG         ","            GGGC CGGG            ","               C C               ","                                 ","                                 "},
                    {"                                 ","                                 ","                                 ","               C C               ","           GGGCCCCCGGG           ","        GGG     D     GGG        ","       GG       B       GG       ","      G                   G      ","     GG                   GG     ","     G                     G     ","     G                     G     ","    G                       G    ","    G                       G    ","    G                       G    ","    C                       C    ","   CC                       CC   ","    CDB                   BDC    ","   CC                       CC   ","    C                       C    ","    G                       G    ","    G                       G    ","    G                       G    ","     G                     G     ","     G                     G     ","     GG                   GG     ","      G                   G      ","       GG       B       GG       ","        GGG     D     GGG        ","           GGGCCCCCGGG           ","               C C               ","                                 ","                                 ","                                 "},
                    {"                                 ","                                 ","                                 ","                                 ","               C C               ","          GGGGGC CGGGGG          ","        GGG     D     GGG        ","       GG    EEEBEEE    GG       ","      GG                 GG      ","      G                   G      ","     GG                   GG     ","     G                     G     ","     G                     G     ","     G E                 E G     ","     G E                 E G     ","    CC E                 E CC    ","      DB                 BD      ","    CC E                 E CC    ","     G E                 E G     ","     G E                 E G     ","     G                     G     ","     G                     G     ","     GG                   GG     ","      G                   G      ","      GG                 GG      ","       GG    EEEBEEE    GG       ","        GGG     D     GGG        ","          GGGGGC CGGGGG          ","               C C               ","                                 ","                                 ","                                 ","                                 "},
                    {"                                 ","                                 ","                                 ","                                 ","                                 ","               C C               ","           GGGCCCCCGGG           ","         GGG    D    GGG         ","        GG      B      GG        ","       GG       B       GG       ","       G                 G       ","      GG                 GG      ","      G                   G      ","      G                   G      ","      C                   C      ","     CC                   CC     ","      CDBB             BBDC      ","     CC                   CC     ","      C                   C      ","      G                   G      ","      G                   G      ","      GG                 GG      ","       G                 G       ","       GG       B       GG       ","        GG      B      GG        ","         GGG    D    GGG         ","           GGGCCCCCGGG           ","               C C               ","                                 ","                                 ","                                 ","                                 ","                                 "},
                    {"                                 ","                                 ","                                 ","                                 ","                                 ","                                 ","               C C               ","            GGGC CGGG            ","          GGG   D   GGG          ","         GG     D     GG         ","        GG             GG        ","        G               G        ","       GG               GG       ","       G                 G       ","       G                 G       ","      CC                 CC      ","        DD             DD        ","      CC                 CC      ","       G                 G       ","       G                 G       ","       GG               GG       ","        G       D       G        ","        GG      D      GG        ","         GG     D     GG         ","          GGG   D   GGG          ","            GGGC CGGG            ","               C C               ","                                 ","                                 ","                                 ","                                 ","                                 ","                                 "},
                    {"                                 ","                                 ","                                 ","                                 ","                                 ","                                 ","                                 ","               C C               ","             GGC CGG             ","           GGGGC CGGGG           ","          GGG   D   GGG          ","         GGG    D    GGG         ","         GG  DDDDDDD  GG         ","        GG  DD     DD  GG        ","        GG  D  EEE  D  GG        ","       CCC  D EAAAE D  CCC       ","          DDD EAAAE DDD          ","       CCC  D EAAAE D  CCC       ","        GG  D  EEE  D  GG        ","        GG  DD     DD  GG        ","         GG  DDDDDDD  GG         ","         GGG    D    GGG         ","          GGG   D   GGG          ","           GGGGC CGGGG           ","             GGC CGG             ","               C C               ","                                 ","                                 ","                                 ","                                 ","                                 ","                                 ","                                 "},
                    {"                                 ","                                 ","                                 ","                                 ","                                 ","                                 ","                                 ","                                 ","                                 ","               C C               ","             GGC CGG             ","            GGGC CGGG            ","           GGGGC CGGGG           ","          GGGGDDDDDGGGG          ","          GGGDDCDCDDGGG          ","         CCCCDCCDCCDCCCC         ","             DDDDDDD             ","         CCCCDCCDCCDCCCC         ","          GGGDDCDCDDGGG          ","          GGGGDDDDDGGGG          ","           GGGGC CGGGG           ","            GGGC CGGG            ","             GGC CGG             ","               C C               ","                                 ","                                 ","                                 ","                                 ","                                 ","                                 ","                                 ","                                 ","                                 "},
                    {"                                 ","                                 ","                                 ","                                 ","                                 ","                                 ","                                 ","                                 ","                                 ","                                 ","                                 ","                                 ","               C C               ","               C C               ","               C C               ","            CCCCCCCCC            ","               C C               ","            CCCCCCCCC            ","               C C               ","               C C               ","               C C               ","                                 ","                                 ","                                 ","                                 ","                                 ","                                 ","                                 ","                                 ","                                 ","                                 ","                                 ","                                 "}
            }))
            .addElement('A', ofBlock(sBlockCasingsTT, 10))
            .addElement('B', ofBlock(sBlockCasingsTT, 11))
            .addElement('C', ofBlock(sBlockCasingsTT, 12))
            .addElement('D', ofBlock(sBlockCasingsTT, 13))
            .addElement('E', ofBlock(sBlockCasingsTT, 14))
            .addElement('F', ofHatchAdderOptional(GT_MetaTileEntity_EM_bhg::addElementalToMachineList, textureOffset + 4, 2, sBlockCasingsTT, 4))
            .addElement('G', ofBlock(QuantumGlassBlock.INSTANCE, 0))
            .addElement('H', ofHatchAdderOptional(GT_MetaTileEntity_EM_bhg::addClassicToMachineList, textureOffset, 1, sBlockCasingsTT, 0))
            .build();

//    private static final IStructureDefinition<GT_MetaTileEntity_EM_bhg> STRUCTURE_DEFINITION= StructureDefinition
//            .<GT_MetaTileEntity_EM_bhg>builder()
//            .addShape("t1",new String[][]{
//                    {"\u000B", "M0000000", "L00     00", "L0       0", "L0  !!!  0", "L0  !.!  0", "L0  !!!  0", "L0       0", "L00     00", "M0000000",},
//                    {"\u0008", "O0A0", "O0A0", "O0A0", "O0A0", "N11111", "M1101011", "I000010010010000", "M1111111", "I000010010010000", "M1101011", "N11111", "O0A0", "O0A0", "O0A0", "O0A0",},
//                    {"\u0006", "O0A0", "O0A0", "O0A0", "P1", "P1", "M1111111", "L11E11", "L1B222B1", "G000B1A23332A1B000", "J111A23332A111", "G000B1A23332A1B000", "L1B222B1", "L11E11", "M1111111", "P1", "P1", "O0A0", "O0A0", "O0A0",},
//                    {"\u0005", "O0A0", "O0A0", "P1", "P1", "\u0004", "F00Q00", "H11M11", "F00Q00", "\u0004", "P1", "P1", "O0A0", "O0A0",},
//                    {"\u0004", "O0A0", "N00000", "P1", "P4", "P4", "\u0003", "F0S0", "E00S00", "F0144M4410", "E00S00", "F0S0", "\u0003", "P4", "P4", "P1", "N00000", "O0A0",},
//                    {"\u0003", "O0A0", "O0A0", "P1", "M2224222", "\u0004", "G2Q2", "G2Q2", "D00A2Q2A00", "F14Q41", "D00A2Q2A00", "G2Q2", "G2Q2", "\u0004", "M2224222", "P1", "O0A0", "O0A0",},
//                    {"\u0002", "O0A0", "N00000", "P1", "P4", "\u0006", "D0W0", "C00W00", "D014S410", "C00W00", "D0W0", "\u0006", "P4", "P1", "N00000", "O0A0",},
//                    {"\u0001", "O0A0", "O0A0", "P1", "M2224222", "\u0006", "E2U2", "E2U2", "B00A2U2A00", "D14U41", "B00A2U2A00", "E2U2", "E2U2", "\u0006", "M2224222", "P1", "O0A0", "O0A0",},
//                    {"\u0001", "O0A0", "P1", "P4", "\u0009", "B0[0", "C14W41", "B0[0", "\u0009", "P4", "P1", "O0A0",},
//                    {E, "O0A0", "O0A0", "P1", "P4", "\u0009", "A00[00", "C14W41", "A00[00", "\u0009", "P4", "P1", "O0A0", "O0A0",},
//                    {E, "O0A0", "P1", "\u000B", "A0]0", "B1[1", "A0]0", "\u000B", "P1", "O0A0",},
//                    {E, "O0A0", "P1", "\u000B", "A0]0", "B1[1", "A0]0", "\u000B", "P1", "O0A0",},
//                    {"O0A0", "O0A0", "M1111111", "\u0009", "B1[1", "B1[1", "001[100", "B1[1", "001[100", "B1[1", "B1[1", "\u0009", "M1111111", "O0A0", "O0A0",},
//                    {"O0A0", "N11111", "L11E11", "\u0001", "G2Q2", E, "E2U2", "\u0003", "B1[1", "B1[1", "A1]1", "01]10", "A1]1", "01]10", "A1]1", "B1[1", "B1[1", "\u0003", "E2U2", E, "G2Q2", "\u0001", "L11E11", "N11111", "O0A0",},
//                    {"O0A0", "M1101011", "L1B222B1", E, "F0S0", "G2Q2", "D0W0", "E2U2", "\u0003", "B1[1", "A1]1", "A1]1", "002[200", "A12[21", "002[200", "A1]1", "A1]1", "B1[1", "\u0003", "E2U2", "D0W0", "G2Q2", "F0S0", E, "L1B222B1", "M1101011", "O0A0",},
//                    {"L000000000", "I000010010010000", "G000B1A23332A1B000", "F00Q00", "E00S00", "D00A2Q2A00", "C00W00", "B00A2U2A00", "B0[0", "A00[00", "A0]0", "A0]0", "001[100", "01]10", "002[200", "003[300", "013[310", "003[300", "002[200", "01]10", "001[100", "A0]0", "A0]0", "A00[00", "B0[0", "B00A2U2A00", "C00W00", "D00A2Q2A00", "E00S00", "F00Q00", "G000B1A23332A1B000", "I000010010010000", "L000000000",},
//                    {"O0A0", "M1111111", "J111A23332A111", "H11M11", "F0144M4410", "F14Q41", "D014S410", "D14U41", "C14W41", "C14W41", "B1[1", "B1[1", "B1[1", "A1]1", "A12[21", "013[310", "A13[31", "013[310", "A12[21", "A1]1", "B1[1", "B1[1", "B1[1", "C14W41", "C14W41", "D14U41", "D014S410", "F14Q41", "F0144M4410", "H11M11", "J111A23332A111", "M1111111", "O0A0",},
//                    {"L000000000", "I000010010010000", "G000B1A23332A1B000", "F00Q00", "E00S00", "D00A2Q2A00", "C00W00", "B00A2U2A00", "B0[0", "A00[00", "A0]0", "A0]0", "001[100", "01]10", "002[200", "003[300", "013[310", "003[300", "002[200", "01]10", "001[100", "A0]0", "A0]0", "A00[00", "B0[0", "B00A2U2A00", "C00W00", "D00A2Q2A00", "E00S00", "F00Q00", "G000B1A23332A1B000", "I000010010010000", "L000000000",},
//                    {"O0A0", "M1101011", "L1B222B1", E, "F0S0", "G2Q2", "D0W0", "E2U2", "\u0003", "B1[1", "A1]1", "A1]1", "002[200", "A12[21", "002[200", "A1]1", "A1]1", "B1[1", "\u0003", "E2U2", "D0W0", "G2Q2", "F0S0", E, "L1B222B1", "M1101011", "O0A0",},
//                    {"O0A0", "N11111", "L11E11", "\u0001", "G2Q2", E, "E2U2", "\u0003", "B1[1", "B1[1", "A1]1", "01]10", "A1]1", "01]10", "A1]1", "B1[1", "B1[1", "\u0003", "E2U2", E, "G2Q2", "\u0001", "L11E11", "N11111", "O0A0",},
//                    {"O0A0", "O0A0", "M1111111", "\u0009", "B1[1", "B1[1", "001[100", "B1[1", "001[100", "B1[1", "B1[1", "\u0009", "M1111111", "O0A0", "O0A0",},
//                    {E, "O0A0", "P1", "\u000B", "A0]0", "B1[1", "A0]0", "\u000B", "P1", "O0A0",},
//                    {E, "O0A0", "P1", "\u000B", "A0]0", "B1[1", "A0]0", "\u000B", "P1", "O0A0",},
//                    {E, "O0A0", "O0A0", "P1", "P4", "\u0009", "A00[00", "C14W41", "A00[00", "\u0009", "P4", "P1", "O0A0", "O0A0",},
//                    {"\u0001", "O0A0", "P1", "P4", "\u0009", "B0[0", "C14W41", "B0[0", "\u0009", "P4", "P1", "O0A0",},
//                    {"\u0001", "O0A0", "O0A0", "P1", "M2224222", "\u0006", "E2U2", "E2U2", "B00A2U2A00", "D14U41", "B00A2U2A00", "E2U2", "E2U2", "\u0006", "M2224222", "P1", "O0A0", "O0A0",},
//                    {"\u0002", "O0A0", "N00000", "P1", "P4", "\u0006", "D0W0", "C00W00", "D014S410", "C00W00", "D0W0", "\u0006", "P4", "P1", "N00000", "O0A0",},
//                    {"\u0003", "O0A0", "O0A0", "P1", "M2224222", "\u0004", "G2Q2", "G2Q2", "D00A2Q2A00", "F14Q41", "D00A2Q2A00", "G2Q2", "G2Q2", "\u0004", "M2224222", "P1", "O0A0", "O0A0",},
//                    {"\u0004", "O0A0", "N00000", "P1", "P4", "P4", "\u0003", "F0S0", "E00S00", "F0144M4410", "E00S00", "F0S0", "\u0003", "P4", "P4", "P1", "N00000", "O0A0",},
//                    {"\u0005", "O0A0", "O0A0", "P1", "P1", "\u0004", "F00Q00", "H11M11", "F00Q00", "\u0004", "P1", "P1", "O0A0", "O0A0",},
//                    {"\u0006", "O0A0", "O0A0", "O0A0", "P1", "P1", "M1111111", "L11E11", "L1B222B1", "G000B1A23332A1B000", "J111A23332A111", "G000B1A23332A1B000", "L1B222B1", "L11E11", "M1111111", "P1", "P1", "O0A0", "O0A0", "O0A0",},
//                    {"\u0008", "O0A0", "O0A0", "O0A0", "O0A0", "N11111", "M1101011", "I000010010010000", "M1111111", "I000010010010000", "M1101011", "N11111", "O0A0", "O0A0", "O0A0", "O0A0",},
//                    {"\u000B", "O0A0", "O0A0", "O0A0", "L000000000", "O0A0", "L000000000", "O0A0", "O0A0", "O0A0",},
//            })
//            .addShape("t2",new String[][]{
//                    {"\u000B", "M0000000", "L00     00", "L0       0", "L0  !!!  0", "L0  !.!  0", "L0  !!!  0", "L0       0", "L00     00", "M0000000",},
//                    {"\u0008", "O0A0", "M550A055", "L5550A0555", "K55550A05555", "J5555111115555", "J5551101011555", "I000010010010000", "M1111111", "I000010010010000", "J5551101011555", "J5555111115555", "K55550A05555", "L5550A0555", "M550A055", "O0A0",},
//                    {"\u0006", "O0A0", "M550A055", "K55550A05555", "J555C1C555", "I555D1D555", "I55B1111111B55", "H55B11E11B55", "H55B1B222B1B55", "G000B1A23332A1B000", "J111A23332A111", "G000B1A23332A1B000", "H55B1B222B1B55", "H55B11E11B55", "I55B1111111B55", "I555D1D555", "J555C1C555", "K55550A05555", "M550A055", "O0A0",},
//                    {"\u0005", "O0A0", "L5550A0555", "J555C1C555", "I55E1E55", "H55M55", "H5O5", "G55O55", "G5Q5", "G5Q5", "F00Q00", "H11M11", "F00Q00", "G5Q5", "G5Q5", "G55O55", "H5O5", "H55M55", "I55E1E55", "J555C1C555", "L5550A0555", "O0A0",},
//                    {"\u0004", "O0A0", "K55500000555", "I555D1D555", "H55F4F55", "G55G4G55", "G5Q5", "F55Q55", "F5S5", "F5S5", "F0S0", "E00S00", "F0144M4410", "E00S00", "F0S0", "F5S5", "F5S5", "F55Q55", "G5Q5", "G55G4G55", "H55F4F55", "I555D1D555", "K55500000555", "O0A0",},
//                    {"\u0003", "O0A0", "J555550A055555", "H555E1E555", "G55D2224222D55", "F55Q55", "F5S5", "E55S55", "E5U5", "E5U5", "E5A2Q2A5", "E5A2Q2A5", "D00A2Q2A00", "F14Q41", "D00A2Q2A00", "E5A2Q2A5", "E5A2Q2A5", "E5U5", "E5U5", "E55S55", "F5S5", "F55Q55", "G55D2224222D55", "H555E1E555", "J555550A055555", "O0A0",},
//                    {"\u0002", "O0A0", "K55500000555", "H555E1E555", "G55G4G55", "F5S5", "E55S55", "E5U5", "E5U5", "D5W5", "D5W5", "D5W5", "D0W0", "C00W00", "D014S410", "C00W00", "D0W0", "D5W5", "D5W5", "D5W5", "E5U5", "E5U5", "E55S55", "F5S5", "G55G4G55", "H555E1E555", "K55500000555", "O0A0",},
//                    {"\u0001", "O0A0", "L5550A0555", "I555D1D555", "G55D2224222D55", "F5S5", "E5U5", "E5U5", "D5W5", "D5W5", "D5W5", "C5Y5", "C5A2U2A5", "C5A2U2A5", "B00A2U2A00", "D14U41", "B00A2U2A00", "C5A2U2A5", "C5A2U2A5", "C5Y5", "D5W5", "D5W5", "D5W5", "E5U5", "E5U5", "F5S5", "G55D2224222D55", "I555D1D555", "L5550A0555", "O0A0",},
//                    {"\u0001", "M550A055", "J555C1C555", "H55F4F55", "F55Q55", "E55S55", "E5U5", "D5W5", "D5W5", "C5Y5", "C5Y5", "C5Y5", "B5[5", "B5[5", "B0[0", "C14W41", "B0[0", "B5[5", "B5[5", "C5Y5", "C5Y5", "C5Y5", "D5W5", "D5W5", "E5U5", "E55S55", "F55Q55", "H55F4F55", "J555C1C555", "M550A055",},
//                    {E, "O0A0", "K55550A05555", "I55E1E55", "G55G4G55", "F5S5", "E5U5", "D5W5", "D5W5", "C5Y5", "C5Y5", "B5[5", "B5[5", "B5[5", "B5[5", "A00[00", "C14W41", "A00[00", "B5[5", "B5[5", "B5[5", "B5[5", "C5Y5", "C5Y5", "D5W5", "D5W5", "E5U5", "F5S5", "G55G4G55", "I55E1E55", "K55550A05555", "O0A0",},
//                    {E, "M550A055", "J555C1C555", "H55M55", "G5Q5", "E55S55", "E5U5", "D5W5", "C5Y5", "C5Y5", "B5[5", "B5[5", "B5[5", "A5]5", "A5]5", "A0]0", "B1[1", "A0]0", "A5]5", "A5]5", "B5[5", "B5[5", "B5[5", "C5Y5", "C5Y5", "D5W5", "E5U5", "E55S55", "G5Q5", "H55M55", "J555C1C555", "M550A055",},
//                    {E, "L5550A0555", "I555D1D555", "H5O5", "F55Q55", "E5U5", "D5W5", "D5W5", "C5Y5", "B5[5", "B5[5", "B5[5", "A5]5", "A5]5", "A5]5", "A0]0", "B1[1", "A0]0", "A5]5", "A5]5", "A5]5", "B5[5", "B5[5", "B5[5", "C5Y5", "D5W5", "D5W5", "E5U5", "F55Q55", "H5O5", "I555D1D555", "L5550A0555",},
//                    {"O0A0", "K55550A05555", "I55B1111111B55", "G55O55", "F5S5", "E5U5", "D5W5", "C5Y5", "C5Y5", "B5[5", "B5[5", "A5]5", "A5]5", "A51[15", "A51[15", "001[100", "B1[1", "001[100", "A51[15", "A51[15", "A5]5", "A5]5", "B5[5", "B5[5", "C5Y5", "C5Y5", "D5W5", "E5U5", "F5S5", "G55O55", "I55B1111111B55", "K55550A05555", "O0A0",},
//                    {"O0A0", "J5555111115555", "H55B11E11B55", "G5Q5", "F5S5", "E5A2Q2A5", "D5W5", "C5A2U2A5", "B5[5", "B5[5", "A5]5", "A5]5", "A51[15", "A51[15", "A1]1", "01]10", "A1]1", "01]10", "A1]1", "A51[15", "A51[15", "A5]5", "A5]5", "B5[5", "B5[5", "C5A2U2A5", "D5W5", "E5A2Q2A5", "F5S5", "G5Q5", "H55B11E11B55", "J5555111115555", "O0A0",},
//                    {"O0A0", "J5551101011555", "H55B1B222B1B55", "G5Q5", "F0S0", "E5A2Q2A5", "D0W0", "C5A2U2A5", "B5[5", "B5[5", "A5]5", "A5]5", "A51[15", "A1]1", "A1]1", "002[200", "A12[21", "002[200", "A1]1", "A1]1", "A51[15", "A5]5", "A5]5", "B5[5", "B5[5", "C5A2U2A5", "D0W0", "E5A2Q2A5", "F0S0", "G5Q5", "H55B1B222B1B55", "J5551101011555", "O0A0",},
//                    {"L000000000", "I000010010010000", "G000B1A23332A1B000", "F00Q00", "E00S00", "D00A2Q2A00", "C00W00", "B00A2U2A00", "B0[0", "A00[00", "A0]0", "A0]0", "001[100", "01]10", "002[200", "003[300", "013[310", "003[300", "002[200", "01]10", "001[100", "A0]0", "A0]0", "A00[00", "B0[0", "B00A2U2A00", "C00W00", "D00A2Q2A00", "E00S00", "F00Q00", "G000B1A23332A1B000", "I000010010010000", "L000000000",},
//                    {"O0A0", "M1111111", "J111A23332A111", "H11M11", "F0144M4410", "F14Q41", "D014S410", "D14U41", "C14W41", "C14W41", "B1[1", "B1[1", "B1[1", "A1]1", "A12[21", "013[310", "A13[31", "013[310", "A12[21", "A1]1", "B1[1", "B1[1", "B1[1", "C14W41", "C14W41", "D14U41", "D014S410", "F14Q41", "F0144M4410", "H11M11", "J111A23332A111", "M1111111", "O0A0",},
//                    {"L000000000", "I000010010010000", "G000B1A23332A1B000", "F00Q00", "E00S00", "D00A2Q2A00", "C00W00", "B00A2U2A00", "B0[0", "A00[00", "A0]0", "A0]0", "001[100", "01]10", "002[200", "003[300", "013[310", "003[300", "002[200", "01]10", "001[100", "A0]0", "A0]0", "A00[00", "B0[0", "B00A2U2A00", "C00W00", "D00A2Q2A00", "E00S00", "F00Q00", "G000B1A23332A1B000", "I000010010010000", "L000000000",},
//                    {"O0A0", "J5551101011555", "H55B1B222B1B55", "G5Q5", "F0S0", "E5A2Q2A5", "D0W0", "C5A2U2A5", "B5[5", "B5[5", "A5]5", "A5]5", "A51[15", "A1]1", "A1]1", "002[200", "A12[21", "002[200", "A1]1", "A1]1", "A51[15", "A5]5", "A5]5", "B5[5", "B5[5", "C5A2U2A5", "D0W0", "E5A2Q2A5", "F0S0", "G5Q5", "H55B1B222B1B55", "J5551101011555", "O0A0",},
//                    {"O0A0", "J5555111115555", "H55B11E11B55", "G5Q5", "F5S5", "E5A2Q2A5", "D5W5", "C5A2U2A5", "B5[5", "B5[5", "A5]5", "A5]5", "A51[15", "A51[15", "A1]1", "01]10", "A1]1", "01]10", "A1]1", "A51[15", "A51[15", "A5]5", "A5]5", "B5[5", "B5[5", "C5A2U2A5", "D5W5", "E5A2Q2A5", "F5S5", "G5Q5", "H55B11E11B55", "J5555111115555", "O0A0",},
//                    {"O0A0", "K55550A05555", "I55B1111111B55", "G55O55", "F5S5", "E5U5", "D5W5", "C5Y5", "C5Y5", "B5[5", "B5[5", "A5]5", "A5]5", "A51[15", "A51[15", "001[100", "B1[1", "001[100", "A51[15", "A51[15", "A5]5", "A5]5", "B5[5", "B5[5", "C5Y5", "C5Y5", "D5W5", "E5U5", "F5S5", "G55O55", "I55B1111111B55", "K55550A05555", "O0A0",},
//                    {E, "L5550A0555", "I555D1D555", "H5O5", "F55Q55", "E5U5", "D5W5", "D5W5", "C5Y5", "B5[5", "B5[5", "B5[5", "A5]5", "A5]5", "A5]5", "A0]0", "B1[1", "A0]0", "A5]5", "A5]5", "A5]5", "B5[5", "B5[5", "B5[5", "C5Y5", "D5W5", "D5W5", "E5U5", "F55Q55", "H5O5", "I555D1D555", "L5550A0555",},
//                    {E, "M550A055", "J555C1C555", "H55M55", "G5Q5", "E55S55", "E5U5", "D5W5", "C5Y5", "C5Y5", "B5[5", "B5[5", "B5[5", "A5]5", "A5]5", "A0]0", "B1[1", "A0]0", "A5]5", "A5]5", "B5[5", "B5[5", "B5[5", "C5Y5", "C5Y5", "D5W5", "E5U5", "E55S55", "G5Q5", "H55M55", "J555C1C555", "M550A055",},
//                    {E, "O0A0", "K55550A05555", "I55E1E55", "G55G4G55", "F5S5", "E5U5", "D5W5", "D5W5", "C5Y5", "C5Y5", "B5[5", "B5[5", "B5[5", "B5[5", "A00[00", "C14W41", "A00[00", "B5[5", "B5[5", "B5[5", "B5[5", "C5Y5", "C5Y5", "D5W5", "D5W5", "E5U5", "F5S5", "G55G4G55", "I55E1E55", "K55550A05555", "O0A0",},
//                    {"\u0001", "M550A055", "J555C1C555", "H55F4F55", "F55Q55", "E55S55", "E5U5", "D5W5", "D5W5", "C5Y5", "C5Y5", "C5Y5", "B5[5", "B5[5", "B0[0", "C14W41", "B0[0", "B5[5", "B5[5", "C5Y5", "C5Y5", "C5Y5", "D5W5", "D5W5", "E5U5", "E55S55", "F55Q55", "H55F4F55", "J555C1C555", "M550A055",},
//                    {"\u0001", "O0A0", "L5550A0555", "I555D1D555", "G55D2224222D55", "F5S5", "E5U5", "E5U5", "D5W5", "D5W5", "D5W5", "C5Y5", "C5A2U2A5", "C5A2U2A5", "B00A2U2A00", "D14U41", "B00A2U2A00", "C5A2U2A5", "C5A2U2A5", "C5Y5", "D5W5", "D5W5", "D5W5", "E5U5", "E5U5", "F5S5", "G55D2224222D55", "I555D1D555", "L5550A0555", "O0A0",},
//                    {"\u0002", "O0A0", "K55500000555", "H555E1E555", "G55G4G55", "F5S5", "E55S55", "E5U5", "E5U5", "D5W5", "D5W5", "D5W5", "D0W0", "C00W00", "D014S410", "C00W00", "D0W0", "D5W5", "D5W5", "D5W5", "E5U5", "E5U5", "E55S55", "F5S5", "G55G4G55", "H555E1E555", "K55500000555", "O0A0",},
//                    {"\u0003", "O0A0", "J555550A055555", "H555E1E555", "G55D2224222D55", "F55Q55", "F5S5", "E55S55", "E5U5", "E5U5", "E5A2Q2A5", "E5A2Q2A5", "D00A2Q2A00", "F14Q41", "D00A2Q2A00", "E5A2Q2A5", "E5A2Q2A5", "E5U5", "E5U5", "E55S55", "F5S5", "F55Q55", "G55D2224222D55", "H555E1E555", "J555550A055555", "O0A0",},
//                    {"\u0004", "O0A0", "K55500000555", "I555D1D555", "H55F4F55", "G55G4G55", "G5Q5", "F55Q55", "F5S5", "F5S5", "F0S0", "E00S00", "F0144M4410", "E00S00", "F0S0", "F5S5", "F5S5", "F55Q55", "G5Q5", "G55G4G55", "H55F4F55", "I555D1D555", "K55500000555", "O0A0",},
//                    {"\u0005", "O0A0", "L5550A0555", "J555C1C555", "I55E1E55", "H55M55", "H5O5", "G55O55", "G5Q5", "G5Q5", "F00Q00", "H11M11", "F00Q00", "G5Q5", "G5Q5", "G55O55", "H5O5", "H55M55", "I55E1E55", "J555C1C555", "L5550A0555", "O0A0",},
