package com.github.technus.tectech.thing.metaTileEntity.multi;

import static com.github.technus.tectech.TecTech.eyeOfHarmonyRecipeStorage;
import static com.github.technus.tectech.thing.casing.GT_Block_CasingsTT.textureOffset;
import static com.github.technus.tectech.thing.casing.GT_Block_CasingsTT.texturePage;
import static com.github.technus.tectech.thing.casing.TT_Container_Casings.eyeOfHarmonyRenderBlock;
import static com.github.technus.tectech.thing.casing.TT_Container_Casings.sBlockCasingsBA0;
import static com.gtnewhorizon.structurelib.structure.StructureUtility.*;
import static gregtech.api.enums.GT_Values.AuthorColen;
import static gregtech.api.util.GT_StructureUtility.ofHatchAdderOptional;
import static gregtech.api.util.GT_Utility.formatNumbers;
import static java.lang.Math.*;
import static net.minecraft.util.EnumChatFormatting.*;

import appeng.util.ReadableNumberConverter;
import com.github.technus.tectech.recipe.EyeOfHarmonyRecipe;
import com.github.technus.tectech.thing.block.TileEyeOfHarmony;
import com.github.technus.tectech.thing.casing.TT_Container_Casings;
import com.github.technus.tectech.thing.metaTileEntity.multi.base.GT_MetaTileEntity_MultiblockBase_EM;
import com.github.technus.tectech.thing.metaTileEntity.multi.base.render.TT_RenderedExtendedFacingTexture;
import com.github.technus.tectech.util.CommonValues;
import com.github.technus.tectech.util.ItemStackLong;
import com.google.common.collect.ImmutableList;
import com.gtnewhorizon.structurelib.alignment.constructable.IConstructable;
import com.gtnewhorizon.structurelib.alignment.constructable.ISurvivalConstructable;
import com.gtnewhorizon.structurelib.structure.IItemSource;
import com.gtnewhorizon.structurelib.structure.IStructureDefinition;
import cpw.mods.fml.relauncher.Side;
import cpw.mods.fml.relauncher.SideOnly;
import gregtech.api.enums.Materials;
import gregtech.api.enums.Textures;
import gregtech.api.interfaces.IGlobalWirelessEnergy;
import gregtech.api.interfaces.ITexture;
import gregtech.api.interfaces.metatileentity.IMetaTileEntity;
import gregtech.api.interfaces.tileentity.IGregTechTileEntity;
import gregtech.api.metatileentity.implementations.GT_MetaTileEntity_Hatch_Input;
import gregtech.api.metatileentity.implementations.GT_MetaTileEntity_Hatch_Output;
import gregtech.api.metatileentity.implementations.GT_MetaTileEntity_Hatch_OutputBus;
import gregtech.api.util.GT_Multiblock_Tooltip_Builder;
import gregtech.common.tileentities.machines.GT_MetaTileEntity_Hatch_OutputBus_ME;
import gregtech.common.tileentities.machines.GT_MetaTileEntity_Hatch_Output_ME;
import java.util.*;
import java.util.List;
import net.minecraft.client.renderer.texture.IIconRegister;
import net.minecraft.entity.player.EntityPlayerMP;
import net.minecraft.init.Blocks;
import net.minecraft.item.ItemStack;
import net.minecraft.nbt.NBTTagCompound;
import net.minecraft.util.EnumChatFormatting;
import net.minecraftforge.fluids.FluidStack;
import org.apache.commons.lang3.tuple.Pair;
import org.spongepowered.libraries.com.google.common.math.LongMath;

@SuppressWarnings("SpellCheckingInspection")
public class GT_MetaTileEntity_EM_EyeOfHarmony extends GT_MetaTileEntity_MultiblockBase_EM
        implements IConstructable, IGlobalWirelessEnergy, ISurvivalConstructable {

    private static final boolean EOH_DEBUG_MODE = false;

    // Region variables.
    private static Textures.BlockIcons.CustomIcon ScreenOFF;
    private static Textures.BlockIcons.CustomIcon ScreenON;

    private int spacetimeCompressionFieldMetadata = -1;
    private int timeAccelerationFieldMetadata = -1;
    private int stabilisationFieldMetadata = -1;

    private static final double SPACETIME_CASING_DIFFERENCE_DISCOUNT_PERCENTAGE = 0.03;

    private String userUUID = "";
    private String userName = "";
    private long euOutput = 0;

    @Override
    public int survivalConstruct(ItemStack stackSize, int elementBudget, IItemSource source, EntityPlayerMP actor) {
        if (mMachine) return -1;
        int realBudget = elementBudget >= 200
                ? elementBudget
                : Math.min(200, elementBudget * 5); // 200 blocks max per placement.
        return survivialBuildPiece(STRUCTURE_PIECE_MAIN, stackSize, 16, 16, 0, realBudget, source, actor, false, true);
    }

    protected static final String STRUCTURE_PIECE_MAIN = "main";

    // Multiblock structure.
    private static final IStructureDefinition<GT_MetaTileEntity_EM_EyeOfHarmony> STRUCTURE_DEFINITION =
            IStructureDefinition.<GT_MetaTileEntity_EM_EyeOfHarmony>builder()
                    .addShape(STRUCTURE_PIECE_MAIN, transpose(new String[][] {
                        {
                            "                                 ",
                            "                                 ",
                            "                                 ",
                            "                                 ",
                            "                                 ",
                            "                                 ",
                            "                                 ",
                            "                                 ",
                            "                                 ",
                            "                                 ",
                            "                                 ",
                            "                                 ",
                            "               C C               ",
                            "               C C               ",
                            "               C C               ",
                            "            CCCCCCCCC            ",
                            "               C C               ",
                            "            CCCCCCCCC            ",
                            "               C C               ",
                            "               C C               ",
                            "               C C               ",
                            "                                 ",
                            "                                 ",
                            "                                 ",
                            "                                 ",
                            "                                 ",
                            "                                 ",
                            "                                 ",
                            "                                 ",
                            "                                 ",
                            "                                 ",
                            "                                 ",
                            "                                 "
                        },
                        {
                            "                                 ",
                            "                                 ",
                            "                                 ",
                            "                                 ",
                            "                                 ",
                            "                                 ",
                            "                                 ",
                            "                                 ",
                            "                                 ",
                            "               C C               ",
                            "               C C               ",
                            "               C C               ",
                            "               C C               ",
                            "              DDDDD              ",
                            "             DDCDCDD             ",
                            "         CCCCDCCDCCDCCCC         ",
                            "             DDDDDDD             ",
                            "         CCCCDCCDCCDCCCC         ",
                            "             DDCDCDD             ",
                            "              DDDDD              ",
                            "               C C               ",
                            "               C C               ",
                            "               C C               ",
                            "               C C               ",
                            "                                 ",
                            "                                 ",
                            "                                 ",
                            "                                 ",
                            "                                 ",
                            "                                 ",
                            "                                 ",
                            "                                 ",
                            "                                 "
                        },
                        {
                            "                                 ",
                            "                                 ",
                            "                                 ",
                            "                                 ",
                            "                                 ",
                            "                                 ",
                            "                                 ",
                            "               C C               ",
                            "               C C               ",
                            "               C C               ",
                            "                D                ",
                            "                D                ",
                            "             DDDDDDD             ",
                            "            DD     DD            ",
                            "            D  EEE  D            ",
                            "       CCC  D EAAAE D  CCC       ",
                            "          DDD EAAAE DDD          ",
                            "       CCC  D EAAAE D  CCC       ",
                            "            D  EEE  D            ",
                            "            DD     DD            ",
                            "             DDDDDDD             ",
                            "                D                ",
                            "                D                ",
                            "               C C               ",
                            "               C C               ",
                            "               C C               ",
                            "                                 ",
                            "                                 ",
                            "                                 ",
                            "                                 ",
                            "                                 ",
                            "                                 ",
                            "                                 "
                        },
                        {
                            "                                 ",
                            "                                 ",
                            "                                 ",
                            "                                 ",
                            "                                 ",
                            "                                 ",
                            "               C C               ",
                            "               C C               ",
                            "                D                ",
                            "                D                ",
                            "                                 ",
                            "                                 ",
                            "                                 ",
                            "                                 ",
                            "                                 ",
                            "      CC                 CC      ",
                            "        DD             DD        ",
                            "      CC                 CC      ",
                            "                                 ",
                            "                                 ",
                            "                                 ",
                            "                                 ",
                            "                                 ",
                            "                D                ",
                            "                D                ",
                            "               C C               ",
                            "               C C               ",
                            "                                 ",
                            "                                 ",
                            "                                 ",
                            "                                 ",
                            "                                 ",
                            "                                 "
                        },
                        {
                            "                                 ",
                            "                                 ",
                            "                                 ",
                            "                                 ",
                            "                                 ",
                            "               C C               ",
                            "              CCCCC              ",
                            "                D                ",
                            "                A                ",
                            "                A                ",
                            "                                 ",
                            "                                 ",
                            "                                 ",
                            "                                 ",
                            "      C                   C      ",
                            "     CC                   CC     ",
                            "      CDAA             AADC      ",
                            "     CC                   CC     ",
                            "      C                   C      ",
                            "                                 ",
                            "                                 ",
                            "                                 ",
                            "                                 ",
                            "                A                ",
                            "                A                ",
                            "                D                ",
                            "              CCCCC              ",
                            "               C C               ",
                            "                                 ",
                            "                                 ",
                            "                                 ",
                            "                                 ",
                            "                                 "
                        },
                        {
                            "                                 ",
                            "                                 ",
                            "                                 ",
                            "                                 ",
                            "               C C               ",
                            "               C C               ",
                            "                D                ",
                            "             SEEAEES             ",
                            "                                 ",
                            "                                 ",
                            "                                 ",
                            "                                 ",
                            "                                 ",
                            "       S                 S       ",
                            "       E                 E       ",
                            "    CC E                 E CC    ",
                            "      DA                 AD      ",
                            "    CC E                 E CC    ",
                            "       E                 E       ",
                            "       S                 S       ",
                            "                                 ",
                            "                                 ",
                            "                                 ",
                            "                                 ",
                            "                                 ",
                            "             SEEAEES             ",
                            "                D                ",
                            "               C C               ",
                            "               C C               ",
                            "                                 ",
                            "                                 ",
                            "                                 ",
                            "                                 "
                        },
                        {
                            "                                 ",
                            "                                 ",
                            "                                 ",
                            "               C C               ",
                            "              CCCCC              ",
                            "                D                ",
                            "                A                ",
                            "                                 ",
                            "                                 ",
                            "                                 ",
                            "                                 ",
                            "                                 ",
                            "                                 ",
                            "                                 ",
                            "    C                       C    ",
                            "   CC                       CC   ",
                            "    CDA                   ADC    ",
                            "   CC                       CC   ",
                            "    C                       C    ",
                            "                                 ",
                            "                                 ",
                            "                                 ",
                            "                                 ",
                            "                                 ",
                            "                                 ",
                            "                                 ",
                            "                A                ",
                            "                D                ",
                            "              CCCCC              ",
                            "               C C               ",
                            "                                 ",
                            "                                 ",
                            "                                 "
                        },
                        {
                            "                                 ",
                            "                                 ",
                            "               C C               ",
                            "               C C               ",
                            "                D                ",
                            "             SEEAEES             ",
                            "                                 ",
                            "                                 ",
                            "                                 ",
                            "                                 ",
                            "                                 ",
                            "                                 ",
                            "                                 ",
                            "     S                     S     ",
                            "     E                     E     ",
                            "  CC E                     E CC  ",
                            "    DA                     AD    ",
                            "  CC E                     E CC  ",
                            "     E                     E     ",
                            "     S                     S     ",
                            "                                 ",
                            "                                 ",
                            "                                 ",
                            "                                 ",
                            "                                 ",
                            "                                 ",
                            "                                 ",
                            "             SEEAEES             ",
                            "                D                ",
                            "               C C               ",
                            "               C C               ",
                            "                                 ",
                            "                                 "
                        },
                        {
                            "                                 ",
                            "                                 ",
                            "               C C               ",
                            "                D                ",
                            "                A                ",
                            "                                 ",
                            "                                 ",
                            "                                 ",
                            "                                 ",
                            "                                 ",
                            "                                 ",
                            "                                 ",
                            "                                 ",
                            "                                 ",
                            "                                 ",
                            "  C                           C  ",
                            "   DA                       AD   ",
                            "  C                           C  ",
                            "                                 ",
                            "                                 ",
                            "                                 ",
                            "                                 ",
                            "                                 ",
                            "                                 ",
                            "                                 ",
                            "                                 ",
                            "                                 ",
                            "                                 ",
                            "                A                ",
                            "                D                ",
                            "               C C               ",
                            "                                 ",
                            "                                 "
                        },
                        {
                            "                                 ",
                            "               C C               ",
                            "               C C               ",
                            "                D                ",
                            "                A                ",
                            "                                 ",
                            "                                 ",
                            "                                 ",
                            "                                 ",
                            "                                 ",
                            "                                 ",
                            "                                 ",
                            "                                 ",
                            "                                 ",
                            "                                 ",
                            " CC                           CC ",
                            "   DA                       AD   ",
                            " CC                           CC ",
                            "                                 ",
                            "                                 ",
                            "                                 ",
                            "                                 ",
                            "                                 ",
                            "                                 ",
                            "                                 ",
                            "                                 ",
                            "                                 ",
                            "                                 ",
                            "                A                ",
                            "                D                ",
                            "               C C               ",
                            "               C C               ",
                            "                                 "
                        },
                        {
                            "                                 ",
                            "               C C               ",
                            "                D                ",
                            "                                 ",
                            "                                 ",
                            "                                 ",
                            "                                 ",
                            "                                 ",
                            "                                 ",
                            "                                 ",
                            "                                 ",
                            "                                 ",
                            "                                 ",
                            "                                 ",
                            "                                 ",
                            " C                             C ",
                            "  D                           D  ",
                            " C                             C ",
                            "                                 ",
                            "                                 ",
                            "                                 ",
                            "                                 ",
                            "                                 ",
                            "                                 ",
                            "                                 ",
                            "                                 ",
                            "                                 ",
                            "                                 ",
                            "                                 ",
                            "                                 ",
                            "                D                ",
                            "               C C               ",
                            "                                 "
                        },
                        {
                            "                                 ",
                            "               C C               ",
                            "                D                ",
                            "                                 ",
                            "                                 ",
                            "                                 ",
                            "                                 ",
                            "                                 ",
                            "                                 ",
                            "                                 ",
                            "                                 ",
                            "                                 ",
                            "                                 ",
                            "                                 ",
                            "                                 ",
                            " C                             C ",
                            "  D                           D  ",
                            " C                             C ",
                            "                                 ",
                            "                                 ",
                            "                                 ",
                            "                                 ",
                            "                                 ",
                            "                                 ",
                            "                                 ",
                            "                                 ",
                            "                                 ",
                            "                                 ",
                            "                                 ",
                            "                                 ",
                            "                D                ",
                            "               C C               ",
                            "                                 "
                        },
                        {
                            "             CCCCCCC             ",
                            "               C C               ",
                            "             DDDDDDD             ",
                            "                                 ",
                            "                                 ",
                            "                                 ",
                            "                                 ",
                            "                                 ",
                            "                                 ",
                            "                                 ",
                            "                                 ",
                            "                                 ",
                            "                                 ",
                            "  D                           D  ",
                            "  D                           D  ",
                            "CCD                           DCC",
                            "  D                           D  ",
                            "CCD                           DCC",
                            "  D                           D  ",
                            "  D                           D  ",
                            "                                 ",
                            "                                 ",
                            "                                 ",
                            "                                 ",
                            "                                 ",
                            "                                 ",
                            "                                 ",
                            "                                 ",
                            "                                 ",
                            "                                 ",
                            "             DDDDDDD             ",
                            "               C C               ",
                            "               C C               "
                        },
                        {
                            "            CCHHHHHCC            ",
                            "              DDDDD              ",
                            "            DD     DD            ",
                            "                                 ",
                            "                                 ",
                            "       S                 S       ",
                            "                                 ",
                            "     S                     S     ",
                            "                                 ",
                            "                                 ",
                            "                                 ",
                            "                                 ",
                            "  D                           D  ",
                            "  D                           D  ",
                            " D                             D ",
                            "CD                             DC",
                            " D                             D ",
                            "CD                             DC",
                            " D                             D ",
                            "  D                           D  ",
                            "  D                           D  ",
                            "                                 ",
                            "                                 ",
                            "                                 ",
                            "                                 ",
                            "     S                     S     ",
                            "                                 ",
                            "       S                 S       ",
                            "                                 ",
                            "                                 ",
                            "            DD     DD            ",
                            "              DDDDD              ",
                            "               C C               "
                        },
                        {
                            "            CHHHHHHHC            ",
                            "             DDCDCDD             ",
                            "            D  EEE  D            ",
                            "                                 ",
                            "      C                   C      ",
                            "       E                 E       ",
                            "    C                       C    ",
                            "     E                     E     ",
                            "                                 ",
                            "                                 ",
                            "                                 ",
                            "                                 ",
                            "  D                           D  ",
                            " D                             D ",
                            " D                             D ",
                            "CCE                           ECC",
                            " DE                           ED ",
                            "CCE                           ECC",
                            " D                             D ",
                            " D                             D ",
                            "  D                           D  ",
                            "                                 ",
                            "                                 ",
                            "                                 ",
                            "                                 ",
                            "     E                     E     ",
                            "    C                       C    ",
                            "       E                 E       ",
                            "      C                   C      ",
                            "                                 ",
                            "            D  EEE  D            ",
                            "             DDCDCDD             ",
                            "               C C               "
                        },
                        {
                            "            CHHCCCHHC            ",
                            "         CCCCDCCDCCDCCCC         ",
                            "       CCC  D EAAAE D  CCC       ",
                            "      CC                 CC      ",
                            "     CC                   CC     ",
                            "    CC E                 E CC    ",
                            "   CC                       CC   ",
                            "  CC E                     E CC  ",
                            "  C                           C  ",
                            " CC                           CC ",
                            " C                             C ",
                            " C                             C ",
                            "CCD                           DCC",
                            "CD                             DC",
                            "CCE                           ECC",
                            "CCA                           ACC",
                            "CDA                           ADC",
                            "CCA                           ACC",
                            "CCE                           ECC",
                            "CD                             DC",
                            "CCD                           DCC",
                            " C                             C ",
                            " C                             C ",
                            " CC                           CC ",
                            "  C                           C  ",
                            "  CC E                     E CC  ",
                            "   CC                       CC   ",
                            "    CC E                 E CC    ",
                            "     CC                   CC     ",
                            "      CC                 CC      ",
                            "       CCC  D EAAAE D  CCC       ",
                            "         CCCCDCCDCCDCCCC         ",
                            "            CCCCCCCCC            "
                        },
                        {
                            "            CHHC~CHHC            ",
                            "             DDDDDDD             ",
                            "          DDD EAAAE DDD          ",
                            "        DD             DD        ",
                            "      CDAA             AADC      ",
                            "      DA                 AD      ",
                            "    CDA                   ADC    ",
                            "    DA                     AD    ",
                            "   DA                       AD   ",
                            "   DA                       AD   ",
                            "  D                           D  ",
                            "  D                           D  ",
                            "  D                           D  ",
                            " D                             D ",
                            " DE                           ED ",
                            "CDA                           ADC",
                            " DA                           AD ",
                            "CDA                           ADC",
                            " DE                           ED ",
                            " D                             D ",
                            "  D                           D  ",
                            "  D                           D  ",
                            "  D                           D  ",
                            "   DA                       AD   ",
                            "   DA                       AD   ",
                            "    DA                     AD    ",
                            "    CDA                   ADC    ",
                            "      DA                 AD      ",
                            "      CDAA             AADC      ",
                            "        DD             DD        ",
                            "          DDD EAAAE DDD          ",
                            "             DDDDDDD             ",
                            "               C C               "
                        },
                        {
                            "            CHHCCCHHC            ",
                            "         CCCCDCCDCCDCCCC         ",
                            "       CCC  D EAAAE D  CCC       ",
                            "      CC                 CC      ",
                            "     CC                   CC     ",
                            "    CC E                 E CC    ",
                            "   CC                       CC   ",
                            "  CC E                     E CC  ",
                            "  C                           C  ",
                            " CC                           CC ",
                            " C                             C ",
                            " C                             C ",
                            "CCD                           DCC",
                            "CD                             DC",
                            "CCE                           ECC",
                            "CCA                           ACC",
                            "CDA                           ADC",
                            "CCA                           ACC",
                            "CCE                           ECC",
                            "CD                             DC",
                            "CCD                           DCC",
                            " C                             C ",
                            " C                             C ",
                            " CC                           CC ",
                            "  C                           C  ",
                            "  CC E                     E CC  ",
                            "   CC                       CC   ",
                            "    CC E                 E CC    ",
                            "     CC                   CC     ",
                            "      CC                 CC      ",
                            "       CCC  D EAAAE D  CCC       ",
                            "         CCCCDCCDCCDCCCC         ",
                            "            CCCCCCCCC            "
                        },
                        {
                            "            CHHHHHHHC            ",
                            "             DDCDCDD             ",
                            "            D  EEE  D            ",
                            "                                 ",
                            "      C                   C      ",
                            "       E                 E       ",
                            "    C                       C    ",
                            "     E                     E     ",
                            "                                 ",
                            "                                 ",
                            "                                 ",
                            "                                 ",
                            "  D                           D  ",
                            " D                             D ",
                            " D                             D ",
                            "CCE                           ECC",
                            " DE                           ED ",
                            "CCE                           ECC",
                            " D                             D ",
                            " D                             D ",
                            "  D                           D  ",
                            "                                 ",
                            "                                 ",
                            "                                 ",
                            "                                 ",
                            "     E                     E     ",
                            "    C                       C    ",
                            "       E                 E       ",
                            "      C                   C      ",
                            "                                 ",
                            "            D  EEE  D            ",
                            "             DDCDCDD             ",
                            "               C C               "
                        },
                        {
                            "            CCHHHHHCC            ",
                            "              DDDDD              ",
                            "            DD     DD            ",
                            "                                 ",
                            "                                 ",
                            "       S                 S       ",
                            "                                 ",
                            "     S                     S     ",
                            "                                 ",
                            "                                 ",
                            "                                 ",
                            "                                 ",
                            "  D                           D  ",
                            "  D                           D  ",
                            " D                             D ",
                            "CD                             DC",
                            " D                             D ",
                            "CD                             DC",
                            " D                             D ",
                            "  D                           D  ",
                            "  D                           D  ",
                            "                                 ",
                            "                                 ",
                            "                                 ",
                            "                                 ",
                            "     S                     S     ",
                            "                                 ",
                            "       S                 S       ",
                            "                                 ",
                            "                                 ",
                            "            DD     DD            ",
                            "              DDDDD              ",
                            "               C C               "
                        },
                        {
                            "             CCCCCCC             ",
                            "               C C               ",
                            "             DDDDDDD             ",
                            "                                 ",
                            "                                 ",
                            "                                 ",
                            "                                 ",
                            "                                 ",
                            "                                 ",
                            "                                 ",
                            "                                 ",
                            "                                 ",
                            "                                 ",
                            "  D                           D  ",
                            "  D                           D  ",
                            "CCD                           DCC",
                            "  D                           D  ",
                            "CCD                           DCC",
                            "  D                           D  ",
                            "  D                           D  ",
                            "                                 ",
                            "                                 ",
                            "                                 ",
                            "                                 ",
                            "                                 ",
                            "                                 ",
                            "                                 ",
                            "                                 ",
                            "                                 ",
                            "                                 ",
                            "             DDDDDDD             ",
                            "               C C               ",
                            "               C C               "
                        },
                        {
                            "                                 ",
                            "               C C               ",
                            "                D                ",
                            "                                 ",
                            "                                 ",
                            "                                 ",
                            "                                 ",
                            "                                 ",
                            "                                 ",
                            "                                 ",
                            "                                 ",
                            "                                 ",
                            "                                 ",
                            "                                 ",
                            "                                 ",
                            " C                             C ",
                            "  D                           D  ",
                            " C                             C ",
                            "                                 ",
                            "                                 ",
                            "                                 ",
                            "                                 ",
                            "                                 ",
                            "                                 ",
                            "                                 ",
                            "                                 ",
                            "                                 ",
                            "                                 ",
                            "                                 ",
                            "                                 ",
                            "                D                ",
                            "               C C               ",
                            "                                 "
                        },
                        {
                            "                                 ",
                            "               C C               ",
                            "                D                ",
                            "                                 ",
                            "                                 ",
                            "                                 ",
                            "                                 ",
                            "                                 ",
                            "                                 ",
                            "                                 ",
                            "                                 ",
                            "                                 ",
                            "                                 ",
                            "                                 ",
                            "                                 ",
                            " C                             C ",
                            "  D                           D  ",
                            " C                             C ",
                            "                                 ",
                            "                                 ",
                            "                                 ",
                            "                                 ",
                            "                                 ",
                            "                                 ",
                            "                                 ",
                            "                                 ",
                            "                                 ",
                            "                                 ",
                            "                                 ",
                            "                                 ",
                            "                D                ",
                            "               C C               ",
                            "                                 "
                        },
                        {
                            "                                 ",
                            "               C C               ",
                            "               C C               ",
                            "                D                ",
                            "                A                ",
                            "                                 ",
                            "                                 ",
                            "                                 ",
                            "                                 ",
                            "                                 ",
                            "                                 ",
                            "                                 ",
                            "                                 ",
                            "                                 ",
                            "                                 ",
                            " CC                           CC ",
                            "   DA                       AD   ",
                            " CC                           CC ",
                            "                                 ",
                            "                                 ",
                            "                                 ",
                            "                                 ",
                            "                                 ",
                            "                                 ",
                            "                                 ",
                            "                                 ",
                            "                                 ",
                            "                                 ",
                            "                A                ",
                            "                D                ",
                            "               C C               ",
                            "               C C               ",
                            "                                 "
                        },
                        {
                            "                                 ",
                            "                                 ",
                            "               C C               ",
                            "                D                ",
                            "                A                ",
                            "                                 ",
                            "                                 ",
                            "                                 ",
                            "                                 ",
                            "                                 ",
                            "                                 ",
                            "                                 ",
                            "                                 ",
                            "                                 ",
                            "                                 ",
                            "  C                           C  ",
                            "   DA                       AD   ",
                            "  C                           C  ",
                            "                                 ",
                            "                                 ",
                            "                                 ",
                            "                                 ",
                            "                                 ",
                            "                                 ",
                            "                                 ",
                            "                                 ",
                            "                                 ",
                            "                                 ",
                            "                A                ",
                            "                D                ",
                            "               C C               ",
                            "                                 ",
                            "                                 "
                        },
                        {
                            "                                 ",
                            "                                 ",
                            "               C C               ",
                            "               C C               ",
                            "                D                ",
                            "             SEEAEES             ",
                            "                                 ",
                            "                                 ",
                            "                                 ",
                            "                                 ",
                            "                                 ",
                            "                                 ",
                            "                                 ",
                            "     S                     S     ",
                            "     E                     E     ",
                            "  CC E                     E CC  ",
                            "    DA                     AD    ",
                            "  CC E                     E CC  ",
                            "     E                     E     ",
                            "     S                     S     ",
                            "                                 ",
                            "                                 ",
                            "                                 ",
                            "                                 ",
                            "                                 ",
                            "                                 ",
                            "                                 ",
                            "             SEEAEES             ",
                            "                D                ",
                            "               C C               ",
                            "               C C               ",
                            "                                 ",
                            "                                 "
                        },
                        {
                            "                                 ",
                            "                                 ",
                            "                                 ",
                            "               C C               ",
                            "              CCCCC              ",
                            "                D                ",
                            "                A                ",
                            "                                 ",
                            "                                 ",
                            "                                 ",
                            "                                 ",
                            "                                 ",
                            "                                 ",
                            "                                 ",
                            "    C                       C    ",
                            "   CC                       CC   ",
                            "    CDA                   ADC    ",
                            "   CC                       CC   ",
                            "    C                       C    ",
                            "                                 ",
                            "                                 ",
                            "                                 ",
                            "                                 ",
                            "                                 ",
                            "                                 ",
                            "                                 ",
                            "                A                ",
                            "                D                ",
                            "              CCCCC              ",
                            "               C C               ",
                            "                                 ",
                            "                                 ",
                            "                                 "
                        },
                        {
                            "                                 ",
                            "                                 ",
                            "                                 ",
                            "                                 ",
                            "               C C               ",
                            "               C C               ",
                            "                D                ",
                            "             SEEAEES             ",
                            "                                 ",
                            "                                 ",
                            "                                 ",
                            "                                 ",
                            "                                 ",
                            "       S                 S       ",
                            "       E                 E       ",
                            "    CC E                 E CC    ",
                            "      DA                 AD      ",
                            "    CC E                 E CC    ",
                            "       E                 E       ",
                            "       S                 S       ",
                            "                                 ",
                            "                                 ",
                            "                                 ",
                            "                                 ",
                            "                                 ",
                            "             SEEAEES             ",
                            "                D                ",
                            "               C C               ",
                            "               C C               ",
                            "                                 ",
                            "                                 ",
                            "                                 ",
                            "                                 "
                        },
                        {
                            "                                 ",
                            "                                 ",
                            "                                 ",
                            "                                 ",
                            "                                 ",
                            "               C C               ",
                            "              CCCCC              ",
                            "                D                ",
                            "                A                ",
                            "                A                ",
                            "                                 ",
                            "                                 ",
                            "                                 ",
                            "                                 ",
                            "      C                   C      ",
                            "     CC                   CC     ",
                            "      CDAA             AADC      ",
                            "     CC                   CC     ",
                            "      C                   C      ",
                            "                                 ",
                            "                                 ",
                            "                                 ",
                            "                                 ",
                            "                A                ",
                            "                A                ",
                            "                D                ",
                            "              CCCCC              ",
                            "               C C               ",
                            "                                 ",
                            "                                 ",
                            "                                 ",
                            "                                 ",
                            "                                 "
                        },
                        {
                            "                                 ",
                            "                                 ",
                            "                                 ",
                            "                                 ",
                            "                                 ",
                            "                                 ",
                            "               C C               ",
                            "               C C               ",
                            "                D                ",
                            "                D                ",
                            "                                 ",
                            "                                 ",
                            "                                 ",
                            "                                 ",
                            "                                 ",
                            "      CC                 CC      ",
                            "        DD             DD        ",
                            "      CC                 CC      ",
                            "                                 ",
                            "                                 ",
                            "                                 ",
                            "                                 ",
                            "                                 ",
                            "                D                ",
                            "                D                ",
                            "               C C               ",
                            "               C C               ",
                            "                                 ",
                            "                                 ",
                            "                                 ",
                            "                                 ",
                            "                                 ",
                            "                                 "
                        },
                        {
                            "                                 ",
                            "                                 ",
                            "                                 ",
                            "                                 ",
                            "                                 ",
                            "                                 ",
                            "                                 ",
                            "               C C               ",
                            "               C C               ",
                            "               C C               ",
                            "                D                ",
                            "                D                ",
                            "             DDDDDDD             ",
                            "            DD     DD            ",
                            "            D  EEE  D            ",
                            "       CCC  D EAAAE D  CCC       ",
                            "          DDD EAAAE DDD          ",
                            "       CCC  D EAAAE D  CCC       ",
                            "            D  EEE  D            ",
                            "            DD     DD            ",
                            "             DDDDDDD             ",
                            "                D                ",
                            "                D                ",
                            "               C C               ",
                            "               C C               ",
                            "               C C               ",
                            "                                 ",
                            "                                 ",
                            "                                 ",
                            "                                 ",
                            "                                 ",
                            "                                 ",
                            "                                 "
                        },
                        {
                            "                                 ",
                            "                                 ",
                            "                                 ",
                            "                                 ",
                            "                                 ",
                            "                                 ",
                            "                                 ",
                            "                                 ",
                            "                                 ",
                            "               C C               ",
                            "               C C               ",
                            "               C C               ",
                            "               C C               ",
                            "              DDDDD              ",
                            "             DDCDCDD             ",
                            "         CCCCDCCDCCDCCCC         ",
                            "             DDDDDDD             ",
                            "         CCCCDCCDCCDCCCC         ",
                            "             DDCDCDD             ",
                            "              DDDDD              ",
                            "               C C               ",
                            "               C C               ",
                            "               C C               ",
                            "               C C               ",
                            "                                 ",
                            "                                 ",
                            "                                 ",
                            "                                 ",
                            "                                 ",
                            "                                 ",
                            "                                 ",
                            "                                 ",
                            "                                 "
                        },
                        {
                            "                                 ",
                            "                                 ",
                            "                                 ",
                            "                                 ",
                            "                                 ",
                            "                                 ",
                            "                                 ",
                            "                                 ",
                            "                                 ",
                            "                                 ",
                            "                                 ",
                            "                                 ",
                            "               C C               ",
                            "               C C               ",
                            "               C C               ",
                            "            CCCCCCCCC            ",
                            "               C C               ",
                            "            CCCCCCCCC            ",
                            "               C C               ",
                            "               C C               ",
                            "               C C               ",
                            "                                 ",
                            "                                 ",
                            "                                 ",
                            "                                 ",
                            "                                 ",
                            "                                 ",
                            "                                 ",
                            "                                 ",
                            "                                 ",
                            "                                 ",
                            "                                 ",
                            "                                 "
                        }
                    }))
                    .addElement(
                            'A',
                            ofBlocksTiered(
                                    (block, meta) -> block == TT_Container_Casings.SpacetimeCompressionFieldGenerators
                                            ? meta
                                            : -1,
                                    ImmutableList.of(
                                            Pair.of(TT_Container_Casings.SpacetimeCompressionFieldGenerators, 0),
                                            Pair.of(TT_Container_Casings.SpacetimeCompressionFieldGenerators, 1),
                                            Pair.of(TT_Container_Casings.SpacetimeCompressionFieldGenerators, 2),
                                            Pair.of(TT_Container_Casings.SpacetimeCompressionFieldGenerators, 3),
                                            Pair.of(TT_Container_Casings.SpacetimeCompressionFieldGenerators, 4),
                                            Pair.of(TT_Container_Casings.SpacetimeCompressionFieldGenerators, 5),
                                            Pair.of(TT_Container_Casings.SpacetimeCompressionFieldGenerators, 6),
                                            Pair.of(TT_Container_Casings.SpacetimeCompressionFieldGenerators, 7),
                                            Pair.of(TT_Container_Casings.SpacetimeCompressionFieldGenerators, 8)),
                                    -1,
                                    (t, meta) -> t.spacetimeCompressionFieldMetadata = meta,
                                    t -> t.spacetimeCompressionFieldMetadata))
                    .addElement(
                            'S',
                            ofBlocksTiered(
                                    (block, meta) ->
                                            block == TT_Container_Casings.StabilisationFieldGenerators ? meta : -1,
                                    ImmutableList.of(
                                            Pair.of(TT_Container_Casings.StabilisationFieldGenerators, 0),
                                            Pair.of(TT_Container_Casings.StabilisationFieldGenerators, 1),
                                            Pair.of(TT_Container_Casings.StabilisationFieldGenerators, 2),
                                            Pair.of(TT_Container_Casings.StabilisationFieldGenerators, 3),
                                            Pair.of(TT_Container_Casings.StabilisationFieldGenerators, 4),
                                            Pair.of(TT_Container_Casings.StabilisationFieldGenerators, 5),
                                            Pair.of(TT_Container_Casings.StabilisationFieldGenerators, 6),
                                            Pair.of(TT_Container_Casings.StabilisationFieldGenerators, 7),
                                            Pair.of(TT_Container_Casings.StabilisationFieldGenerators, 8)),
                                    -1,
                                    (t, meta) -> t.stabilisationFieldMetadata = meta,
                                    t -> t.stabilisationFieldMetadata))
                    .addElement('C', ofBlock(sBlockCasingsBA0, 11))
                    .addElement('D', ofBlock(sBlockCasingsBA0, 10))
                    .addElement(
                            'E',
                            ofBlocksTiered(
                                    (block, meta) ->
                                            block == TT_Container_Casings.TimeAccelerationFieldGenerator ? meta : -1,
                                    ImmutableList.of(
                                            Pair.of(TT_Container_Casings.TimeAccelerationFieldGenerator, 0),
                                            Pair.of(TT_Container_Casings.TimeAccelerationFieldGenerator, 1),
                                            Pair.of(TT_Container_Casings.TimeAccelerationFieldGenerator, 2),
                                            Pair.of(TT_Container_Casings.TimeAccelerationFieldGenerator, 3),
                                            Pair.of(TT_Container_Casings.TimeAccelerationFieldGenerator, 4),
                                            Pair.of(TT_Container_Casings.TimeAccelerationFieldGenerator, 5),
                                            Pair.of(TT_Container_Casings.TimeAccelerationFieldGenerator, 6),
                                            Pair.of(TT_Container_Casings.TimeAccelerationFieldGenerator, 7),
                                            Pair.of(TT_Container_Casings.TimeAccelerationFieldGenerator, 8)),
                                    -1,
                                    (t, meta) -> t.timeAccelerationFieldMetadata = meta,
                                    t -> t.timeAccelerationFieldMetadata))
                    .addElement(
                            'H',
                            ofHatchAdderOptional(
                                    GT_MetaTileEntity_EM_EyeOfHarmony::addClassicToMachineList,
                                    textureOffset,
                                    1,
                                    sBlockCasingsBA0,
                                    12))
                    .build();

    private double hydrogenOverflowProbabilityAdjustment;
    private double heliumOverflowProbabilityAdjustment;
    private static final long TICKS_BETWEEN_HATCH_DRAIN = EOH_DEBUG_MODE ? 20 : 200;

    private List<ItemStackLong> outputItems = new ArrayList<>();

    private void calculateHydrogenHeliumInputExcessValues(
            final long hydrogenRecipeRequirement, final long heliumRecipeRequirement) {

        long hydrogenStored = validFluidMap.get(Materials.Hydrogen.getGas(1L));
        long heliumStored = validFluidMap.get(Materials.Helium.getGas(1L));

        double hydrogenExcessPercentage = abs(1 - hydrogenStored / hydrogenRecipeRequirement);
        double heliumExcessPercentage = abs(1 - heliumStored / heliumRecipeRequirement);

        hydrogenOverflowProbabilityAdjustment = 1 - exp(-pow(30 * hydrogenExcessPercentage, 2));
        heliumOverflowProbabilityAdjustment = 1 - exp(-pow(30 * heliumExcessPercentage, 2));
    }

    private double recipeChanceCalculator() {
        double chance = currentRecipe.getBaseRecipeSuccessChance()
                - timeAccelerationFieldMetadata * 0.1
                + stabilisationFieldMetadata * 0.05
                - hydrogenOverflowProbabilityAdjustment
                - heliumOverflowProbabilityAdjustment;

        return clamp(chance, 0.0, 1.0);
    }

    public static double clamp(double amount, double min, double max) {
        return Math.max(min, Math.min(amount, max));
    }

    private double recipeYieldCalculator() {
        double yield = 1.0
                - hydrogenOverflowProbabilityAdjustment
                - heliumOverflowProbabilityAdjustment
                - stabilisationFieldMetadata * 0.05;

        return clamp(yield, 0.0, 1.0);
    }

    private int recipeProcessTimeCalculator(long recipeTime, long recipeSpacetimeCasingRequired) {

        // Tier 1 recipe.
        // Tier 2 spacetime blocks.
        // = 3% discount.

        // Tier 1 recipe.
        // Tier 3 spacetime blocks.
        // = 3%*3% = 5.91% discount.

        long spacetimeCasingDifference = (recipeSpacetimeCasingRequired - spacetimeCompressionFieldMetadata);
        double recipeTimeDiscounted = recipeTime
                * pow(2.0, -timeAccelerationFieldMetadata)
                * pow(1 - SPACETIME_CASING_DIFFERENCE_DISCOUNT_PERCENTAGE, spacetimeCasingDifference);
        return (int) Math.max(recipeTimeDiscounted, 1.0);
    }

    @Override
    public IStructureDefinition<GT_MetaTileEntity_EM_EyeOfHarmony> getStructure_EM() {
        return STRUCTURE_DEFINITION;
    }

    public GT_MetaTileEntity_EM_EyeOfHarmony(int aID, String aName, String aNameRegional) {
        super(aID, aName, aNameRegional);
    }

    public GT_MetaTileEntity_EM_EyeOfHarmony(String aName) {
        super(aName);
    }

    @Override
    public IMetaTileEntity newMetaEntity(IGregTechTileEntity aTileEntity) {
        return new GT_MetaTileEntity_EM_EyeOfHarmony(mName);
    }

    @Override
    public boolean checkMachine_EM(IGregTechTileEntity iGregTechTileEntity, ItemStack itemStack) {

        spacetimeCompressionFieldMetadata = -1;
        timeAccelerationFieldMetadata = -1;
        stabilisationFieldMetadata = -1;

        // Check structure of multi.
        if (!structureCheck_EM(STRUCTURE_PIECE_MAIN, 16, 16, 0)) {
            return false;
        }

        // Check if there is 1+ output bus, and they are ME output busses.
        {
            if (mOutputBusses.size() == 0) {
                return false;
            }

            for (GT_MetaTileEntity_Hatch_OutputBus hatch : mOutputBusses) {
                if (!(hatch instanceof GT_MetaTileEntity_Hatch_OutputBus_ME)) {
                    return false;
                }
            }
        }

        // Check if there is 1+ output hatch, and they are ME output hatches.
        {
            if (mOutputHatches.size() == 0) {
                return false;
            }

            for (GT_MetaTileEntity_Hatch_Output hatch : mOutputHatches) {
                if (!(hatch instanceof GT_MetaTileEntity_Hatch_Output_ME)) {
                    return false;
                }
            }
        }

        // Make sure there are no energy hatches.
        {
            if (mEnergyHatches.size() > 0) {
                return false;
            }

            if (mExoticEnergyHatches.size() > 0) {
                return false;
            }
        }

        // Make sure there are 2 input hatches.
        if (mInputHatches.size() != 2) {
            return false;
        }

        // 1 Maintenance hatch, as usual.
        return (mMaintenanceHatches.size() == 1);
    }

    @Override
    public GT_Multiblock_Tooltip_Builder createTooltip() {
        final GT_Multiblock_Tooltip_Builder tt = new GT_Multiblock_Tooltip_Builder();
        tt.addMachineType("Spacetime Manipulator, EOH")
                .addInfo(GOLD + "--------------------------------------------------------------------------------")
                .addInfo("Creates a pocket of spacetime that is bigger on the inside using transdimensional")
                .addInfo("engineering. Certified Time Lord regulation compliant. This multi uses too much EU")
                .addInfo("to be handled with conventional means. All EU requirements are handled directly by")
                .addInfo("your wireless EU network.")
                .addInfo(GOLD + "--------------------------------------------------------------------------------")
                .addInfo("This multiblock will constantly consume hydrogen and helium when it is not running a")
                .addInfo("recipe as fast as it can. It will store this internally, you can see the totals by")
                .addInfo("using a scanner. This multi also has three tiered blocks with " + RED + 9 + GRAY + " tiers")
                .addInfo("each. They are as follows and have the associated effects on the multi.")
                .addInfo(BLUE + "Spacetime Compression Field Generator:")
                .addInfo("- The tier of this block determines what recipes can be run. If the multiblocks")
                .addInfo("  spacetime compression field block exceeds the requirements of the recipe it")
                .addInfo("  will decrease the processing time by " + RED + "3%" + GRAY
                        + " per tier over the requirement. This")
                .addInfo("  is multiplicative.")
                .addInfo(BLUE + "Time Dilation Field Generator:")
                .addInfo("- Decreases the time required by a recipe by a factor of " + RED + "2" + GRAY
                        + " per tier of block.")
                .addInfo("  Decreases the probability of a recipe succeeding by " + RED + "10%" + GRAY
                        + " per tier (additive)")
                .addInfo(BLUE + "Stabilisation Field Generator:")
                .addInfo("- Increases the probability of a recipe succeeding by " + RED + "5%" + GRAY
                        + " per tier (additive).")
                .addInfo("  Decreases the yield of a recipe by " + RED + "5%" + GRAY + " per tier (additive). ")
                .addInfo(GOLD + "--------------------------------------------------------------------------------")
                .addInfo("Going over a recipe requirement on hydrogen or helium has a penalty on yield and recipe")
                .addInfo(
                        "chance. All stored hydrogen and helium is consumed during a craft. The associated formulas are:")
                .addInfo(GREEN + "percentageOverflow = abs(1 - fluidStored/recipeRequirement)")
                .addInfo(GREEN + "adjustmentValue = 1 - exp(-(30 * percentageOverflow)^2)")
                .addInfo("The value of adjustmentValue is then subtracted from the total yield and recipe chance.")
                .addInfo(GOLD + "--------------------------------------------------------------------------------")
                .addInfo("It should be noted that base recipe chance is determined per recipe and yield always")
                .addInfo("starts at 1 and subtracts depending on penalities. All fluid/item outputs are multiplied")
                .addInfo("by the yield calculated.")
                .addInfo(GOLD + "--------------------------------------------------------------------------------")
                .addInfo("This multiblock can only output to ME output busses/hatches. If no space in the network")
                .addInfo(
                        "is avaliable the items/fluids will be " + UNDERLINE + DARK_RED + "voided" + RESET + GRAY + ".")
                .addInfo(GOLD + "--------------------------------------------------------------------------------")
                .addInfo("Recipes that fail will return a random amount of the fluid back from the recipe and some")
                .addInfo("exotic material that rejects conventional physics.")
                .addSeparator()
                .addStructureInfo("Eye of Harmony structure is too complex! See schematic for details.")
                .addStructureInfo(EnumChatFormatting.GOLD + "896" + EnumChatFormatting.GRAY
                        + " Reinforced Spacetime Structure Casing.")
                .addStructureInfo(EnumChatFormatting.GOLD + "534" + EnumChatFormatting.GRAY
                        + " Ultimate Temporal Boundary Casing.")
                .addStructureInfo(
                        EnumChatFormatting.GOLD + "680" + EnumChatFormatting.GRAY + " Time Dilation Field Generator.")
                .addStructureInfo(
                        EnumChatFormatting.GOLD + "48" + EnumChatFormatting.GRAY + " Stabilisation Field Generator.")
                .addStructureInfo(EnumChatFormatting.GOLD + "138" + EnumChatFormatting.GRAY
                        + " Spacetime Compression Field Generator.")
                .addStructureInfo("--------------------------------------------")
                .addStructureInfo(
                        "Requires " + EnumChatFormatting.GOLD + 1 + EnumChatFormatting.GRAY + " maintenance hatch.")
                .addStructureInfo(
                        "Requires " + EnumChatFormatting.GOLD + 2 + EnumChatFormatting.GRAY + " input hatches.")
                .addStructureInfo(
                        "Requires " + EnumChatFormatting.GOLD + 1 + EnumChatFormatting.GRAY + "+ ME output hatch.")
                .addStructureInfo(
                        "Requires " + EnumChatFormatting.GOLD + 1 + EnumChatFormatting.GRAY + " input busses.")
                .addStructureInfo(
                        "Requires " + EnumChatFormatting.GOLD + 1 + EnumChatFormatting.GRAY + " ME output bus.")
                .addStructureInfo("--------------------------------------------")
                .beginStructureBlock(33, 33, 33, false)
                .toolTipFinisher(AuthorColen.substring(8) + EnumChatFormatting.GRAY + "&" + CommonValues.TEC_MARK_EM);
        return tt;
    }

    @Override
    @SideOnly(Side.CLIENT)
    public void registerIcons(IIconRegister aBlockIconRegister) {
        ScreenOFF = new Textures.BlockIcons.CustomIcon("iconsets/EM_BHG");
        ScreenON = new Textures.BlockIcons.CustomIcon("iconsets/EM_BHG_ACTIVE");
        super.registerIcons(aBlockIconRegister);
    }

    @Override
    public ITexture[] getTexture(
            IGregTechTileEntity aBaseMetaTileEntity,
            byte aSide,
            byte aFacing,
            byte aColorIndex,
            boolean aActive,
            boolean aRedstone) {
        if (aSide == aFacing) {
            return new ITexture[] {
                Textures.BlockIcons.casingTexturePages[texturePage][12],
                new TT_RenderedExtendedFacingTexture(aActive ? ScreenON : ScreenOFF)
            };
        }
        return new ITexture[] {Textures.BlockIcons.casingTexturePages[texturePage][12]};
    }

    @Override
    public void construct(ItemStack stackSize, boolean hintsOnly) {
        structureBuild_EM(STRUCTURE_PIECE_MAIN, 16, 16, 0, stackSize, hintsOnly);
    }

    private final Map<FluidStack, Long> validFluidMap = new HashMap<FluidStack, Long>() {
        {
            put(Materials.Hydrogen.getGas(1), 0L);
            put(Materials.Helium.getGas(1), 0L);
        }
    };

    private void drainFluidFromHatchesAndStoreInternally() {
        for (GT_MetaTileEntity_Hatch_Input inputHatch : mInputHatches) {
            FluidStack fluidInHatch = inputHatch.getFluid();

            if (fluidInHatch == null) {
                continue;
            }

            // Iterate over valid fluids and store them in a hashmap.
            for (FluidStack validFluid : validFluidMap.keySet()) {
                if (fluidInHatch.isFluidEqual(validFluid)) {
                    validFluidMap.put(validFluid, validFluidMap.get(validFluid) + (long) fluidInHatch.amount);
                    inputHatch.setFillableStack(null);
                }
            }
        }
    }

    private EyeOfHarmonyRecipe currentRecipe;

    // Counter for lag prevention.
    private long lagPreventer = 0;

    // Check for recipe every recipeCheckInterval ticks.
    private static final long RECIPE_CHECK_INTERVAL = 3 * 20;

    @Override
    public boolean checkRecipe_EM(ItemStack aStack) {
        if (aStack == null) {
            return false;
        }

        lagPreventer++;
        if (lagPreventer < RECIPE_CHECK_INTERVAL) {
            lagPreventer = 0;
            // No item in multi gui slot.

            currentRecipe = eyeOfHarmonyRecipeStorage.recipeLookUp(aStack);
            if (processRecipe(currentRecipe)) {
                return true;
            }

            currentRecipe = null;
        }
        return false;
    }

    private long getHydrogenStored() {
        return validFluidMap.get(Materials.Hydrogen.getGas(1));
    }

    private long getHeliumStored() {
        return validFluidMap.get(Materials.Helium.getGas(1));
    }

    public boolean processRecipe(EyeOfHarmonyRecipe recipeObject) {

        // Debug mode, overwrites the required fluids to initiate the recipe to 100L of each.
        if (EOH_DEBUG_MODE) {
            if ((getHydrogenStored() < 100) || (getHeliumStored() < 100)) {
                return false;
            }
        } else {
            if ((getHydrogenStored() < currentRecipe.getHydrogenRequirement())
                    || (getHeliumStored() < currentRecipe.getHeliumRequirement())) {
                return false;
            }
        }

        // Check tier of spacetime compression blocks is high enough.
        if (spacetimeCompressionFieldMetadata < recipeObject.getSpacetimeCasingTierRequired()) {
            return false;
        }

        // Remove EU from the users network.
        if (!addEUToGlobalEnergyMap(userUUID, -recipeObject.getEUStartCost())) {
            return false;
        }

        mMaxProgresstime = recipeProcessTimeCalculator(
                recipeObject.getRecipeTimeInTicks(), recipeObject.getSpacetimeCasingTierRequired());

        calculateHydrogenHeliumInputExcessValues(
                recipeObject.getHydrogenRequirement(), recipeObject.getHeliumRequirement());

        if (EOH_DEBUG_MODE) {
            hydrogenOverflowProbabilityAdjustment = 0;
            heliumOverflowProbabilityAdjustment = 0;
        }

        successChance = recipeChanceCalculator();

        // Determine EU recipe output.
        euOutput = recipeObject.getEUOutput();

        // Reduce internal storage by hydrogen and helium quantity required for recipe.
        validFluidMap.put(Materials.Hydrogen.getGas(1), 0L);
        validFluidMap.put(Materials.Helium.getGas(1), 0L);

        double yield = recipeYieldCalculator();
        if (EOH_DEBUG_MODE) {
            successChance = 1; // Debug recipes, sets them to 100% output chance.
        }

        // Return copies of the output objects.
        mOutputFluids = recipeObject.getOutputFluids();
        outputItems = recipeObject.getOutputItems();

        if (yield != 1.0) {
            // Iterate over item output list and apply yield values.
            for (ItemStackLong itemStackLong : outputItems) {
                itemStackLong.stackSize *= yield;
            }

            // Iterate over fluid output list and apply yield values.
            for (FluidStack fluidStack : mOutputFluids) {
                fluidStack.amount *= yield;
            }
        }

        updateSlots();

        createRenderBlock(currentRecipe);

        recipeRunning = true;
        return true;
    }

    private void createRenderBlock(final EyeOfHarmonyRecipe currentRecipe) {

        IGregTechTileEntity gregTechTileEntity = this.getBaseMetaTileEntity();

        int x = gregTechTileEntity.getXCoord();
        int y = gregTechTileEntity.getYCoord();
        int z = gregTechTileEntity.getZCoord();

        double xOffset = 16 * getExtendedFacing().getRelativeBackInWorld().offsetX;
        double zOffset = 16 * getExtendedFacing().getRelativeBackInWorld().offsetZ;
        double yOffset = 16 * getExtendedFacing().getRelativeBackInWorld().offsetY;

        this.getBaseMetaTileEntity()
                .getWorld()
                .setBlock((int) (x + xOffset), (int) (y + yOffset), (int) (z + zOffset), Blocks.air);
        this.getBaseMetaTileEntity()
                .getWorld()
                .setBlock((int) (x + xOffset), (int) (y + yOffset), (int) (z + zOffset), eyeOfHarmonyRenderBlock);
        TileEyeOfHarmony rendererTileEntity = (TileEyeOfHarmony)
                this.getBaseMetaTileEntity().getWorld().getTileEntity((int) (x + xOffset), (int) (y + yOffset), (int)
                        (z + zOffset));

