package com.github.technus.tectech.thing.metaTileEntity.multi;

import static com.github.technus.tectech.thing.casing.GT_Block_CasingsTT.textureOffset;
import static com.github.technus.tectech.thing.casing.GT_Block_CasingsTT.texturePage;
import static com.github.technus.tectech.thing.casing.TT_Container_Casings.sBlockCasingsTT;
import static com.github.technus.tectech.thing.metaTileEntity.multi.GT_MetaTileEntity_EM_decay.URANIUM_INGOT_MASS_DIFF;
import static com.github.technus.tectech.thing.metaTileEntity.multi.GT_MetaTileEntity_EM_decay.URANIUM_MASS_TO_EU_INSTANT;
import static com.gtnewhorizon.structurelib.structure.StructureUtility.ofBlock;
import static com.gtnewhorizon.structurelib.structure.StructureUtility.transpose;
import static gregtech.api.util.GT_StructureUtility.ofHatchAdderOptional;
import static net.minecraft.util.StatCollector.translateToLocal;

import com.github.technus.tectech.thing.block.QuantumGlassBlock;
import com.github.technus.tectech.thing.metaTileEntity.multi.base.GT_MetaTileEntity_MultiblockBase_EM;
import com.github.technus.tectech.thing.metaTileEntity.multi.base.render.TT_RenderedExtendedFacingTexture;
import com.github.technus.tectech.util.CommonValues;
import com.gtnewhorizon.structurelib.alignment.constructable.IConstructable;
import com.gtnewhorizon.structurelib.structure.IStructureDefinition;
import cpw.mods.fml.relauncher.Side;
import cpw.mods.fml.relauncher.SideOnly;
import gregtech.api.enums.Textures;
import gregtech.api.interfaces.ITexture;
import gregtech.api.interfaces.metatileentity.IMetaTileEntity;
import gregtech.api.interfaces.tileentity.IGregTechTileEntity;
import gregtech.api.util.GT_Multiblock_Tooltip_Builder;
import net.minecraft.client.renderer.texture.IIconRegister;
import net.minecraft.item.ItemStack;
import net.minecraft.util.EnumChatFormatting;

/**
 * Created by danie_000 on 17.12.2016.
 */
public class GT_MetaTileEntity_EM_bhg extends GT_MetaTileEntity_MultiblockBase_EM implements IConstructable {
    // region variables
    private static Textures.BlockIcons.CustomIcon ScreenOFF;
    private static Textures.BlockIcons.CustomIcon ScreenON;

    // todo CHECK VALUES
    private static final double NEUTRONIUM_BLOCK_MASS = 4.1E17;
    private static final double NEUTRONIUM_BLOCK_ATOM_COUNT = 2.4478671E44;
    private static final double NEUTRONIUM_BLOCK_TO_EU_INSTANT = URANIUM_MASS_TO_EU_INSTANT
            * NEUTRONIUM_BLOCK_MASS
            / (URANIUM_INGOT_MASS_DIFF * 1.78266191e-36); // ~ 5.314e40
    private static final double NEUTRON_TO_EU_INSTANT =
            NEUTRONIUM_BLOCK_TO_EU_INSTANT / NEUTRONIUM_BLOCK_ATOM_COUNT; // ~ 0.00021708694

    public boolean glassDome = false;
    // endregion

    // Time dillatation - to slow down the explosion thing but REALLY REDUCE POWER OUTPUT
    // Startcodes to startup
    // per dim disable thingies

    // region structure actual
    private static final IStructureDefinition<GT_MetaTileEntity_EM_bhg> STRUCTURE_DEFINITION =
            IStructureDefinition.<GT_MetaTileEntity_EM_bhg>builder()
                    .addShape("main_t1", transpose(new String[][] {
                        {
                            "                                 ",
                            "                                 ",
                            "                                 ",
                            "                                 ",
                            "                                 ",
                            "                                 ",
                            "                                 ",
                            "                                 ",
                            "                                 ",
                            "                                 ",
                            "                                 ",
                            "                                 ",
                            "               C C               ",
                            "               C C               ",
                            "               C C               ",
                            "            CCCCCCCCC            ",
                            "               C C               ",
                            "            CCCCCCCCC            ",
                            "               C C               ",
                            "               C C               ",
                            "               C C               ",
                            "                                 ",
                            "                                 ",
                            "                                 ",
                            "                                 ",
                            "                                 ",
                            "                                 ",
                            "                                 ",
                            "                                 ",
                            "                                 ",
                            "                                 ",
                            "                                 ",
                            "                                 "
                        },
                        {
                            "                                 ",
                            "                                 ",
                            "                                 ",
                            "                                 ",
                            "                                 ",
                            "                                 ",
                            "                                 ",
                            "                                 ",
                            "                                 ",
                            "               C C               ",
                            "               C C               ",
                            "               C C               ",
                            "               C C               ",
                            "              DDDDD              ",
                            "             DDCDCDD             ",
                            "         CCCCDCCDCCDCCCC         ",
                            "             DDDDDDD             ",
                            "         CCCCDCCDCCDCCCC         ",
                            "             DDCDCDD             ",
                            "              DDDDD              ",
                            "               C C               ",
                            "               C C               ",
                            "               C C               ",
                            "               C C               ",
                            "                                 ",
                            "                                 ",
                            "                                 ",
                            "                                 ",
                            "                                 ",
                            "                                 ",
                            "                                 ",
                            "                                 ",
                            "                                 "
                        },
                        {
                            "                                 ",
                            "                                 ",
                            "                                 ",
                            "                                 ",
                            "                                 ",
                            "                                 ",
                            "                                 ",
                            "               C C               ",
                            "               C C               ",
                            "               C C               ",
                            "                D                ",
                            "                D                ",
                            "             DDDDDDD             ",
                            "            DD     DD            ",
                            "            D  EEE  D            ",
                            "       CCC  D EAAAE D  CCC       ",
                            "          DDD EAAAE DDD          ",
                            "       CCC  D EAAAE D  CCC       ",
                            "            D  EEE  D            ",
                            "            DD     DD            ",
                            "             DDDDDDD             ",
                            "                D                ",
                            "                D                ",
                            "               C C               ",
                            "               C C               ",
                            "               C C               ",
                            "                                 ",
                            "                                 ",
                            "                                 ",
                            "                                 ",
                            "                                 ",
                            "                                 ",
                            "                                 "
                        },
                        {
                            "                                 ",
                            "                                 ",
                            "                                 ",
                            "                                 ",
                            "                                 ",
                            "                                 ",
                            "               C C               ",
                            "               C C               ",
                            "                D                ",
                            "                D                ",
                            "                                 ",
                            "                                 ",
                            "                                 ",
                            "                                 ",
                            "                                 ",
                            "      CC                 CC      ",
                            "        DD             DD        ",
                            "      CC                 CC      ",
                            "                                 ",
                            "                                 ",
                            "                                 ",
                            "                                 ",
                            "                                 ",
                            "                D                ",
                            "                D                ",
                            "               C C               ",
                            "               C C               ",
                            "                                 ",
                            "                                 ",
                            "                                 ",
                            "                                 ",
                            "                                 ",
                            "                                 "
                        },
                        {
                            "                                 ",
                            "                                 ",
                            "                                 ",
                            "                                 ",
                            "                                 ",
                            "               C C               ",
                            "              CCCCC              ",
                            "                D                ",
                            "                B                ",
                            "                B                ",
                            "                                 ",
                            "                                 ",
                            "                                 ",
                            "                                 ",
                            "      C                   C      ",
                            "     CC                   CC     ",
                            "      CDBB             BBDC      ",
                            "     CC                   CC     ",
                            "      C                   C      ",
                            "                                 ",
                            "                                 ",
                            "                                 ",
                            "                                 ",
                            "                B                ",
                            "                B                ",
                            "                D                ",
                            "              CCCCC              ",
                            "               C C               ",
                            "                                 ",
                            "                                 ",
                            "                                 ",
                            "                                 ",
                            "                                 "
                        },
                        {
                            "                                 ",
                            "                                 ",
                            "                                 ",
                            "                                 ",
                            "               C C               ",
                            "               C C               ",
                            "                D                ",
                            "             EEEBEEE             ",
                            "                                 ",
                            "                                 ",
                            "                                 ",
                            "                                 ",
                            "                                 ",
                            "       E                 E       ",
                            "       E                 E       ",
                            "    CC E                 E CC    ",
                            "      DB                 BD      ",
                            "    CC E                 E CC    ",
                            "       E                 E       ",
                            "       E                 E       ",
                            "                                 ",
                            "                                 ",
                            "                                 ",
                            "                                 ",
                            "                                 ",
                            "             EEEBEEE             ",
                            "                D                ",
                            "               C C               ",
                            "               C C               ",
                            "                                 ",
                            "                                 ",
                            "                                 ",
                            "                                 "
                        },
                        {
                            "                                 ",
                            "                                 ",
                            "                                 ",
                            "               C C               ",
                            "              CCCCC              ",
                            "                D                ",
                            "                B                ",
                            "                                 ",
                            "                                 ",
                            "                                 ",
                            "                                 ",
                            "                                 ",
                            "                                 ",
                            "                                 ",
                            "    C                       C    ",
                            "   CC                       CC   ",
                            "    CDB                   BDC    ",
                            "   CC                       CC   ",
                            "    C                       C    ",
                            "                                 ",
                            "                                 ",
                            "                                 ",
                            "                                 ",
                            "                                 ",
                            "                                 ",
                            "                                 ",
                            "                B                ",
                            "                D                ",
                            "              CCCCC              ",
                            "               C C               ",
                            "                                 ",
                            "                                 ",
                            "                                 "
                        },
                        {
                            "                                 ",
                            "                                 ",
                            "               C C               ",
                            "               C C               ",
                            "                D                ",
                            "             EEEBEEE             ",
                            "                                 ",
                            "                                 ",
                            "                                 ",
                            "                                 ",
                            "                                 ",
                            "                                 ",
                            "                                 ",
                            "     E                     E     ",
                            "     E                     E     ",
                            "  CC E                     E CC  ",
                            "    DB                     BD    ",
                            "  CC E                     E CC  ",
                            "     E                     E     ",
                            "     E                     E     ",
                            "                                 ",
                            "                                 ",
                            "                                 ",
                            "                                 ",
                            "                                 ",
                            "                                 ",
                            "                                 ",
                            "             EEEBEEE             ",
                            "                D                ",
                            "               C C               ",
                            "               C C               ",
                            "                                 ",
                            "                                 "
                        },
                        {
                            "                                 ",
                            "                                 ",
                            "               C C               ",
                            "                D                ",
                            "                B                ",
                            "                                 ",
                            "                                 ",
                            "                                 ",
                            "                                 ",
                            "                                 ",
                            "                                 ",
                            "                                 ",
                            "                                 ",
                            "                                 ",
                            "                                 ",
                            "  C                           C  ",
                            "   DB                       BD   ",
                            "  C                           C  ",
                            "                                 ",
                            "                                 ",
                            "                                 ",
                            "                                 ",
                            "                                 ",
                            "                                 ",
                            "                                 ",
                            "                                 ",
                            "                                 ",
                            "                                 ",
                            "                B                ",
                            "                D                ",
                            "               C C               ",
                            "                                 ",
                            "                                 "
                        },
                        {
                            "                                 ",
                            "               C C               ",
                            "               C C               ",
                            "                D                ",
                            "                B                ",
                            "                                 ",
                            "                                 ",
                            "                                 ",
                            "                                 ",
                            "                                 ",
                            "                                 ",
                            "                                 ",
                            "                                 ",
                            "                                 ",
                            "                                 ",
                            " CC                           CC ",
                            "   DB                       BD   ",
                            " CC                           CC ",
                            "                                 ",
                            "                                 ",
                            "                                 ",
                            "                                 ",
                            "                                 ",
                            "                                 ",
                            "                                 ",
                            "                                 ",
                            "                                 ",
                            "                                 ",
                            "                B                ",
                            "                D                ",
                            "               C C               ",
                            "               C C               ",
                            "                                 "
                        },
                        {
                            "                                 ",
                            "               C C               ",
                            "                D                ",
                            "                                 ",
                            "                                 ",
                            "                                 ",
                            "                                 ",
                            "                                 ",
                            "                                 ",
                            "                                 ",
                            "                                 ",
                            "                                 ",
                            "                                 ",
                            "                                 ",
                            "                                 ",
                            " C                             C ",
                            "  D                           D  ",
                            " C                             C ",
                            "                                 ",
                            "                                 ",
                            "                                 ",
                            "                                 ",
                            "                                 ",
                            "                                 ",
                            "                                 ",
                            "                                 ",
                            "                                 ",
                            "                                 ",
                            "                                 ",
                            "                                 ",
                            "                D                ",
                            "               C C               ",
                            "                                 "
                        },
                        {
                            "                                 ",
                            "               C C               ",
                            "                D                ",
                            "                                 ",
                            "                                 ",
                            "                                 ",
                            "                                 ",
                            "                                 ",
                            "                                 ",
                            "                                 ",
                            "                                 ",
                            "                                 ",
                            "                                 ",
                            "                                 ",
                            "                                 ",
                            " C                             C ",
                            "  D                           D  ",
                            " C                             C ",
                            "                                 ",
                            "                                 ",
                            "                                 ",
                            "                                 ",
                            "                                 ",
                            "                                 ",
                            "                                 ",
                            "                                 ",
                            "                                 ",
                            "                                 ",
                            "                                 ",
                            "                                 ",
                            "                D                ",
                            "               C C               ",
                            "                                 "
                        },
                        {
                            "             CCCCCCC             ",
                            "               C C               ",
                            "             DDDDDDD             ",
                            "                                 ",
                            "                                 ",
                            "                                 ",
                            "                                 ",
                            "                                 ",
                            "                                 ",
                            "                                 ",
                            "                                 ",
                            "                                 ",
                            "                                 ",
                            "  D                           D  ",
                            "  D                           D  ",
                            "CCD                           DCC",
                            "  D                           D  ",
                            "CCD                           DCC",
                            "  D                           D  ",
                            "  D                           D  ",
                            "                                 ",
                            "                                 ",
                            "                                 ",
                            "                                 ",
                            "                                 ",
                            "                                 ",
                            "                                 ",
                            "                                 ",
                            "                                 ",
                            "                                 ",
                            "             DDDDDDD             ",
                            "               C C               ",
                            "               C C               "
                        },
                        {
                            "            CCHHHHHCC            ",
                            "              DDDDD              ",
                            "            DD     DD            ",
                            "                                 ",
                            "                                 ",
                            "       E                 E       ",
                            "                                 ",
                            "     E                     E     ",
                            "                                 ",
                            "                                 ",
                            "                                 ",
                            "                                 ",
                            "  D                           D  ",
                            "  D                           D  ",
                            " D                             D ",
                            "CD                             DC",
                            " D                             D ",
                            "CD                             DC",
                            " D                             D ",
                            "  D                           D  ",
                            "  D                           D  ",
                            "                                 ",
                            "                                 ",
                            "                                 ",
                            "                                 ",
                            "     E                     E     ",
                            "                                 ",
                            "       E                 E       ",
                            "                                 ",
                            "                                 ",
                            "            DD     DD            ",
                            "              DDDDD              ",
                            "               C C               "
                        },
                        {
                            "            CHHHHHHHC            ",
                            "             DDCDCDD             ",
                            "            D  EEE  D            ",
                            "                                 ",
                            "      C                   C      ",
                            "       E                 E       ",
                            "    C                       C    ",
                            "     E                     E     ",
                            "                                 ",
                            "                                 ",
                            "                                 ",
                            "                                 ",
                            "  D                           D  ",
                            " D                             D ",
                            " D                             D ",
                            "CCE                           ECC",
                            " DE                           ED ",
                            "CCE                           ECC",
                            " D                             D ",
                            " D                             D ",
                            "  D                           D  ",
                            "                                 ",
                            "                                 ",
                            "                                 ",
                            "                                 ",
                            "     E                     E     ",
                            "    C                       C    ",
                            "       E                 E       ",
                            "      C                   C      ",
                            "                                 ",
                            "            D  EEE  D            ",
                            "             DDCDCDD             ",
                            "               C C               "
                        },
                        {
                            "            CHHFFFHHC            ",
                            "         CCCCDCCDCCDCCCC         ",
                            "       CCC  D EAAAE D  CCC       ",
                            "      CC                 CC      ",
                            "     CC                   CC     ",
                            "    CC E                 E CC    ",
                            "   CC                       CC   ",
                            "  CC E                     E CC  ",
                            "  C                           C  ",
                            " CC                           CC ",
                            " C                             C ",
                            " C                             C ",
                            "CCD                           DCC",
                            "CD                             DC",
                            "CCE                           ECC",
                            "CCA                           ACC",
                            "CDA                           ADC",
                            "CCA                           ACC",
                            "CCE                           ECC",
                            "CD                             DC",
                            "CCD                           DCC",
                            " C                             C ",
                            " C                             C ",
                            " CC                           CC ",
                            "  C                           C  ",
                            "  CC E                     E CC  ",
                            "   CC                       CC   ",
                            "    CC E                 E CC    ",
                            "     CC                   CC     ",
                            "      CC                 CC      ",
                            "       CCC  D EAAAE D  CCC       ",
                            "         CCCCDCCDCCDCCCC         ",
                            "            CCCCCCCCC            "
                        },
                        {
                            "            CHHF~FHHC            ",
                            "             DDDDDDD             ",
                            "          DDD EAAAE DDD          ",
                            "        DD             DD        ",
                            "      CDBB             BBDC      ",
                            "      DB                 BD      ",
                            "    CDB                   BDC    ",
                            "    DB                     BD    ",
                            "   DB                       BD   ",
                            "   DB                       BD   ",
                            "  D                           D  ",
                            "  D                           D  ",
                            "  D                           D  ",
                            " D                             D ",
                            " DE                           ED ",
                            "CDA                           ADC",
                            " DA                           AD ",
                            "CDA                           ADC",
                            " DE                           ED ",
                            " D                             D ",
                            "  D                           D  ",
                            "  D                           D  ",
                            "  D                           D  ",
                            "   DB                       BD   ",
                            "   DB                       BD   ",
                            "    DB                     BD    ",
                            "    CDB                   BDC    ",
                            "      DB                 BD      ",
                            "      CDBB             BBDC      ",
                            "        DD             DD        ",
                            "          DDD EAAAE DDD          ",
                            "             DDDDDDD             ",
                            "               C C               "
                        },
                        {
                            "            CHHFFFHHC            ",
                            "         CCCCDCCDCCDCCCC         ",
                            "       CCC  D EAAAE D  CCC       ",
                            "      CC                 CC      ",
                            "     CC                   CC     ",
                            "    CC E                 E CC    ",
                            "   CC                       CC   ",
                            "  CC E                     E CC  ",
                            "  C                           C  ",
                            " CC                           CC ",
                            " C                             C ",
                            " C                             C ",
                            "CCD                           DCC",
                            "CD                             DC",
                            "CCE                           ECC",
                            "CCA                           ACC",
                            "CDA                           ADC",
                            "CCA                           ACC",
                            "CCE                           ECC",
                            "CD                             DC",
                            "CCD                           DCC",
                            " C                             C ",
                            " C                             C ",
                            " CC                           CC ",
                            "  C                           C  ",
                            "  CC E                     E CC  ",
                            "   CC                       CC   ",
                            "    CC E                 E CC    ",
                            "     CC                   CC     ",
                            "      CC                 CC      ",
                            "       CCC  D EAAAE D  CCC       ",
                            "         CCCCDCCDCCDCCCC         ",
                            "            CCCCCCCCC            "
                        },
                        {
                            "            CHHHHHHHC            ",
                            "             DDCDCDD             ",
                            "            D  EEE  D            ",
                            "                                 ",
                            "      C                   C      ",
                            "       E                 E       ",
                            "    C                       C    ",
                            "     E                     E     ",
                            "                                 ",
                            "                                 ",
                            "                                 ",
                            "                                 ",
                            "  D                           D  ",
                            " D                             D ",
                            " D                             D ",
                            "CCE                           ECC",
                            " DE                           ED ",
                            "CCE                           ECC",
                            " D                             D ",
                            " D                             D ",
                            "  D                           D  ",
                            "                                 ",
                            "                                 ",
                            "                                 ",
                            "                                 ",
                            "     E                     E     ",
                            "    C                       C    ",
                            "       E                 E       ",
                            "      C                   C      ",
                            "                                 ",
                            "            D  EEE  D            ",
                            "             DDCDCDD             ",
                            "               C C               "
                        },
                        {
                            "            CCHHHHHCC            ",
                            "              DDDDD              ",
                            "            DD     DD            ",
                            "                                 ",
                            "                                 ",
                            "       E                 E       ",
                            "                                 ",
                            "     E                     E     ",
                            "                                 ",
                            "                                 ",
                            "                                 ",
                            "                                 ",
                            "  D                           D  ",
                            "  D                           D  ",
                            " D                             D ",
                            "CD                             DC",
                            " D                             D ",
                            "CD                             DC",
                            " D                             D ",
                            "  D                           D  ",
                            "  D                           D  ",
                            "                                 ",
                            "                                 ",
                            "                                 ",
                            "                                 ",
                            "     E                     E     ",
                            "                                 ",
                            "       E                 E       ",
                            "                                 ",
                            "                                 ",
                            "            DD     DD            ",
                            "              DDDDD              ",
                            "               C C               "
                        },
                        {
                            "             CCCCCCC             ",
                            "               C C               ",
                            "             DDDDDDD             ",
                            "                                 ",
                            "                                 ",
                            "                                 ",
                            "                                 ",
                            "                                 ",
                            "                                 ",
                            "                                 ",
                            "                                 ",
                            "                                 ",
                            "                                 ",
                            "  D                           D  ",
                            "  D                           D  ",
                            "CCD                           DCC",
                            "  D                           D  ",
                            "CCD                           DCC",
                            "  D                           D  ",
                            "  D                           D  ",
                            "                                 ",
                            "                                 ",
                            "                                 ",
                            "                                 ",
                            "                                 ",
                            "                                 ",
                            "                                 ",
                            "                                 ",
                            "                                 ",
                            "                                 ",
                            "             DDDDDDD             ",
                            "               C C               ",
                            "               C C               "
                        },
                        {
                            "                                 ",
                            "               C C               ",
                            "                D                ",
                            "                                 ",
                            "                                 ",
                            "                                 ",
                            "                                 ",
                            "                                 ",
                            "                                 ",
                            "                                 ",
                            "                                 ",
                            "                                 ",
                            "                                 ",
                            "                                 ",
                            "                                 ",
                            " C                             C ",
                            "  D                           D  ",
                            " C                             C ",
                            "                                 ",
                            "                                 ",
                            "                                 ",
                            "                                 ",
                            "                                 ",
                            "                                 ",
                            "                                 ",
                            "                                 ",
                            "                                 ",
                            "                                 ",
                            "                                 ",
                            "                                 ",
                            "                D                ",
                            "               C C               ",
                            "                                 "
                        },
                        {
                            "                                 ",
                            "               C C               ",
                            "                D                ",
                            "                                 ",
                            "                                 ",
                            "                                 ",
                            "                                 ",
                            "                                 ",
                            "                                 ",
                            "                                 ",
                            "                                 ",
                            "                                 ",
                            "                                 ",
                            "                                 ",
                            "                                 ",
                            " C                             C ",
                            "  D                           D  ",
                            " C                             C ",
                            "                                 ",
                            "                                 ",
                            "                                 ",
                            "                                 ",
                            "                                 ",
                            "                                 ",
                            "                                 ",
                            "                                 ",
                            "                                 ",
                            "                                 ",
                            "                                 ",
                            "                                 ",
                            "                D                ",
                            "               C C               ",
                            "                                 "
                        },
                        {
                            "                                 ",
                            "               C C               ",
                            "               C C               ",
                            "                D                ",
                            "                B                ",
                            "                                 ",
                            "                                 ",
                            "                                 ",
                            "                                 ",
                            "                                 ",
                            "                                 ",
                            "                                 ",
                            "                                 ",
                            "                                 ",
                            "                                 ",
                            " CC                           CC ",
                            "   DB                       BD   ",
                            " CC                           CC ",
                            "                                 ",
                            "                                 ",
                            "                                 ",
                            "                                 ",
                            "                                 ",
                            "                                 ",
                            "                                 ",
                            "                                 ",
                            "                                 ",
                            "                                 ",
                            "                B                ",
                            "                D                ",
                            "               C C               ",
                            "               C C               ",
                            "                                 "
                        },
                        {
                            "                                 ",
                            "                                 ",
                            "               C C               ",
                            "                D                ",
                            "                B                ",
                            "                                 ",
                            "                                 ",
                            "                                 ",
                            "                                 ",
                            "                                 ",
                            "                                 ",
                            "                                 ",
                            "                                 ",
                            "                                 ",
                            "                                 ",
                            "  C                           C  ",
                            "   DB                       BD   ",
                            "  C                           C  ",
                            "                                 ",
                            "                                 ",
                            "                                 ",
                            "                                 ",
                            "                                 ",
                            "                                 ",
                            "                                 ",
                            "                                 ",
                            "                                 ",
                            "                                 ",
                            "                B                ",
                            "                D                ",
                            "               C C               ",
                            "                                 ",
                            "                                 "
                        },
                        {
                            "                                 ",
                            "                                 ",
                            "               C C               ",
                            "               C C               ",
                            "                D                ",
                            "             EEEBEEE             ",
                            "                                 ",
                            "                                 ",
                            "                                 ",
                            "                                 ",
                            "                                 ",
                            "                                 ",
                            "                                 ",
                            "     E                     E     ",
                            "     E                     E     ",
                            "  CC E                     E CC  ",
                            "    DB                     BD    ",
                            "  CC E                     E CC  ",
                            "     E                     E     ",
                            "     E                     E     ",
                            "                                 ",
                            "                                 ",
                            "                                 ",
                            "                                 ",
                            "                                 ",
                            "                                 ",
                            "                                 ",
                            "             EEEBEEE             ",
                            "                D                ",
                            "               C C               ",
                            "               C C               ",
                            "                                 ",
                            "                                 "
                        },
                        {
                            "                                 ",
                            "                                 ",
                            "                                 ",
                            "               C C               ",
                            "              CCCCC              ",
                            "                D                ",
                            "                B                ",
                            "                                 ",
                            "                                 ",
                            "                                 ",
                            "                                 ",
                            "                                 ",
                            "                                 ",
                            "                                 ",
                            "    C                       C    ",
                            "   CC                       CC   ",
                            "    CDB                   BDC    ",
                            "   CC                       CC   ",
                            "    C                       C    ",
                            "                                 ",
                            "                                 ",
                            "                                 ",
                            "                                 ",
                            "                                 ",
                            "                                 ",
                            "                                 ",
                            "                B                ",
                            "                D                ",
                            "              CCCCC              ",
                            "               C C               ",
                            "                                 ",
                            "                                 ",
                            "                                 "
                        },
                        {
                            "                                 ",
                            "                                 ",
                            "                                 ",
                            "                                 ",
                            "               C C               ",
                            "               C C               ",
                            "                D                ",
                            "             EEEBEEE             ",
                            "                                 ",
                            "                                 ",
                            "                                 ",
                            "                                 ",
                            "                                 ",
                            "       E                 E       ",
                            "       E                 E       ",
                            "    CC E                 E CC    ",
                            "      DB                 BD      ",
                            "    CC E                 E CC    ",
                            "       E                 E       ",
                            "       E                 E       ",
                            "                                 ",
                            "                                 ",
                            "                                 ",
                            "                                 ",
                            "                                 ",
                            "             EEEBEEE             ",
                            "                D                ",
                            "               C C               ",
                            "               C C               ",
                            "                                 ",
                            "                                 ",
                            "                                 ",
                            "                                 "
                        },
                        {
                            "                                 ",
                            "                                 ",
                            "                                 ",
                            "                                 ",
                            "                                 ",
                            "               C C               ",
                            "              CCCCC              ",
                            "                D                ",
                            "                B                ",
                            "                B                ",
                            "                                 ",
                            "                                 ",
                            "                                 ",
                            "                                 ",
                            "      C                   C      ",
                            "     CC                   CC     ",
                            "      CDBB             BBDC      ",
                            "     CC                   CC     ",
                            "      C                   C      ",
                            "                                 ",
                            "                                 ",
                            "                                 ",
                            "                                 ",
                            "                B                ",
                            "                B                ",
                            "                D                ",
                            "              CCCCC              ",
                            "               C C               ",
                            "                                 ",
                            "                                 ",
                            "                                 ",
                            "                                 ",
                            "                                 "
                        },
                        {
                            "                                 ",
                            "                                 ",
                            "                                 ",
                            "                                 ",
                            "                                 ",
                            "                                 ",
                            "               C C               ",
                            "               C C               ",
                            "                D                ",
                            "                D                ",
                            "                                 ",
                            "                                 ",
                            "                                 ",
                            "                                 ",
                            "                                 ",
                            "      CC                 CC      ",
                            "        DD             DD        ",
                            "      CC                 CC      ",
                            "                                 ",
                            "                                 ",
                            "                                 ",
                            "                D                ",
                            "                D                ",
                            "                D                ",
                            "                D                ",
                            "               C C               ",
                            "               C C               ",
                            "                                 ",
                            "                                 ",
                            "                                 ",
                            "                                 ",
                            "                                 ",
                            "                                 "
                        },
                        {
                            "                                 ",
                            "                                 ",
                            "                                 ",
                            "                                 ",
                            "                                 ",
                            "                                 ",
                            "                                 ",
                            "               C C               ",
                            "               C C               ",
                            "               C C               ",
                            "                D                ",
                            "                D                ",
                            "             DDDDDDD             ",
                            "            DD     DD            ",
                            "            D  EEE  D            ",
                            "       CCC  D EAAAE D  CCC       ",
                            "          DDD EAAAE DDD          ",
                            "       CCC  D EAAAE D  CCC       ",
                            "            D  EEE  D            ",
                            "            DD     DD            ",
                            "             DDDDDDD             ",
                            "                D                ",
                            "                D                ",
                            "               C C               ",
                            "               C C               ",
                            "               C C               ",
                            "                                 ",
                            "                                 ",
                            "                                 ",
                            "                                 ",
                            "                                 ",
                            "                                 ",
                            "                                 "
                        },
                        {
                            "                                 ",
                            "                                 ",
                            "                                 ",
                            "                                 ",
                            "                                 ",
                            "                                 ",
                            "                                 ",
                            "                                 ",
                            "                                 ",
                            "               C C               ",
                            "               C C               ",
                            "               C C               ",
                            "               C C               ",
                            "              DDDDD              ",
                            "             DDCDCDD             ",
                            "         CCCCDCCDCCDCCCC         ",
                            "             DDDDDDD             ",
                            "         CCCCDCCDCCDCCCC         ",
                            "             DDCDCDD             ",
                            "              DDDDD              ",
                            "               C C               ",
                            "               C C               ",
                            "               C C               ",
                            "               C C               ",
                            "                                 ",
                            "                                 ",
                            "                                 ",
                            "                                 ",
                            "                                 ",
                            "                                 ",
                            "                                 ",
                            "                                 ",
                            "                                 "
                        },
                        {
                            "                                 ",
                            "                                 ",
                            "                                 ",
                            "                                 ",
                            "                                 ",
                            "                                 ",
                            "                                 ",
                            "                                 ",
                            "                                 ",
                            "                                 ",
                            "                                 ",
                            "                                 ",
                            "               C C               ",
                            "               C C               ",
                            "               C C               ",
                            "            CCCCCCCCC            ",
                            "               C C               ",
                            "            CCCCCCCCC            ",
                            "               C C               ",
                            "               C C               ",
                            "               C C               ",
                            "                                 ",
                            "                                 ",
                            "                                 ",
                            "                                 ",
                            "                                 ",
                            "                                 ",
                            "                                 ",
                            "                                 ",
                            "                                 ",
                            "                                 ",
                            "                                 ",
                            "                                 "
                        }
                    }))
                    .addShape("main_t2", transpose(new String[][] {
                        {
                            "                                 ",
                            "                                 ",
                            "                                 ",
                            "                                 ",
                            "                                 ",
                            "                                 ",
                            "                                 ",
                            "                                 ",
                            "                                 ",
                            "                                 ",
                            "                                 ",
                            "                                 ",
                            "               C C               ",
                            "               C C               ",
                            "               C C               ",
                            "            CCCCCCCCC            ",
                            "               C C               ",
                            "            CCCCCCCCC            ",
                            "               C C               ",
                            "               C C               ",
                            "               C C               ",
                            "                                 ",
                            "                                 ",
                            "                                 ",
                            "                                 ",
                            "                                 ",
                            "                                 ",
                            "                                 ",
                            "                                 ",
                            "                                 ",
                            "                                 ",
                            "                                 ",
                            "                                 "
                        },
                        {
                            "                                 ",
                            "                                 ",
                            "                                 ",
                            "                                 ",
                            "                                 ",
                            "                                 ",
                            "                                 ",
                            "                                 ",
                            "                                 ",
                            "               C C               ",
                            "             GGC CGG             ",
                            "            GGGC CGGG            ",
                            "           GGGGC CGGGG           ",
                            "          GGGGDDDDDGGGG          ",
                            "          GGGDDCDCDDGGG          ",
                            "         CCCCDCCDCCDCCCC         ",
                            "             DDDDDDD             ",
                            "         CCCCDCCDCCDCCCC         ",
                            "          GGGDDCDCDDGGG          ",
                            "          GGGGDDDDDGGGG          ",
                            "           GGGGC CGGGG           ",
                            "            GGGC CGGG            ",
                            "             GGC CGG             ",
                            "               C C               ",
                            "                                 ",
                            "                                 ",
                            "                                 ",
                            "                                 ",
                            "                                 ",
                            "                                 ",
                            "                                 ",
                            "                                 ",
                            "                                 "
                        },
                        {
                            "                                 ",
                            "                                 ",
                            "                                 ",
                            "                                 ",
                            "                                 ",
                            "                                 ",
                            "                                 ",
                            "               C C               ",
                            "             GGC CGG             ",
                            "           GGGGC CGGGG           ",
                            "          GGG   D   GGG          ",
                            "         GGG    D    GGG         ",
                            "         GG  DDDDDDD  GG         ",
                            "        GG  DD     DD  GG        ",
                            "        GG  D  EEE  D  GG        ",
                            "       CCC  D EAAAE D  CCC       ",
                            "          DDD EAAAE DDD          ",
                            "       CCC  D EAAAE D  CCC       ",
                            "        GG  D  EEE  D  GG        ",
                            "        GG  DD     DD  GG        ",
                            "         GG  DDDDDDD  GG         ",
                            "         GGG    D    GGG         ",
                            "          GGG   D   GGG          ",
                            "           GGGGC CGGGG           ",
                            "             GGC CGG             ",
                            "               C C               ",
                            "                                 ",
                            "                                 ",
                            "                                 ",
                            "                                 ",
                            "                                 ",
                            "                                 ",
                            "                                 "
                        },
                        {
                            "                                 ",
                            "                                 ",
                            "                                 ",
                            "                                 ",
                            "                                 ",
                            "                                 ",
                            "               C C               ",
                            "            GGGC CGGG            ",
                            "          GGG   D   GGG          ",
                            "         GG     D     GG         ",
                            "        GG             GG        ",
                            "        G               G        ",
                            "       GG               GG       ",
                            "       G                 G       ",
                            "       G                 G       ",
                            "      CC                 CC      ",
                            "        DD             DD        ",
                            "      CC                 CC      ",
                            "       G                 G       ",
                            "       G                 G       ",
                            "       GG               GG       ",
                            "        G               G        ",
                            "        GG             GG        ",
                            "         GG     D     GG         ",
                            "          GGG   D   GGG          ",
                            "            GGGC CGGG            ",
                            "               C C               ",
                            "                                 ",
                            "                                 ",
                            "                                 ",
                            "                                 ",
                            "                                 ",
                            "                                 "
                        },
                        {
                            "                                 ",
                            "                                 ",
                            "                                 ",
                            "                                 ",
                            "                                 ",
                            "               C C               ",
                            "           GGGCCCCCGGG           ",
                            "         GGG    D    GGG         ",
                            "        GG      B      GG        ",
                            "       GG       B       GG       ",
                            "       G                 G       ",
                            "      GG                 GG      ",
                            "      G                   G      ",
                            "      G                   G      ",
                            "      C                   C      ",
                            "     CC                   CC     ",
                            "      CDBB             BBDC      ",
                            "     CC                   CC     ",
                            "      C                   C      ",
                            "      G                   G      ",
                            "      G                   G      ",
                            "      GG                 GG      ",
                            "       G                 G       ",
                            "       GG       B       GG       ",
                            "        GG      B      GG        ",
                            "         GGG    D    GGG         ",
                            "           GGGCCCCCGGG           ",
                            "               C C               ",
                            "                                 ",
                            "                                 ",
                            "                                 ",
                            "                                 ",
                            "                                 "
                        },
                        {
                            "                                 ",
                            "                                 ",
                            "                                 ",
                            "                                 ",
                            "               C C               ",
                            "          GGGGGC CGGGGG          ",
                            "        GGG     D     GGG        ",
                            "       GG    EEEBEEE    GG       ",
                            "      GG                 GG      ",
                            "      G                   G      ",
                            "     GG                   GG     ",
                            "     G                     G     ",
                            "     G                     G     ",
                            "     G E                 E G     ",
                            "     G E                 E G     ",
                            "    CC E                 E CC    ",
                            "      DB                 BD      ",
                            "    CC E                 E CC    ",
                            "     G E                 E G     ",
                            "     G E                 E G     ",
                            "     G                     G     ",
                            "     G                     G     ",
                            "     GG                   GG     ",
                            "      G                   G      ",
                            "      GG                 GG      ",
                            "       GG    EEEBEEE    GG       ",
                            "        GGG     D     GGG        ",
                            "          GGGGGC CGGGGG          ",
                            "               C C               ",
                            "                                 ",
                            "                                 ",
                            "                                 ",
                            "                                 "
                        },
                        {
                            "                                 ",
                            "                                 ",
                            "                                 ",
                            "               C C               ",
                            "           GGGCCCCCGGG           ",
                            "        GGG     D     GGG        ",
                            "       GG       B       GG       ",
                            "      G                   G      ",
                            "     GG                   GG     ",
                            "     G                     G     ",
                            "     G                     G     ",
                            "    G                       G    ",
                            "    G                       G    ",
                            "    G                       G    ",
                            "    C                       C    ",
                            "   CC                       CC   ",
                            "    CDB                   BDC    ",
                            "   CC                       CC   ",
                            "    C                       C    ",
                            "    G                       G    ",
                            "    G                       G    ",
                            "    G                       G    ",
                            "     G                     G     ",
                            "     G                     G     ",
                            "     GG                   GG     ",
                            "      G                   G      ",
                            "       GG       B       GG       ",
                            "        GGG     D     GGG        ",
                            "           GGGCCCCCGGG           ",
                            "               C C               ",
                            "                                 ",
                            "                                 ",
                            "                                 "
                        },
                        {
                            "                                 ",
                            "                                 ",
                            "               C C               ",
                            "            GGGC CGGG            ",
                            "         GGG    D    GGG         ",
                            "       GG    EEEBEEE    GG       ",
                            "      G                   G      ",
                            "     G                     G     ",
                            "     G                     G     ",
                            "    G                       G    ",
                            "    G                       G    ",
                            "    G                       G    ",
                            "   G                         G   ",
                            "   G E                     E G   ",
                            "   G E                     E G   ",
                            "  CC E                     E CC  ",
                            "    DB                     BD    ",
                            "  CC E                     E CC  ",
                            "   G E                     E G   ",
                            "   G E                     E G   ",
                            "   G                         G   ",
                            "    G                       G    ",
                            "    G                       G    ",
                            "    G                       G    ",
                            "     G                     G     ",
                            "     G                     G     ",
                            "      G                   G      ",
                            "       GG    EEEBEEE    GG       ",
                            "         GGG    D    GGG         ",
                            "            GGGC CGGG            ",
                            "               C C               ",
                            "                                 ",
                            "                                 "
                        },
                        {
                            "                                 ",
                            "                                 ",
                            "             GGC CGG             ",
                            "          GGG   D   GGG          ",
                            "        GG      B      GG        ",
                            "      GG                 GG      ",
                            "     GG                   GG     ",
                            "     G                     G     ",
                            "    G                       G    ",
                            "    G                       G    ",
                            "   G                         G   ",
                            "   G                         G   ",
                            "   G                         G   ",
                            "  G                           G  ",
                            "  G                           G  ",
                            "  C                           C  ",
                            "   DB                       BD   ",
                            "  C                           C  ",
                            "  G                           G  ",
                            "  G                           G  ",
                            "   G                         G   ",
                            "   G                         G   ",
                            "   G                         G   ",
                            "    G                       G    ",
                            "    G                       G    ",
                            "     G                     G     ",
                            "     GG                   GG     ",
                            "      GG                 GG      ",
                            "        GG      B      GG        ",
                            "          GGG   D   GGG          ",
                            "             GGC CGG             ",
                            "                                 ",
                            "                                 "
                        },
                        {
                            "                                 ",
                            "               C C               ",
                            "           GGGGC CGGGG           ",
                            "         GG     D     GG         ",
                            "       GG       B       GG       ",
                            "      G                   G      ",
                            "     G                     G     ",
                            "    G                       G    ",
                            "    G                       G    ",
                            "   G                         G   ",
                            "   G                         G   ",
                            "  G                           G  ",
                            "  G                           G  ",
                            "  G                           G  ",
                            "  G                           G  ",
                            " CC                           CC ",
                            "   DB                       BD   ",
                            " CC                           CC ",
                            "  G                           G  ",
                            "  G                           G  ",
                            "  G                           G  ",
                            "  G                           G  ",
                            "   G                         G   ",
                            "   G                         G   ",
                            "    G                       G    ",
                            "    G                       G    ",
                            "     G                     G     ",
                            "      G                   G      ",
                            "       GG       B       GG       ",
                            "         GG     D     GG         ",
                            "           GGGGC CGGGG           ",
                            "               C C               ",
                            "                                 "
                        },
                        {
                            "                                 ",
                            "             GGC CGG             ",
                            "          GGG   D   GGG          ",
                            "        GG             GG        ",
                            "       G                 G       ",
                            "     GG                   GG     ",
                            "     G                     G     ",
                            "    G                       G    ",
                            "   G                         G   ",
                            "   G                         G   ",
                            "  G                           G  ",
                            "  G                           G  ",
                            "  G                           G  ",
                            " G                             G ",
                            " G                             G ",
                            " C                             C ",
                            "  D                           D  ",
                            " C                             C ",
                            " G                             G ",
                            " G                             G ",
                            "  G                           G  ",
                            "  G                           G  ",
                            "  G                           G  ",
                            "   G                         G   ",
                            "   G                         G   ",
                            "    G                       G    ",
                            "     G                     G     ",
                            "     GG                   GG     ",
                            "       G                 G       ",
                            "        GG             GG        ",
                            "          GGG   D   GGG          ",
                            "             GGC CGG             ",
                            "                                 "
                        },
                        {
                            "                                 ",
