package tectech.thing.metaTileEntity.multi;

import static com.gtnewhorizon.structurelib.structure.StructureUtility.ofBlock;
import static com.gtnewhorizon.structurelib.structure.StructureUtility.ofBlocksTiered;
import static com.gtnewhorizon.structurelib.structure.StructureUtility.transpose;
import static com.gtnewhorizon.structurelib.structure.StructureUtility.withChannel;
import static gregtech.api.enums.GTValues.AuthorColen;
import static gregtech.api.enums.HatchElement.InputBus;
import static gregtech.api.enums.HatchElement.InputHatch;
import static gregtech.api.enums.HatchElement.OutputBus;
import static gregtech.api.enums.HatchElement.OutputHatch;
import static gregtech.api.util.GTStructureUtility.buildHatchAdder;
import static gregtech.api.util.GTUtility.formatNumbers;
import static gregtech.api.util.ParallelHelper.calculateChancedOutputMultiplier;
import static gregtech.common.misc.WirelessNetworkManager.addEUToGlobalEnergyMap;
import static gregtech.common.misc.WirelessNetworkManager.strongCheckOrAddUser;
import static java.lang.Math.exp;
import static java.lang.Math.max;
import static java.lang.Math.pow;
import static kekztech.util.Util.toStandardForm;
import static net.minecraft.util.EnumChatFormatting.AQUA;
import static net.minecraft.util.EnumChatFormatting.BLUE;
import static net.minecraft.util.EnumChatFormatting.GOLD;
import static net.minecraft.util.EnumChatFormatting.GRAY;
import static net.minecraft.util.EnumChatFormatting.GREEN;
import static net.minecraft.util.EnumChatFormatting.RED;
import static net.minecraft.util.EnumChatFormatting.RESET;
import static net.minecraft.util.EnumChatFormatting.YELLOW;

import java.math.BigInteger;
import java.util.ArrayList;
import java.util.Arrays;
import java.util.HashMap;
import java.util.List;
import java.util.Map;
import java.util.UUID;

import javax.annotation.Nonnull;

import net.minecraft.client.renderer.texture.IIconRegister;
import net.minecraft.entity.player.EntityPlayer;
import net.minecraft.entity.player.EntityPlayerMP;
import net.minecraft.init.Blocks;
import net.minecraft.item.ItemStack;
import net.minecraft.nbt.NBTTagCompound;
import net.minecraft.util.ChatComponentText;
import net.minecraft.util.EnumChatFormatting;
import net.minecraft.util.MathHelper;
import net.minecraftforge.common.util.ForgeDirection;
import net.minecraftforge.fluids.Fluid;
import net.minecraftforge.fluids.FluidStack;

import org.apache.commons.lang3.tuple.Pair;
import org.jetbrains.annotations.NotNull;

import com.google.common.collect.ImmutableList;
import com.gtnewhorizon.structurelib.alignment.constructable.IConstructable;
import com.gtnewhorizon.structurelib.alignment.constructable.ISurvivalConstructable;
import com.gtnewhorizon.structurelib.structure.IItemSource;
import com.gtnewhorizon.structurelib.structure.IStructureDefinition;

import cpw.mods.fml.relauncher.Side;
import cpw.mods.fml.relauncher.SideOnly;
import gregtech.api.enums.Materials;
import gregtech.api.enums.MaterialsUEVplus;
import gregtech.api.enums.Textures;
import gregtech.api.interfaces.ITexture;
import gregtech.api.interfaces.metatileentity.IMetaTileEntity;
import gregtech.api.interfaces.tileentity.IGregTechTileEntity;
import gregtech.api.recipe.RecipeMap;
import gregtech.api.recipe.check.CheckRecipeResult;
import gregtech.api.recipe.check.CheckRecipeResultRegistry;
import gregtech.api.recipe.check.SimpleCheckRecipeResult;
import gregtech.api.util.GTLanguageManager;
import gregtech.api.util.GTUtility;
import gregtech.api.util.MultiblockTooltipBuilder;
import gregtech.api.util.shutdown.ShutDownReason;
import gregtech.common.tileentities.machines.MTEHatchInputBusME;
import gregtech.common.tileentities.machines.MTEHatchOutputBusME;
import gregtech.common.tileentities.machines.MTEHatchOutputME;
import gtPlusPlus.core.util.minecraft.ItemUtils;
import gtneioreplugin.plugin.block.BlockDimensionDisplay;
import gtneioreplugin.plugin.block.ModBlocks;
import tectech.TecTech;
import tectech.recipe.EyeOfHarmonyRecipe;
import tectech.recipe.TecTechRecipeMaps;
import tectech.thing.CustomItemList;
import tectech.thing.block.TileEntityEyeOfHarmony;
import tectech.thing.casing.BlockGTCasingsTT;
import tectech.thing.casing.TTCasingsContainer;
import tectech.thing.metaTileEntity.multi.base.TTMultiblockBase;
import tectech.thing.metaTileEntity.multi.base.render.TTRenderedExtendedFacingTexture;
import tectech.util.CommonValues;
import tectech.util.FluidStackLong;
import tectech.util.ItemStackLong;

@SuppressWarnings("SpellCheckingInspection")
public class MTEEyeOfHarmony extends TTMultiblockBase implements IConstructable, ISurvivalConstructable {

    public static final boolean EOH_DEBUG_MODE = false;
    private static final long MOLTEN_SPACETIME_PER_FAILURE_TIER = 14_400L;
    private static final double SPACETIME_FAILURE_BASE = 2;
    private static final String TOOLTIP_BAR = GOLD
        + "---------------------------------------------------------------------------------------";

    // Region variables.
    private static Textures.BlockIcons.CustomIcon ScreenOFF;
    private static Textures.BlockIcons.CustomIcon ScreenON;

    private int spacetimeCompressionFieldMetadata = -1;
    private int timeAccelerationFieldMetadata = -1;
    private int stabilisationFieldMetadata = -1;

    private static final double SPACETIME_CASING_DIFFERENCE_DISCOUNT_PERCENTAGE = 0.03;
    private static final double TIME_ACCEL_DECREASE_CHANCE_PER_TIER = 0.0925;
    // % Increase in recipe chance and % decrease in yield per tier.
    private static final double STABILITY_INCREASE_PROBABILITY_DECREASE_YIELD_PER_TIER = 0.05;
    private static final double PARALLEL_FOR_FIRST_ASTRAL_ARRAY = 8;
    private static final double CONSTANT_FOR_LOG = 1.7;
    private static final double LOG_CONSTANT = Math.log(CONSTANT_FOR_LOG);
    private static final double PARALLEL_MULTIPLIER_CONSTANT = 1.63;
    private static final double POWER_DIVISION_CONSTANT = 20.7;
    private static final double POWER_INCREASE_CONSTANT = 2.3;
    private static final int TOTAL_CASING_TIERS_WITH_POWER_PENALTY = 8;
    private static final long PRECISION_MULTIPLIER = 1_000_000;
    // Exact value to get 2^21 parallels.
    private static final long ASTRAL_ARRAY_LIMIT = 8637;

    private UUID userUUID;
    private BigInteger outputEU_BigInt = BigInteger.ZERO;
    private long startEU = 0;

    @Override
    public int survivalConstruct(ItemStack stackSize, int elementBudget, IItemSource source, EntityPlayerMP actor) {
        if (mMachine) return -1;
        int realBudget = elementBudget >= 200 ? elementBudget : Math.min(200, elementBudget * 5); // 200 blocks max per
                                                                                                  // placement.
        return survivialBuildPiece(STRUCTURE_PIECE_MAIN, stackSize, 16, 16, 0, realBudget, source, actor, false, true);
    }

    protected static final String STRUCTURE_PIECE_MAIN = "main";

    // Multiblock structure.
    private static final IStructureDefinition<MTEEyeOfHarmony> STRUCTURE_DEFINITION = IStructureDefinition
        .<MTEEyeOfHarmony>builder()
        .addShape(
            STRUCTURE_PIECE_MAIN,
            transpose(
                new String[][] {
                    { "                                 ", "                                 ",
                        "                                 ", "                                 ",
                        "                                 ", "                                 ",
                        "                                 ", "                                 ",
                        "                                 ", "                                 ",
                        "                                 ", "                                 ",
                        "               C C               ", "               C C               ",
                        "               C C               ", "            CCCCCCCCC            ",
                        "               C C               ", "            CCCCCCCCC            ",
                        "               C C               ", "               C C               ",
                        "               C C               ", "                                 ",
                        "                                 ", "                                 ",
                        "                                 ", "                                 ",
                        "                                 ", "                                 ",
                        "                                 ", "                                 ",
                        "                                 ", "                                 ",
                        "                                 " },
                    { "                                 ", "                                 ",
                        "                                 ", "                                 ",
                        "                                 ", "                                 ",
                        "                                 ", "                                 ",
                        "                                 ", "               C C               ",
                        "               C C               ", "               C C               ",
                        "               C C               ", "              DDDDD              ",
                        "             DDCDCDD             ", "         CCCCDCCDCCDCCCC         ",
                        "             DDDDDDD             ", "         CCCCDCCDCCDCCCC         ",
                        "             DDCDCDD             ", "              DDDDD              ",
                        "               C C               ", "               C C               ",
                        "               C C               ", "               C C               ",
                        "                                 ", "                                 ",
                        "                                 ", "                                 ",
                        "                                 ", "                                 ",
                        "                                 ", "                                 ",
                        "                                 " },
                    { "                                 ", "                                 ",
                        "                                 ", "                                 ",
                        "                                 ", "                                 ",
                        "                                 ", "               C C               ",
                        "               C C               ", "               C C               ",
                        "                D                ", "                D                ",
                        "             DDDDDDD             ", "            DD     DD            ",
                        "            D  EEE  D            ", "       CCC  D EAAAE D  CCC       ",
                        "          DDD EAAAE DDD          ", "       CCC  D EAAAE D  CCC       ",
                        "            D  EEE  D            ", "            DD     DD            ",
                        "             DDDDDDD             ", "                D                ",
                        "                D                ", "               C C               ",
                        "               C C               ", "               C C               ",
                        "                                 ", "                                 ",
                        "                                 ", "                                 ",
                        "                                 ", "                                 ",
                        "                                 " },
                    { "                                 ", "                                 ",
                        "                                 ", "                                 ",
                        "                                 ", "                                 ",
                        "               C C               ", "               C C               ",
                        "                D                ", "                D                ",
                        "                                 ", "                                 ",
                        "                                 ", "                                 ",
                        "                                 ", "      CC                 CC      ",
                        "        DD             DD        ", "      CC                 CC      ",
                        "                                 ", "                                 ",
                        "                                 ", "                                 ",
                        "                                 ", "                D                ",
                        "                D                ", "               C C               ",
                        "               C C               ", "                                 ",
                        "                                 ", "                                 ",
                        "                                 ", "                                 ",
                        "                                 " },
                    { "                                 ", "                                 ",
                        "                                 ", "                                 ",
                        "                                 ", "               C C               ",
                        "              CCCCC              ", "                D                ",
                        "                A                ", "                A                ",
                        "                                 ", "                                 ",
                        "                                 ", "                                 ",
                        "      C                   C      ", "     CC                   CC     ",
                        "      CDAA             AADC      ", "     CC                   CC     ",
                        "      C                   C      ", "                                 ",
                        "                                 ", "                                 ",
                        "                                 ", "                A                ",
                        "                A                ", "                D                ",
                        "              CCCCC              ", "               C C               ",
                        "                                 ", "                                 ",
                        "                                 ", "                                 ",
                        "                                 " },
                    { "                                 ", "                                 ",
                        "                                 ", "                                 ",
                        "               C C               ", "               C C               ",
                        "                D                ", "             SEEAEES             ",
                        "                                 ", "                                 ",
                        "                                 ", "                                 ",
                        "                                 ", "       S                 S       ",
                        "       E                 E       ", "    CC E                 E CC    ",
                        "      DA                 AD      ", "    CC E                 E CC    ",
                        "       E                 E       ", "       S                 S       ",
                        "                                 ", "                                 ",
                        "                                 ", "                                 ",
                        "                                 ", "             SEEAEES             ",
                        "                D                ", "               C C               ",
                        "               C C               ", "                                 ",
                        "                                 ", "                                 ",
                        "                                 " },
                    { "                                 ", "                                 ",
                        "                                 ", "               C C               ",
                        "              CCCCC              ", "                D                ",
                        "                A                ", "                                 ",
                        "                                 ", "                                 ",
                        "                                 ", "                                 ",
                        "                                 ", "                                 ",
                        "    C                       C    ", "   CC                       CC   ",
                        "    CDA                   ADC    ", "   CC                       CC   ",
                        "    C                       C    ", "                                 ",
                        "                                 ", "                                 ",
                        "                                 ", "                                 ",
                        "                                 ", "                                 ",
                        "                A                ", "                D                ",
                        "              CCCCC              ", "               C C               ",
                        "                                 ", "                                 ",
                        "                                 " },
                    { "                                 ", "                                 ",
                        "               C C               ", "               C C               ",
                        "                D                ", "             SEEAEES             ",
                        "                                 ", "                                 ",
                        "                                 ", "                                 ",
                        "                                 ", "                                 ",
                        "                                 ", "     S                     S     ",
                        "     E                     E     ", "  CC E                     E CC  ",
                        "    DA                     AD    ", "  CC E                     E CC  ",
                        "     E                     E     ", "     S                     S     ",
                        "                                 ", "                                 ",
                        "                                 ", "                                 ",
                        "                                 ", "                                 ",
                        "                                 ", "             SEEAEES             ",
                        "                D                ", "               C C               ",
                        "               C C               ", "                                 ",
                        "                                 " },
                    { "                                 ", "                                 ",
                        "               C C               ", "                D                ",
                        "                A                ", "                                 ",
                        "                                 ", "                                 ",
                        "                                 ", "                                 ",
                        "                                 ", "                                 ",
                        "                                 ", "                                 ",
                        "                                 ", "  C                           C  ",
                        "   DA                       AD   ", "  C                           C  ",
                        "                                 ", "                                 ",
                        "                                 ", "                                 ",
                        "                                 ", "                                 ",
                        "                                 ", "                                 ",
                        "                                 ", "                                 ",
                        "                A                ", "                D                ",
                        "               C C               ", "                                 ",
                        "                                 " },
                    { "                                 ", "               C C               ",
                        "               C C               ", "                D                ",
                        "                A                ", "                                 ",
                        "                                 ", "                                 ",
                        "                                 ", "                                 ",
                        "                                 ", "                                 ",
                        "                                 ", "                                 ",
                        "                                 ", " CC                           CC ",
                        "   DA                       AD   ", " CC                           CC ",
                        "                                 ", "                                 ",
                        "                                 ", "                                 ",
                        "                                 ", "                                 ",
                        "                                 ", "                                 ",
                        "                                 ", "                                 ",
                        "                A                ", "                D                ",
                        "               C C               ", "               C C               ",
                        "                                 " },
                    { "                                 ", "               C C               ",
                        "                D                ", "                                 ",
                        "                                 ", "                                 ",
                        "                                 ", "                                 ",
                        "                                 ", "                                 ",
                        "                                 ", "                                 ",
                        "                                 ", "                                 ",
                        "                                 ", " C                             C ",
                        "  D                           D  ", " C                             C ",
                        "                                 ", "                                 ",
                        "                                 ", "                                 ",
                        "                                 ", "                                 ",
                        "                                 ", "                                 ",
                        "                                 ", "                                 ",
                        "                                 ", "                                 ",
                        "                D                ", "               C C               ",
                        "                                 " },
                    { "                                 ", "               C C               ",
                        "                D                ", "                                 ",
                        "                                 ", "                                 ",
                        "                                 ", "                                 ",
                        "                                 ", "                                 ",
                        "                                 ", "                                 ",
                        "                                 ", "                                 ",
                        "                                 ", " C                             C ",
                        "  D                           D  ", " C                             C ",
                        "                                 ", "                                 ",
                        "                                 ", "                                 ",
                        "                                 ", "                                 ",
                        "                                 ", "                                 ",
                        "                                 ", "                                 ",
                        "                                 ", "                                 ",
                        "                D                ", "               C C               ",
                        "                                 " },
                    { "             CCCCCCC             ", "               C C               ",
                        "             DDDDDDD             ", "                                 ",
                        "                                 ", "                                 ",
                        "                                 ", "                                 ",
                        "                                 ", "                                 ",
                        "                                 ", "                                 ",
                        "                                 ", "  D                           D  ",
                        "  D                           D  ", "CCD                           DCC",
                        "  D                           D  ", "CCD                           DCC",
                        "  D                           D  ", "  D                           D  ",
                        "                                 ", "                                 ",
                        "                                 ", "                                 ",
                        "                                 ", "                                 ",
                        "                                 ", "                                 ",
                        "                                 ", "                                 ",
                        "             DDDDDDD             ", "               C C               ",
                        "               C C               " },
                    { "            CCHHHHHCC            ", "              DDDDD              ",
                        "            DD     DD            ", "                                 ",
                        "                                 ", "       S                 S       ",
                        "                                 ", "     S                     S     ",
                        "                                 ", "                                 ",
                        "                                 ", "                                 ",
                        "  D                           D  ", "  D                           D  ",
                        " D                             D ", "CD                             DC",
                        " D                             D ", "CD                             DC",
                        " D                             D ", "  D                           D  ",
                        "  D                           D  ", "                                 ",
                        "                                 ", "                                 ",
                        "                                 ", "     S                     S     ",
                        "                                 ", "       S                 S       ",
                        "                                 ", "                                 ",
                        "            DD     DD            ", "              DDDDD              ",
                        "               C C               " },
                    { "            CHHHHHHHC            ", "             DDCDCDD             ",
                        "            D  EEE  D            ", "                                 ",
                        "      C                   C      ", "       E                 E       ",
                        "    C                       C    ", "     E                     E     ",
                        "                                 ", "                                 ",
                        "                                 ", "                                 ",
                        "  D                           D  ", " D                             D ",
                        " D                             D ", "CCE                           ECC",
                        " DE                           ED ", "CCE                           ECC",
                        " D                             D ", " D                             D ",
                        "  D                           D  ", "                                 ",
                        "                                 ", "                                 ",
                        "                                 ", "     E                     E     ",
                        "    C                       C    ", "       E                 E       ",
                        "      C                   C      ", "                                 ",
                        "            D  EEE  D            ", "             DDCDCDD             ",
                        "               C C               " },
                    { "            CHHCCCHHC            ", "         CCCCDCCDCCDCCCC         ",
                        "       CCC  D EAAAE D  CCC       ", "      CC                 CC      ",
                        "     CC                   CC     ", "    CC E                 E CC    ",
                        "   CC                       CC   ", "  CC E                     E CC  ",
                        "  C                           C  ", " CC                           CC ",
                        " C                             C ", " C                             C ",
                        "CCD                           DCC", "CD                             DC",
                        "CCE                           ECC", "CCA                           ACC",
                        "CDA                           ADC", "CCA                           ACC",
                        "CCE                           ECC", "CD                             DC",
                        "CCD                           DCC", " C                             C ",
                        " C                             C ", " CC                           CC ",
                        "  C                           C  ", "  CC E                     E CC  ",
                        "   CC                       CC   ", "    CC E                 E CC    ",
                        "     CC                   CC     ", "      CC                 CC      ",
                        "       CCC  D EAAAE D  CCC       ", "         CCCCDCCDCCDCCCC         ",
                        "            CCCCCCCCC            " },
                    { "            CHHC~CHHC            ", "             DDDDDDD             ",
                        "          DDD EAAAE DDD          ", "        DD             DD        ",
                        "      CDAA             AADC      ", "      DA                 AD      ",
                        "    CDA                   ADC    ", "    DA                     AD    ",
                        "   DA                       AD   ", "   DA                       AD   ",
                        "  D                           D  ", "  D                           D  ",
                        "  D                           D  ", " D                             D ",
                        " DE                           ED ", "CDA                           ADC",
                        " DA                           AD ", "CDA                           ADC",
                        " DE                           ED ", " D                             D ",
                        "  D                           D  ", "  D                           D  ",
                        "  D                           D  ", "   DA                       AD   ",
                        "   DA                       AD   ", "    DA                     AD    ",
                        "    CDA                   ADC    ", "      DA                 AD      ",
                        "      CDAA             AADC      ", "        DD             DD        ",
                        "          DDD EAAAE DDD          ", "             DDDDDDD             ",
                        "               C C               " },
                    { "            CHHCCCHHC            ", "         CCCCDCCDCCDCCCC         ",
                        "       CCC  D EAAAE D  CCC       ", "      CC                 CC      ",
                        "     CC                   CC     ", "    CC E                 E CC    ",
                        "   CC                       CC   ", "  CC E                     E CC  ",
                        "  C                           C  ", " CC                           CC ",
                        " C                             C ", " C                             C ",
                        "CCD                           DCC", "CD                             DC",
                        "CCE                           ECC", "CCA                           ACC",
                        "CDA                           ADC", "CCA                           ACC",
                        "CCE                           ECC", "CD                             DC",
                        "CCD                           DCC", " C                             C ",
                        " C                             C ", " CC                           CC ",
                        "  C                           C  ", "  CC E                     E CC  ",
                        "   CC                       CC   ", "    CC E                 E CC    ",
                        "     CC                   CC     ", "      CC                 CC      ",
                        "       CCC  D EAAAE D  CCC       ", "         CCCCDCCDCCDCCCC         ",
                        "            CCCCCCCCC            " },
                    { "            CHHHHHHHC            ", "             DDCDCDD             ",
                        "            D  EEE  D            ", "                                 ",
                        "      C                   C      ", "       E                 E       ",
                        "    C                       C    ", "     E                     E     ",
                        "                                 ", "                                 ",
                        "                                 ", "                                 ",
                        "  D                           D  ", " D                             D ",
                        " D                             D ", "CCE                           ECC",
                        " DE                           ED ", "CCE                           ECC",
                        " D                             D ", " D                             D ",
                        "  D                           D  ", "                                 ",
                        "                                 ", "                                 ",
                        "                                 ", "     E                     E     ",
                        "    C                       C    ", "       E                 E       ",
                        "      C                   C      ", "                                 ",
                        "            D  EEE  D            ", "             DDCDCDD             ",
                        "               C C               " },
                    { "            CCHHHHHCC            ", "              DDDDD              ",
                        "            DD     DD            ", "                                 ",
                        "                                 ", "       S                 S       ",
                        "                                 ", "     S                     S     ",
                        "                                 ", "                                 ",
                        "                                 ", "                                 ",
                        "  D                           D  ", "  D                           D  ",
                        " D                             D ", "CD                             DC",
                        " D                             D ", "CD                             DC",
                        " D                             D ", "  D                           D  ",
                        "  D                           D  ", "                                 ",
                        "                                 ", "                                 ",
                        "                                 ", "     S                     S     ",
                        "                                 ", "       S                 S       ",
                        "                                 ", "                                 ",
                        "            DD     DD            ", "              DDDDD              ",
                        "               C C               " },
                    { "             CCCCCCC             ", "               C C               ",
                        "             DDDDDDD             ", "                                 ",
                        "                                 ", "                                 ",
                        "                                 ", "                                 ",
                        "                                 ", "                                 ",
                        "                                 ", "                                 ",
                        "                                 ", "  D                           D  ",
                        "  D                           D  ", "CCD                           DCC",
                        "  D                           D  ", "CCD                           DCC",
                        "  D                           D  ", "  D                           D  ",
                        "                                 ", "                                 ",
                        "                                 ", "                                 ",
                        "                                 ", "                                 ",
                        "                                 ", "                                 ",
                        "                                 ", "                                 ",
                        "             DDDDDDD             ", "               C C               ",
                        "               C C               " },
                    { "                                 ", "               C C               ",
                        "                D                ", "                                 ",
                        "                                 ", "                                 ",
                        "                                 ", "                                 ",
                        "                                 ", "                                 ",
                        "                                 ", "                                 ",
                        "                                 ", "                                 ",
                        "                                 ", " C                             C ",
                        "  D                           D  ", " C                             C ",
                        "                                 ", "                                 ",
                        "                                 ", "                                 ",
                        "                                 ", "                                 ",
                        "                                 ", "                                 ",
                        "                                 ", "                                 ",
                        "                                 ", "                                 ",
                        "                D                ", "               C C               ",
                        "                                 " },
                    { "                                 ", "               C C               ",
                        "                D                ", "                                 ",
                        "                                 ", "                                 ",
                        "                                 ", "                                 ",
                        "                                 ", "                                 ",
                        "                                 ", "                                 ",
                        "                                 ", "                                 ",
                        "                                 ", " C                             C ",
                        "  D                           D  ", " C                             C ",
                        "                                 ", "                                 ",
                        "                                 ", "                                 ",
                        "                                 ", "                                 ",
                        "                                 ", "                                 ",
                        "                                 ", "                                 ",
                        "                                 ", "                                 ",
                        "                D                ", "               C C               ",
                        "                                 " },
                    { "                                 ", "               C C               ",
                        "               C C               ", "                D                ",
                        "                A                ", "                                 ",
                        "                                 ", "                                 ",
                        "                                 ", "                                 ",
                        "                                 ", "                                 ",
                        "                                 ", "                                 ",
                        "                                 ", " CC                           CC ",
                        "   DA                       AD   ", " CC                           CC ",
                        "                                 ", "                                 ",
                        "                                 ", "                                 ",
                        "                                 ", "                                 ",
                        "                                 ", "                                 ",
                        "                                 ", "                                 ",
                        "                A                ", "                D                ",
                        "               C C               ", "               C C               ",
                        "                                 " },
                    { "                                 ", "                                 ",
                        "               C C               ", "                D                ",
                        "                A                ", "                                 ",
                        "                                 ", "                                 ",
                        "                                 ", "                                 ",
                        "                                 ", "                                 ",
                        "                                 ", "                                 ",
                        "                                 ", "  C                           C  ",
                        "   DA                       AD   ", "  C                           C  ",
                        "                                 ", "                                 ",
                        "                                 ", "                                 ",
                        "                                 ", "                                 ",
                        "                                 ", "                                 ",
                        "                                 ", "                                 ",
                        "                A                ", "                D                ",
                        "               C C               ", "                                 ",
                        "                                 " },
                    { "                                 ", "                                 ",
                        "               C C               ", "               C C               ",
                        "                D                ", "             SEEAEES             ",
                        "                                 ", "                                 ",
                        "                                 ", "                                 ",
                        "                                 ", "                                 ",
                        "                                 ", "     S                     S     ",
                        "     E                     E     ", "  CC E                     E CC  ",
                        "    DA                     AD    ", "  CC E                     E CC  ",
                        "     E                     E     ", "     S                     S     ",
                        "                                 ", "                                 ",
                        "                                 ", "                                 ",
                        "                                 ", "                                 ",
                        "                                 ", "             SEEAEES             ",
                        "                D                ", "               C C               ",
                        "               C C               ", "                                 ",
                        "                                 " },
                    { "                                 ", "                                 ",
                        "                                 ", "               C C               ",
                        "              CCCCC              ", "                D                ",
                        "                A                ", "                                 ",
                        "                                 ", "                                 ",
                        "                                 ", "                                 ",
                        "                                 ", "                                 ",
                        "    C                       C    ", "   CC                       CC   ",
                        "    CDA                   ADC    ", "   CC                       CC   ",
                        "    C                       C    ", "                                 ",
                        "                                 ", "                                 ",
                        "                                 ", "                                 ",
                        "                                 ", "                                 ",
                        "                A                ", "                D                ",
                        "              CCCCC              ", "               C C               ",
                        "                                 ", "                                 ",
                        "                                 " },
                    { "                                 ", "                                 ",
                        "                                 ", "                                 ",
                        "               C C               ", "               C C               ",
                        "                D                ", "             SEEAEES             ",
                        "                                 ", "                                 ",
                        "                                 ", "                                 ",
                        "                                 ", "       S                 S       ",
                        "       E                 E       ", "    CC E                 E CC    ",
                        "      DA                 AD      ", "    CC E                 E CC    ",
                        "       E                 E       ", "       S                 S       ",
                        "                                 ", "                                 ",
                        "                                 ", "                                 ",
                        "                                 ", "             SEEAEES             ",
                        "                D                ", "               C C               ",
                        "               C C               ", "                                 ",
                        "                                 ", "                                 ",
                        "                                 " },
                    { "                                 ", "                                 ",
                        "                                 ", "                                 ",
                        "                                 ", "               C C               ",
                        "              CCCCC              ", "                D                ",
                        "                A                ", "                A                ",
                        "                                 ", "                                 ",
                        "                                 ", "                                 ",
                        "      C                   C      ", "     CC                   CC     ",
                        "      CDAA             AADC      ", "     CC                   CC     ",
                        "      C                   C      ", "                                 ",
                        "                                 ", "                                 ",
                        "                                 ", "                A                ",
                        "                A                ", "                D                ",
                        "              CCCCC              ", "               C C               ",
                        "                                 ", "                                 ",
                        "                                 ", "                                 ",
                        "                                 " },
                    { "                                 ", "                                 ",
                        "                                 ", "                                 ",
                        "                                 ", "                                 ",
                        "               C C               ", "               C C               ",
                        "                D                ", "                D                ",
                        "                                 ", "                                 ",
                        "                                 ", "                                 ",
                        "                                 ", "      CC                 CC      ",
                        "        DD             DD        ", "      CC                 CC      ",
                        "                                 ", "                                 ",
                        "                                 ", "                                 ",
                        "                                 ", "                D                ",
                        "                D                ", "               C C               ",
                        "               C C               ", "                                 ",
                        "                                 ", "                                 ",
                        "                                 ", "                                 ",
                        "                                 " },
                    { "                                 ", "                                 ",
                        "                                 ", "                                 ",
                        "                                 ", "                                 ",
                        "                                 ", "               C C               ",
                        "               C C               ", "               C C               ",
                        "                D                ", "                D                ",
                        "             DDDDDDD             ", "            DD     DD            ",
                        "            D  EEE  D            ", "       CCC  D EAAAE D  CCC       ",
                        "          DDD EAAAE DDD          ", "       CCC  D EAAAE D  CCC       ",
                        "            D  EEE  D            ", "            DD     DD            ",
                        "             DDDDDDD             ", "                D                ",
                        "                D                ", "               C C               ",
                        "               C C               ", "               C C               ",
                        "                                 ", "                                 ",
                        "                                 ", "                                 ",
                        "                                 ", "                                 ",
                        "                                 " },
                    { "                                 ", "                                 ",
                        "                                 ", "                                 ",
                        "                                 ", "                                 ",
                        "                                 ", "                                 ",
                        "                                 ", "               C C               ",
                        "               C C               ", "               C C               ",
                        "               C C               ", "              DDDDD              ",
                        "             DDCDCDD             ", "         CCCCDCCDCCDCCCC         ",
                        "             DDDDDDD             ", "         CCCCDCCDCCDCCCC         ",
                        "             DDCDCDD             ", "              DDDDD              ",
                        "               C C               ", "               C C               ",
                        "               C C               ", "               C C               ",
                        "                                 ", "                                 ",
                        "                                 ", "                                 ",
                        "                                 ", "                                 ",
                        "                                 ", "                                 ",
                        "                                 " },
                    { "                                 ", "                                 ",
                        "                                 ", "                                 ",
                        "                                 ", "                                 ",
                        "                                 ", "                                 ",
                        "                                 ", "                                 ",
                        "                                 ", "                                 ",
                        "               C C               ", "               C C               ",
                        "               C C               ", "            CCCCCCCCC            ",
                        "               C C               ", "            CCCCCCCCC            ",
                        "               C C               ", "               C C               ",
                        "               C C               ", "                                 ",
                        "                                 ", "                                 ",
                        "                                 ", "                                 ",
                        "                                 ", "                                 ",
                        "                                 ", "                                 ",
                        "                                 ", "                                 ",
                        "                                 " } }))
        .addElement(
            'A',
            withChannel(
                "spacetime compression",
                ofBlocksTiered(
                    (block, meta) -> block == TTCasingsContainer.SpacetimeCompressionFieldGenerators ? meta : null,
                    ImmutableList.of(
                        Pair.of(TTCasingsContainer.SpacetimeCompressionFieldGenerators, 0),
                        Pair.of(TTCasingsContainer.SpacetimeCompressionFieldGenerators, 1),
                        Pair.of(TTCasingsContainer.SpacetimeCompressionFieldGenerators, 2),
                        Pair.of(TTCasingsContainer.SpacetimeCompressionFieldGenerators, 3),
                        Pair.of(TTCasingsContainer.SpacetimeCompressionFieldGenerators, 4),
                        Pair.of(TTCasingsContainer.SpacetimeCompressionFieldGenerators, 5),
                        Pair.of(TTCasingsContainer.SpacetimeCompressionFieldGenerators, 6),
                        Pair.of(TTCasingsContainer.SpacetimeCompressionFieldGenerators, 7),
                        Pair.of(TTCasingsContainer.SpacetimeCompressionFieldGenerators, 8)),
                    -1,
                    (t, meta) -> t.spacetimeCompressionFieldMetadata = meta,
                    t -> t.spacetimeCompressionFieldMetadata)))
        .addElement(
            'S',
            withChannel(
                "stabilisation",
                ofBlocksTiered(
                    (block, meta) -> block == TTCasingsContainer.StabilisationFieldGenerators ? meta : null,
                    ImmutableList.of(
                        Pair.of(TTCasingsContainer.StabilisationFieldGenerators, 0),
                        Pair.of(TTCasingsContainer.StabilisationFieldGenerators, 1),
                        Pair.of(TTCasingsContainer.StabilisationFieldGenerators, 2),
                        Pair.of(TTCasingsContainer.StabilisationFieldGenerators, 3),
                        Pair.of(TTCasingsContainer.StabilisationFieldGenerators, 4),
                        Pair.of(TTCasingsContainer.StabilisationFieldGenerators, 5),
                        Pair.of(TTCasingsContainer.StabilisationFieldGenerators, 6),
                        Pair.of(TTCasingsContainer.StabilisationFieldGenerators, 7),
                        Pair.of(TTCasingsContainer.StabilisationFieldGenerators, 8)),
                    -1,
                    (t, meta) -> t.stabilisationFieldMetadata = meta,
                    t -> t.stabilisationFieldMetadata)))
        .addElement('C', ofBlock(TTCasingsContainer.sBlockCasingsBA0, 11))
        .addElement('D', ofBlock(TTCasingsContainer.sBlockCasingsBA0, 10))
        .addElement(
            'H',
            buildHatchAdder(MTEEyeOfHarmony.class).atLeast(InputHatch, OutputHatch, InputBus, OutputBus)
                .casingIndex(BlockGTCasingsTT.texturePage << 7)
                .dot(1)
                .buildAndChain(TTCasingsContainer.sBlockCasingsBA0, 12))
        .addElement(
            'E',
            withChannel(
                "time dilation",
                ofBlocksTiered(
                    (block, meta) -> block == TTCasingsContainer.TimeAccelerationFieldGenerator ? meta : null,
                    ImmutableList.of(
                        Pair.of(TTCasingsContainer.TimeAccelerationFieldGenerator, 0),
                        Pair.of(TTCasingsContainer.TimeAccelerationFieldGenerator, 1),
                        Pair.of(TTCasingsContainer.TimeAccelerationFieldGenerator, 2),
                        Pair.of(TTCasingsContainer.TimeAccelerationFieldGenerator, 3),
                        Pair.of(TTCasingsContainer.TimeAccelerationFieldGenerator, 4),
                        Pair.of(TTCasingsContainer.TimeAccelerationFieldGenerator, 5),
                        Pair.of(TTCasingsContainer.TimeAccelerationFieldGenerator, 6),
                        Pair.of(TTCasingsContainer.TimeAccelerationFieldGenerator, 7),
                        Pair.of(TTCasingsContainer.TimeAccelerationFieldGenerator, 8)),
                    -1,
                    (t, meta) -> t.timeAccelerationFieldMetadata = meta,
                    t -> t.timeAccelerationFieldMetadata)))
        .build();

    private double hydrogenOverflowProbabilityAdjustment;
    private double heliumOverflowProbabilityAdjustment;
    private double stellarPlasmaOverflowProbabilityAdjustment;
    private static final long TICKS_BETWEEN_HATCH_DRAIN = EOH_DEBUG_MODE ? 10 : 20;

    private List<ItemStackLong> outputItems = new ArrayList<>();
    private List<FluidStackLong> outputFluids = new ArrayList<>();

    private void calculateInputFluidExcessValues(final long hydrogenRecipeRequirement,
        final long heliumRecipeRequirement) {

        double hydrogenStored = getHydrogenStored();
        double heliumStored = getHeliumStored();
        double stellarPlasmaStored = getStellarPlasmaStored();

        double hydrogenExcessPercentage = hydrogenStored / hydrogenRecipeRequirement - 1;
        double heliumExcessPercentage = heliumStored / heliumRecipeRequirement - 1;
        double stellarPlasmaExcessPercentage = stellarPlasmaStored
            / (heliumRecipeRequirement * (12.4 / 1_000_000f) * parallelAmount) - 1;

        hydrogenOverflowProbabilityAdjustment = 1 - exp(-pow(30 * hydrogenExcessPercentage, 2));
        heliumOverflowProbabilityAdjustment = 1 - exp(-pow(30 * heliumExcessPercentage, 2));
        stellarPlasmaOverflowProbabilityAdjustment = 1 - exp(-pow(30 * stellarPlasmaExcessPercentage, 2));
    }

    private double recipeChanceCalculator() {
        double chance = currentRecipe.getBaseRecipeSuccessChance()
            - timeAccelerationFieldMetadata * TIME_ACCEL_DECREASE_CHANCE_PER_TIER
            + stabilisationFieldMetadata * STABILITY_INCREASE_PROBABILITY_DECREASE_YIELD_PER_TIER;

        if (parallelAmount > 1) {
            chance -= stellarPlasmaOverflowProbabilityAdjustment;
        } else {
            chance -= (hydrogenOverflowProbabilityAdjustment + heliumOverflowProbabilityAdjustment);
        }

        return MathHelper.clamp_double(chance, 0.0, 1.0);
    }

    private double recipeYieldCalculator() {
        double yield = 1.0 - stabilisationFieldMetadata * STABILITY_INCREASE_PROBABILITY_DECREASE_YIELD_PER_TIER;

        if (parallelAmount > 1) {
            yield -= stellarPlasmaOverflowProbabilityAdjustment;
        } else {
            yield -= (hydrogenOverflowProbabilityAdjustment + heliumOverflowProbabilityAdjustment);
        }
        return MathHelper.clamp_double(yield, 0.0, 1.0);
    }

    private int recipeProcessTimeCalculator(final long recipeTime, final long recipeSpacetimeCasingRequired) {

        // Tier 1 recipe.
        // Tier 2 spacetime blocks.
        // = 3% discount.

        // Tier 1 recipe.
        // Tier 3 spacetime blocks.
        // = 3%*3% = 5.91% discount.

        final long spacetimeCasingDifference = (recipeSpacetimeCasingRequired - spacetimeCompressionFieldMetadata);
        final double recipeTimeDiscounted = recipeTime * pow(2.0, -timeAccelerationFieldMetadata)
            * pow(1 - SPACETIME_CASING_DIFFERENCE_DISCOUNT_PERCENTAGE, -spacetimeCasingDifference)
            / max(1, pow(2, currentCircuitMultiplier));
        return (int) Math.max(recipeTimeDiscounted, 1.0);
    }

    @Override
    public IStructureDefinition<MTEEyeOfHarmony> getStructure_EM() {
        return STRUCTURE_DEFINITION;
    }

    public MTEEyeOfHarmony(int aID, String aName, String aNameRegional) {
        super(aID, aName, aNameRegional);
    }

    public MTEEyeOfHarmony(String aName) {
        super(aName);
    }

    @Override
    public IMetaTileEntity newMetaEntity(IGregTechTileEntity aTileEntity) {
        return new MTEEyeOfHarmony(mName);
    }

    @Override
    public boolean checkMachine_EM(IGregTechTileEntity iGregTechTileEntity, ItemStack itemStack) {

        spacetimeCompressionFieldMetadata = -1;
        timeAccelerationFieldMetadata = -1;
        stabilisationFieldMetadata = -1;

        // Check structure of multi.
        if (!structureCheck_EM(STRUCTURE_PIECE_MAIN, 16, 16, 0)) {
            return false;
        }

        // Make sure there are no Crafting Input Buffers/Buses/Slaves.
        if (!mDualInputHatches.isEmpty()) {
            return false;
        }

        // Check if there is 1 output bus, and it is a ME output bus.
        {
            if (mOutputBusses.size() != 1) {
                return false;
            }

            if (!(mOutputBusses.get(0) instanceof MTEHatchOutputBusME)) {
                return false;
            }
        }

        // Check if there is 1 output hatch, and they are ME output hatches.
        {
            if (mOutputHatches.size() != 1) {
                return false;
            }

            if (!(mOutputHatches.get(0) instanceof MTEHatchOutputME)) {
                return false;
            }
        }

        // Check there is 1 input bus, and it is not a stocking input bus.
        {
            if (mInputBusses.size() != 1) {
                return false;
            }

            if (mInputBusses.get(0) instanceof MTEHatchInputBusME) {
                return false;
            }
        }

        // Make sure there are no energy hatches.
        {
            if (mEnergyHatches.size() > 0) {
                return false;
            }

            if (mExoticEnergyHatches.size() > 0) {
                return false;
            }
        }

        // Make sure there are 2 input hatches.
        if (mInputHatches.size() != 2) {
            return false;
        }

        return true;
    }

    private boolean animationsEnabled = true;

    @Override
    public final void onScrewdriverRightClick(ForgeDirection side, EntityPlayer aPlayer, float aX, float aY, float aZ) {
        animationsEnabled = !animationsEnabled;
        aPlayer.addChatMessage(
            new ChatComponentText("Animations are now " + (animationsEnabled ? "enabled" : "disabled") + "."));
    }

    @Override
    public boolean onWireCutterRightClick(ForgeDirection side, ForgeDirection wrenchingSide, EntityPlayer aPlayer,
        float aX, float aY, float aZ, ItemStack aTool) {
        if (astralArrayAmount != 0) {
            while (astralArrayAmount >= 64) {
                if (aPlayer.inventory.getFirstEmptyStack() != -1) {
                    aPlayer.inventory.addItemStackToInventory(CustomItemList.astralArrayFabricator.get(64));
                    astralArrayAmount -= 64;
                } else {
                    break;
                }
            }
            if (aPlayer.inventory.getFirstEmptyStack() != -1) {
                aPlayer.inventory.addItemStackToInventory(CustomItemList.astralArrayFabricator.get(astralArrayAmount));
                astralArrayAmount = 0;
            }
        }
        return true;
    }

    @Override
    public boolean onRightclick(IGregTechTileEntity aBaseMetaTileEntity, EntityPlayer aPlayer) {
        if (getControllerSlot() == null) {
            ItemStack heldItem = aPlayer.getHeldItem();
            if (GTUtility.getBlockFromStack(heldItem) instanceof BlockDimensionDisplay) {
                mInventory[getControllerSlotIndex()] = heldItem.copy();
                mInventory[getControllerSlotIndex()].stackSize = 1;
                aPlayer.setCurrentItemOrArmor(0, ItemUtils.depleteStack(heldItem));
                return true;
            }
        }
        return super.onRightclick(aBaseMetaTileEntity, aPlayer);
    }

    @Override
    public MultiblockTooltipBuilder createTooltip() {
        final MultiblockTooltipBuilder tt = new MultiblockTooltipBuilder();
        tt.addMachineType("Spacetime Manipulator, EOH")
            .addInfo(TOOLTIP_BAR)
            .addInfo("Creates a pocket of spacetime that is bigger on the inside using transdimensional")
            .addInfo("engineering. Certified Time Lord regulation compliant. This multi uses too much EU")
            .addInfo("to be handled with conventional means. All EU requirements are handled directly by")
            .addInfo("your wireless EU network.")
            .addInfo(TOOLTIP_BAR)
            .addInfo("This multiblock will constantly consume hydrogen and helium when it is not running a")
            .addInfo("recipe once per second. It will store this internally, you can see the totals by")
            .addInfo("using a scanner. This multi also has three tiered blocks with " + RED + 9 + GRAY + " tiers")
            .addInfo("each. They are as follows and have the associated effects on the multi.")
            .addInfo(BLUE + "Spacetime Compression Field Generator:")
            .addInfo("- The tier of this block determines what recipes can be run. If the multiblocks")
            .addInfo("  spacetime compression field block exceeds the requirements of the recipe it")
            .addInfo(
                "  will decrease the processing time by " + RED
                    + formatNumbers(SPACETIME_CASING_DIFFERENCE_DISCOUNT_PERCENTAGE * 100)
                    + "%"
                    + GRAY
                    + " per tier over the requirement (multiplicative).")
            .addInfo(BLUE + "Time Dilation Field Generator:")
            .addInfo(
                "- Decreases the time required for a recipe by " + RED
                    + "50%"
                    + GRAY
                    + " per tier of block (multiplicative).")
            .addInfo(
                "  Decreases the probability of a recipe succeeding by " + RED
                    + formatNumbers(TIME_ACCEL_DECREASE_CHANCE_PER_TIER * 100)
                    + "%"
                    + GRAY
                    + " per tier (additive)")
            .addInfo(BLUE + "Stabilisation Field Generator:")
            .addInfo(
                "- Increases the probability of a recipe succeeding by " + RED
                    + formatNumbers(STABILITY_INCREASE_PROBABILITY_DECREASE_YIELD_PER_TIER * 100)
                    + "%"
                    + GRAY
                    + " per tier (additive).")
            .addInfo(
                "  Decreases the yield of a recipe by " + RED
                    + formatNumbers(STABILITY_INCREASE_PROBABILITY_DECREASE_YIELD_PER_TIER * 100)
                    + "%"
                    + GRAY
                    + " per tier (additive). ")
            .addInfo("  > Low tier stabilisation field generators have a power output penalty.")
            .addInfo(
                "     The power output penalty for using Crude Stabilisation Field Generators is " + RED
                    + formatNumbers(
                        STABILITY_INCREASE_PROBABILITY_DECREASE_YIELD_PER_TIER * TOTAL_CASING_TIERS_WITH_POWER_PENALTY
                            * 100)
                    + "%"
                    + GRAY
                    + ".")
            .addInfo(
                "     This penalty decreases by " + RED
                    + formatNumbers(STABILITY_INCREASE_PROBABILITY_DECREASE_YIELD_PER_TIER * 100)
                    + "%"
                    + GRAY
                    + " per tier (additive).")
            .addInfo(TOOLTIP_BAR)
            .addInfo("Going over a recipe requirement on hydrogen or helium has a penalty on yield and recipe chance.")
            .addInfo("All stored hydrogen and helium is consumed during a craft. The associated formulas are:")
            .addInfo(GREEN + "Overflow ratio = (Stored fluid / Recipe requirement) - 1")
            .addInfo(GREEN + "Adjustment value = 1 - exp(-(30 * Overflow ratio)^2)")
            .addInfo("The Adjustment value is then subtracted from the total yield and recipe chance.")
            .addInfo(TOOLTIP_BAR)
            .addInfo("It should be noted that base recipe chance is determined per recipe and yield always starts")
            .addInfo("at 1 and subtracts depending on penalties. All fluid/item outputs are multiplied by the")
            .addInfo("yield. Failure fluid is exempt.")
            .addInfo(TOOLTIP_BAR)
            .addInfo("This multiblock can only output to ME output buses/hatches.")
            .addInfo(TOOLTIP_BAR)
            .addInfo("This multiblock can be overclocked by placing a programmed circuit into the input bus.")
            .addInfo(
                "E.g. A circuit of 2 will provide 2 OCs, 16x EU input and 0.25x the time. EU output is unaffected.")
            .addInfo("All outputs are equal. All item and fluid output chances & amounts per recipe are unaffected.")
            .addInfo(TOOLTIP_BAR)
            .addInfo(
                "If a recipe fails the EOH will output " + GREEN
                    + "Success chance * "
                    + formatNumbers(MOLTEN_SPACETIME_PER_FAILURE_TIER)
                    + " * ("
                    + SPACETIME_FAILURE_BASE
                    + ")^(Recipe tier)"
                    + GRAY
                    + "L of molten")
            .addInfo(
                MaterialsUEVplus.SpaceTime.getLocalizedNameForItem("%material")
                    + " instead of fluid/item outputs and output as much EU as a successful recipe.")
            .addInfo(TOOLTIP_BAR)
            .addInfo(
                "This multiblock can perform parallel processing by placing Astral Array Fabricators into the input bus.")
            .addInfo(
                "They are stored internally and can be retrieved via right-clicking the controller with a wire cutter.")
            .addInfo(
                "The maximum amount of stored Astral Arrays is " + formatNumbers(ASTRAL_ARRAY_LIMIT)
                    + ". The amount of parallel is calculated via these formulas:")
            .addInfo(
                GREEN + "Parallel exponent = floor(log("
                    + formatNumbers(PARALLEL_FOR_FIRST_ASTRAL_ARRAY)
                    + " * Astral Array amount) / log("
                    + formatNumbers(CONSTANT_FOR_LOG)
                    + "))")
            .addInfo(GREEN + "Parallel = 2^(Parallel exponent)")
            .addInfo("If the EOH is running parallel recipes, the power calculation changes.")
            .addInfo("The power needed for parallel processing is calculated as follows:")
            .addInfo(
                GREEN + "total EU = ((EU output - EU input * "
                    + formatNumbers(PARALLEL_MULTIPLIER_CONSTANT)
                    + ") / "
                    + formatNumbers(POWER_DIVISION_CONSTANT)
                    + ") * "
                    + formatNumbers(POWER_INCREASE_CONSTANT)
                    + "^(Parallel exponent)")
            .addInfo(
                "Furthermore, if parallel recipes are run, the recipes consume "
                    + MaterialsUEVplus.RawStarMatter.getLocalizedNameForItem("%material"))
            .addInfo("instead of helium and hydrogen. Overflow penalties still apply.")
            .addInfo(
                "The required amount of fluid to start a recipe is " + GREEN
                    + "12.4 / 10^6 * Helium amount * Parallel"
                    + GRAY
                    + ".")
            .addInfo("The success or failure of each parallel is determined independently.")
            .addInfo(TOOLTIP_BAR)
            .addInfo("Animations can be disabled by using a screwdriver on the multiblock.")
            .addInfo("Planet block can be inserted directly by right-clicking the controller with planet block.")
            .addSeparator()
            .addStructureInfo("Eye of Harmony structure is too complex! See schematic for details.")
            .addStructureInfo(
                EnumChatFormatting.GOLD + "896" + EnumChatFormatting.GRAY + " Reinforced Spatial Structure Casing.")
            .addStructureInfo(
                EnumChatFormatting.GOLD + "534" + EnumChatFormatting.GRAY + " Reinforced Temporal Structure Casing.")
            .addStructureInfo(
                EnumChatFormatting.GOLD + "31"
                    + EnumChatFormatting.GRAY
                    + " Infinite SpaceTime Energy Boundary Casing.")
            .addStructureInfo(
                EnumChatFormatting.GOLD + "168" + EnumChatFormatting.GRAY + " Time Dilation Field Generator.")
            .addStructureInfo(
                EnumChatFormatting.GOLD + "48" + EnumChatFormatting.GRAY + " Stabilisation Field Generator.")
            .addStructureInfo(
                EnumChatFormatting.GOLD + "138" + EnumChatFormatting.GRAY + " Spacetime Compression Field Generator.")
            .addStructureInfo("--------------------------------------------")
            .addStructureInfo("Requires " + EnumChatFormatting.GOLD + 2 + EnumChatFormatting.GRAY + " input hatches.")
            .addStructureInfo("Requires " + EnumChatFormatting.GOLD + 1 + EnumChatFormatting.GRAY + " ME output hatch.")
            .addStructureInfo("Requires " + EnumChatFormatting.GOLD + 1 + EnumChatFormatting.GRAY + " input bus.")
            .addStructureInfo("Requires " + EnumChatFormatting.GOLD + 1 + EnumChatFormatting.GRAY + " ME output bus.")
            .addStructureInfo("--------------------------------------------")
            .beginStructureBlock(33, 33, 33, false)
            .toolTipFinisher(AuthorColen.substring(8) + EnumChatFormatting.GRAY + "&" + CommonValues.TEC_MARK_EM);
        return tt;
    }

    @Override
    @SideOnly(Side.CLIENT)
    public void registerIcons(IIconRegister aBlockIconRegister) {
        ScreenOFF = new Textures.BlockIcons.CustomIcon("iconsets/EM_BHG");
        ScreenON = new Textures.BlockIcons.CustomIcon("iconsets/EM_BHG_ACTIVE");
        super.registerIcons(aBlockIconRegister);
    }

    @Override
    public ITexture[] getTexture(IGregTechTileEntity aBaseMetaTileEntity, ForgeDirection side, ForgeDirection facing,
        int colorIndex, boolean aActive, boolean aRedstone) {
        if (side == facing) {
            return new ITexture[] { Textures.BlockIcons.casingTexturePages[BlockGTCasingsTT.texturePage][12],
                new TTRenderedExtendedFacingTexture(aActive ? ScreenON : ScreenOFF) };
        }
        return new ITexture[] { Textures.BlockIcons.casingTexturePages[BlockGTCasingsTT.texturePage][12] };
    }

    @Override
    public void construct(ItemStack stackSize, boolean hintsOnly) {
        structureBuild_EM(STRUCTURE_PIECE_MAIN, 16, 16, 0, stackSize, hintsOnly);
    }

    private final Map<Fluid, Long> validFluidMap = new HashMap<>() {

        private static final long serialVersionUID = -8452610443191188130L;

        {
            put(Materials.Hydrogen.mGas, 0L);
            put(Materials.Helium.mGas, 0L);
            put(MaterialsUEVplus.RawStarMatter.mFluid, 0L);
        }
    };

    private void drainFluidFromHatchesAndStoreInternally() {
        List<FluidStack> fluidStacks = getStoredFluids();
        for (FluidStack fluidStack : fluidStacks) {
            if (validFluidMap.containsKey(fluidStack.getFluid())) {
                validFluidMap.merge(fluidStack.getFluid(), (long) fluidStack.amount, Long::sum);
                fluidStack.amount = 0;
            }
        }
        updateSlots();
    }

    @Override
    public RecipeMap<?> getRecipeMap() {
        // Only for visual
        return TecTechRecipeMaps.eyeOfHarmonyRecipes;
    }

    private EyeOfHarmonyRecipe currentRecipe;

    // Counter for lag prevention.
    private long lagPreventer = 0;

    // Check for recipe every recipeCheckInterval ticks.
    private static final long RECIPE_CHECK_INTERVAL = 3 * 20;
    private long currentCircuitMultiplier = 0;
    private long astralArrayAmount = 0;
    private long parallelAmount = 1;
    private long successfulParallelAmount = 0;
    private double yield = 0;
    private BigInteger usedEU = BigInteger.ZERO;
    private FluidStackLong stellarPlasma;
    private FluidStackLong starMatter;

    @Override
    @NotNull
    protected CheckRecipeResult checkProcessing_EM() {
        ItemStack controllerStack = getControllerSlot();
        if (controllerStack == null) {
            return SimpleCheckRecipeResult.ofFailure("no_planet_block");
        }

        lagPreventer++;
        if (lagPreventer < RECIPE_CHECK_INTERVAL) {
            lagPreventer = 0;
            // No item in multi gui slot.

            currentRecipe = TecTech.eyeOfHarmonyRecipeStorage.recipeLookUp(controllerStack);
            if (currentRecipe == null) {
                return CheckRecipeResultRegistry.NO_RECIPE;
            }
            CheckRecipeResult result = processRecipe(currentRecipe);
            if (!result.wasSuccessful()) currentRecipe = null;
            return result;
        }
        return CheckRecipeResultRegistry.NO_RECIPE;
    }

    private long getHydrogenStored() {
        return validFluidMap.get(Materials.Hydrogen.mGas);
    }

    private long getHeliumStored() {
        return validFluidMap.get(Materials.Helium.mGas);
    }

    private long getStellarPlasmaStored() {
        return validFluidMap.get(MaterialsUEVplus.RawStarMatter.mFluid);
    }

    public CheckRecipeResult processRecipe(EyeOfHarmonyRecipe recipeObject) {

        // Get circuit damage, clamp it and then use it later for overclocking.
        currentCircuitMultiplier = 0;
        for (ItemStack itemStack : mInputBusses.get(0)
            .getRealInventory()) {
            if (GTUtility.isAnyIntegratedCircuit(itemStack)) {
                currentCircuitMultiplier = MathHelper.clamp_int(itemStack.getItemDamage(), 0, 24);
                break;
            }
        }

        for (ItemStack itemStack : mInputBusses.get(0)
            .getRealInventory()) {
            if (astralArrayAmount >= ASTRAL_ARRAY_LIMIT) break;
            if (itemStack != null && itemStack.isItemEqual(CustomItemList.astralArrayFabricator.get(1))) {
                long insertAmount = Math.min(itemStack.stackSize, ASTRAL_ARRAY_LIMIT - astralArrayAmount);
                astralArrayAmount += insertAmount;
                itemStack.stackSize -= insertAmount;
            }
        }

        long parallelExponent = 1;

        if (astralArrayAmount != 0) {
            parallelExponent = (long) Math.floor(
                Math.log(PARALLEL_FOR_FIRST_ASTRAL_ARRAY * Math.min(astralArrayAmount, ASTRAL_ARRAY_LIMIT))
                    / LOG_CONSTANT);
            parallelAmount = (long) pow(2, parallelExponent);
        } else {
            parallelAmount = 1;
        }

        // Debug mode, overwrites the required fluids to initiate the recipe to 100L of each.
        if (parallelAmount > 1) {
            if ((EOH_DEBUG_MODE && getStellarPlasmaStored() < 100) || (!EOH_DEBUG_MODE && getStellarPlasmaStored()
                < currentRecipe.getHeliumRequirement() * (12.4 / 1_000_000f) * parallelAmount)) {
                return SimpleCheckRecipeResult.ofFailure("no_stellar_plasma");
            }
        }

        if (parallelAmount == 1) {
            if ((EOH_DEBUG_MODE && getHydrogenStored() < 100)
                || (!EOH_DEBUG_MODE && getHydrogenStored() < currentRecipe.getHydrogenRequirement())) {
                return SimpleCheckRecipeResult.ofFailure("no_hydrogen");
            }

            if ((EOH_DEBUG_MODE && getHeliumStored() < 100)
                || (!EOH_DEBUG_MODE && getHeliumStored() < currentRecipe.getHeliumRequirement())) {
                return SimpleCheckRecipeResult.ofFailure("no_helium");
            }
        }

        if (spacetimeCompressionFieldMetadata == -1) {
            return CheckRecipeResultRegistry
                .insufficientMachineTier((int) recipeObject.getSpacetimeCasingTierRequired());
        }

        // Check tier of spacetime compression blocks is high enough.
        if (spacetimeCompressionFieldMetadata < recipeObject.getSpacetimeCasingTierRequired()) {
            return CheckRecipeResultRegistry
                .insufficientMachineTier((int) recipeObject.getSpacetimeCasingTierRequired());
        }

        // Calculate multipliers used in power calculations
        double powerMultiplier = Math.max(1, Math.pow(POWER_INCREASE_CONSTANT, parallelExponent));

        // Determine EU recipe input
        startEU = recipeObject.getEUStartCost();

        // Calculate normal EU values
        double outputEUPenalty = (TOTAL_CASING_TIERS_WITH_POWER_PENALTY - stabilisationFieldMetadata)
            * STABILITY_INCREASE_PROBABILITY_DECREASE_YIELD_PER_TIER;
        outputEU_BigInt = BigInteger.valueOf((long) (recipeObject.getEUOutput() * (1 - outputEUPenalty)));
        usedEU = BigInteger.valueOf(-startEU)
            .multiply(BigInteger.valueOf((long) Math.pow(4, currentCircuitMultiplier)));

        // Calculate parallel EU values
        if (parallelAmount > 1) {
            outputEU_BigInt = outputEU_BigInt
                .multiply(BigInteger.valueOf((long) (powerMultiplier * PRECISION_MULTIPLIER)))
                .divide(BigInteger.valueOf((long) (PRECISION_MULTIPLIER * POWER_DIVISION_CONSTANT)));

            usedEU = usedEU
                .multiply(
                    BigInteger.valueOf((long) (powerMultiplier * PARALLEL_MULTIPLIER_CONSTANT * PRECISION_MULTIPLIER)))
                .divide(BigInteger.valueOf((long) (PRECISION_MULTIPLIER * POWER_DIVISION_CONSTANT)));
        }

        // Remove EU from the users network.
        if (!addEUToGlobalEnergyMap(userUUID, usedEU)) {
            return CheckRecipeResultRegistry.insufficientStartupPower(usedEU.abs());
        }

        mMaxProgresstime = recipeProcessTimeCalculator(
            recipeObject.getRecipeTimeInTicks(),
            recipeObject.getSpacetimeCasingTierRequired());

        calculateInputFluidExcessValues(recipeObject.getHydrogenRequirement(), recipeObject.getHeliumRequirement());

        if (EOH_DEBUG_MODE) {
            hydrogenOverflowProbabilityAdjustment = 0;
            heliumOverflowProbabilityAdjustment = 0;
            stellarPlasmaOverflowProbabilityAdjustment = 0;
        }

        successChance = recipeChanceCalculator();
        currentRecipeRocketTier = currentRecipe.getRocketTier();

        // Reduce internal storage by input fluid quantity required for recipe.
        if (parallelAmount > 1) {
            validFluidMap.put(MaterialsUEVplus.RawStarMatter.mFluid, 0L);
        } else {
            validFluidMap.put(Materials.Hydrogen.mGas, 0L);
            validFluidMap.put(Materials.Helium.mGas, 0L);
        }

        yield = recipeYieldCalculator();
        if (EOH_DEBUG_MODE) {
            successChance = 1; // Debug recipes, sets them to 100% output chance.
        }

        // Return copies of the output objects.
        outputFluids = recipeObject.getOutputFluids();
        outputItems = recipeObject.getOutputItems();

        // Star matter is always the last element in the array.
        starMatter = new FluidStackLong(outputFluids.get(outputFluids.size() - 1));

        // And stellar plasma is the second last.
        stellarPlasma = new FluidStackLong(outputFluids.get(outputFluids.size() - 2));

        successfulParallelAmount = (long) calculateChancedOutputMultiplier(
            (int) (10000 * successChance),
            (int) parallelAmount);
        // Iterate over item output list and apply yield & successful parallel values.
        for (ItemStackLong itemStackLong : outputItems) {
            itemStackLong.stackSize *= yield * successfulParallelAmount;
        }

        // Iterate over fluid output list and apply yield & successful parallel values.
        for (FluidStackLong fluidStackLong : outputFluids) {
            fluidStackLong.amount *= yield * successfulParallelAmount;
        }

        updateSlots();

        if (animationsEnabled) {
            createRenderBlock(currentRecipe);
        }

        recipeRunning = true;
        return CheckRecipeResultRegistry.SUCCESSFUL;
    }

    private void createRenderBlock(final EyeOfHarmonyRecipe currentRecipe) {

        IGregTechTileEntity gregTechTileEntity = this.getBaseMetaTileEntity();

        int x = gregTechTileEntity.getXCoord();
        int y = gregTechTileEntity.getYCoord();
        int z = gregTechTileEntity.getZCoord();

        double xOffset = 16 * getExtendedFacing().getRelativeBackInWorld().offsetX;
        double zOffset = 16 * getExtendedFacing().getRelativeBackInWorld().offsetZ;
        double yOffset = 16 * getExtendedFacing().getRelativeBackInWorld().offsetY;

        this.getBaseMetaTileEntity()
            .getWorld()
            .setBlock((int) (x + xOffset), (int) (y + yOffset), (int) (z + zOffset), Blocks.air);
        this.getBaseMetaTileEntity()
            .getWorld()
            .setBlock(
                (int) (x + xOffset),
                (int) (y + yOffset),
                (int) (z + zOffset),
                TTCasingsContainer.eyeOfHarmonyRenderBlock);
        TileEntityEyeOfHarmony rendererTileEntity = (TileEntityEyeOfHarmony) this.getBaseMetaTileEntity()
            .getWorld()
            .getTileEntity((int) (x + xOffset), (int) (y + yOffset), (int) (z + zOffset));

        rendererTileEntity.setTier(currentRecipe.getRocketTier());

        int recipeSpacetimeTier = (int) currentRecipe.getSpacetimeCasingTierRequired();

        // Star is a larger size depending on the spacetime tier of the recipe.
        rendererTileEntity.setSize((1 + recipeSpacetimeTier));

        // Star rotates faster the higher tier time dilation you use in the multi.
        // Lower value = faster rotation speed.
        rendererTileEntity.setRotationSpeed((1 + timeAccelerationFieldMetadata) / 2.0f);
    }

    private double successChance;
    private long currentRecipeRocketTier;

    private void outputFailedChance() {
        long failedParallelAmount = parallelAmount - successfulParallelAmount;
        if (failedParallelAmount > 0) {
            // 2^Tier spacetime released upon recipe failure.
            outputFluidToAENetwork(
                MaterialsUEVplus.SpaceTime.getMolten(1),
                (long) ((successChance * MOLTEN_SPACETIME_PER_FAILURE_TIER
                    * pow(SPACETIME_FAILURE_BASE, currentRecipeRocketTier + 1)) * failedParallelAmount));
        }
        super.outputAfterRecipe_EM();
    }

    @Override
    public void stopMachine(@Nonnull ShutDownReason reason) {
        super.stopMachine(reason);
        destroyRenderBlock();
        recipeRunning = false;
    }

    @Override
    public void onBlockDestroyed() {
        super.onBlockDestroyed();
        destroyRenderBlock();
    }

    private void destroyRenderBlock() {
        IGregTechTileEntity gregTechTileEntity = this.getBaseMetaTileEntity();

        int x = gregTechTileEntity.getXCoord();
        int y = gregTechTileEntity.getYCoord();
        int z = gregTechTileEntity.getZCoord();

        double xOffset = 16 * getExtendedFacing().getRelativeBackInWorld().offsetX;
        double zOffset = 16 * getExtendedFacing().getRelativeBackInWorld().offsetZ;
        double yOffset = 16 * getExtendedFacing().getRelativeBackInWorld().offsetY;

        this.getBaseMetaTileEntity()
            .getWorld()
            .setBlock((int) (x + xOffset), (int) (y + yOffset), (int) (z + zOffset), Blocks.air);
    }

    public void outputAfterRecipe_EM() {
        recipeRunning = false;
        eRequiredData = 0L;

        destroyRenderBlock();

        // Output EU
        addEUToGlobalEnergyMap(userUUID, outputEU_BigInt);

        startEU = 0;
        outputEU_BigInt = BigInteger.ZERO;

        outputFailedChance();

        if (successfulParallelAmount > 0) {
            for (ItemStackLong itemStack : outputItems) {
                outputItemToAENetwork(itemStack.itemStack, itemStack.stackSize);
            }

            for (FluidStackLong fluidStack : outputFluids) {
                outputFluidToAENetwork(fluidStack.fluidStack, fluidStack.amount);
            }
        }

        // Clear the array list for new recipes.
        outputItems = new ArrayList<>();
        outputFluids = new ArrayList<>();

        // Do other stuff from TT superclasses. E.g. outputting fluids.
        super.outputAfterRecipe_EM();
    }

    @Override
    public void onPreTick(IGregTechTileEntity aBaseMetaTileEntity, long aTick) {
        super.onPreTick(aBaseMetaTileEntity, aTick);

        if (aTick == 1) {
            userUUID = getBaseMetaTileEntity().getOwnerUuid();
            strongCheckOrAddUser(userUUID);
        }

        if (!recipeRunning && mMachine) {
            if ((aTick % TICKS_BETWEEN_HATCH_DRAIN) == 0) {
                drainFluidFromHatchesAndStoreInternally();
            }
        }
    }

    private boolean recipeRunning = false;

    private void outputItemToAENetwork(ItemStack item, long amount) {
        if (item == null || amount <= 0) return;

        while (amount >= Integer.MAX_VALUE) {
            ItemStack tmpItem = item.copy();
            tmpItem.stackSize = Integer.MAX_VALUE;
            ((MTEHatchOutputBusME) mOutputBusses.get(0)).store(tmpItem);
            amount -= Integer.MAX_VALUE;
        }
        ItemStack tmpItem = item.copy();
        tmpItem.stackSize = (int) amount;
        ((MTEHatchOutputBusME) mOutputBusses.get(0)).store(tmpItem);
    }

    private void outputFluidToAENetwork(FluidStack fluid, long amount) {
        if (fluid == null || amount <= 0) return;

        while (amount >= Integer.MAX_VALUE) {
            FluidStack tmpFluid = fluid.copy();
            tmpFluid.amount = Integer.MAX_VALUE;
            ((MTEHatchOutputME) mOutputHatches.get(0)).tryFillAE(tmpFluid);
            amount -= Integer.MAX_VALUE;
        }
        FluidStack tmpFluid = fluid.copy();
        tmpFluid.amount = (int) amount;
        ((MTEHatchOutputME) mOutputHatches.get(0)).tryFillAE(tmpFluid);
    }

    @Override
    public String[] getInfoData() {
        ArrayList<String> str = new ArrayList<>(Arrays.asList(super.getInfoData()));
        str.add(GOLD + "---------------- Control Block Statistics ----------------");
        if (spacetimeCompressionFieldMetadata < 0) {
            str.add("Spacetime Compression Field Grade: None");
        } else {
            str.add(
                "Spacetime Compression Field Grade: "
                    + CommonValues.EOH_TIER_FANCY_NAMES[spacetimeCompressionFieldMetadata]
                    + RESET
                    + " ("
                    + YELLOW
                    + spacetimeCompressionFieldMetadata
                    + RESET
                    + ")");
        }
        if (timeAccelerationFieldMetadata < 0) {
            str.add("Time Dilation Field Grade: None");
        } else {
            str.add(
                "Time Dilation Field Grade: " + CommonValues.EOH_TIER_FANCY_NAMES[timeAccelerationFieldMetadata]
                    + RESET
                    + " ("
                    + YELLOW
                    + timeAccelerationFieldMetadata
                    + RESET
                    + ")");
        }
        if (stabilisationFieldMetadata < 0) {
            str.add("Stabilisation Field Grade: None");
        } else {
            str.add(
                "Stabilisation Field Grade: " + CommonValues.EOH_TIER_FANCY_NAMES[stabilisationFieldMetadata]
